Workbook

Sheet Key
A1: Guide to interpreting this cost-effectiveness analysis
A2: Sheet descriptions
E4: Main CEA | F4: This sheet contains the primary calculations that result in final cost-effectiveness estimates. This sheet draws on inputs from the "Inputs" sheet and inputs calculated in the other supplemental sheets listed below.
E5: Effective coverage | F5: This sheet contains our calculations of how much protection nets distributed in grantee programs provide compared to the protection provided by nets distributed in the trials that inform our treatment effect estimates.
E6: Counterfactual malaria | F6: This sheet contains our calculations of how high malaria mortality and prevalence rates would be in the absence of net distributions.
E7: Insecticide resistance | F7: This sheet contains our calculations of how much the protective effect of nets is reduced by insecticide resistance among malaria-transmitting mosquitos.
E8: Leverage/Funging | F8: This sheet contains our calculations of the impact that crowding in and crowding out funding by other contributors has on the benefits of the program.
E9: Inputs | F9: This sheet contains all of the manually entered input values informing the CEA, along with the sources and reasoning supporting them. This sheet also contains inputs sourced from the "GBD estimates" sheet.
E10: Net decay model | F10: This sheet contains our models of physical net decay over time, which inform calculations on the "Effective coverage" sheet.
E11: GBD estimates | F11: This sheet contains disease burden and population datasets downloaded from the Institute of Health Metrics (IHME)'s Global Burden of Disease (GBD) project.
E12: Simple CEA | F12: This sheet contains a simplified version of the CEA that is designed to be comparable to our CEAs of other programs.
E13: Confidence intervals | F13: This sheet contains our best guesses of the 25th and 75th percentile values for each of the parameters of our simple CEA.
E14: Sensitivity analysis | F14: This sheet contains the outputs of our sensitivity analysis that tests the cost-effectiveness ranges that would result from updating certain inputs to their 25th or 75th percentile values.
A16: Terminology key
C18: Terms specific to this CEA
E19: ITN | F19: Insecticide-treated nets (ITNs) are mosquito nets have have been treated with insecticidal chemicals designed to kill and/or repel mosquitoes. ITNs are an umbrella category of nets that include conventionally treated nets (CTNs), long-lasting insecticide-treated nets (LLINs), and newer types of nets like PBO and chlorfenapyr nets.
E20: LLIN | F20: Long-lasting insecticide-treated nets (LLINs) are mosquito nets that have been treated with insecticides using a method that extends the effectiveness of the insecticide for multiple years without retreatment. Some of the nets (which we sometimes refer to as "standard nets") distributed in programs we consider funding are LLINs.
E21: Pyrethroid | F21: A class of insecticides commonly used to treat LLINs. The pyrethroid compounds most commonly used to treat LLINs are permethrin, alpha-cypermethrin, and deltamethrin.
E22: CTN | F22: Conventionally treated nets (CTNs) are mosquito nets that must be re-treated with insecticide periodically to retain their effectiveness. The nets distributed in the trials informing our treatment effect estimates were CTNs.
E23: Dual AI nets | F23: Dual active ingredient (Dual AI) nets are LLINs that are treated with multiple insecticidal chemicals that have different mechanisms of action. These nets are typically treated with a pyrethroid plus another insecticide and are designed to combat pyrethroid-resistant mosquitoes.
E24: PBO | F24: Piperonyl butoxide (PBO) is a chemical used alongside pyrethroid insecticides to treat some types of LLINs ("PBO nets") to enhance their effectiveness against insecticide-resistant mosquitos. PBO is not itself an insecticidal chemical but acts as a "synergist" that inhibits the metabolic enzymes that grant mosquitoes immunity to pyrethroids.
E25: Chlorfenapyr | F25: The rate of new cases in a given unit of time.
E26: Incidence
E27: Prevalence | F27: The proportion of people with a disease or condition at or during a particular time period (regardless of when they first contracted it).
E28: Indirect malaria deaths | F28: Deaths in which malaria plays a causal role, but are attributed to another cause. For example, malaria may increase the likelihood of death from malnutrition or other infectious diseases. Malaria control interventions often have a larger effect on all-cause mortality than would be expected exclusively from declines in malaria-specific mortality, which we interpret as evidence that averting malaria may also avert deaths attributed to other causes.
E29: Insecticide resistance | F29: Immunity among mosquito populations to the insecticidal chemicals commonly used to treat LLINs. Insecticide resistance can inhibit the protective effect of nets against malaria transmission.
E30: Bioassay | F30: An insecticide resistance test that involves exposing mosquitos to an insecticidal chemical and measuring the proportion of mosquitos that are killed.
E31: Person-year of effective coverage | F31: We use "effective coverage" to refer to a level of protection against malaria equivalent to the protection provided by the nets distributed in the mortality studies we rely on. A "person-year" refers to the equivalent of one person receiving one year of effective coverage. This unit is a simplification. For example, because nets typically remain effective longer than a year, two person-years of coverage could actually reflect one person receiving effective coverage for two years.
C33: Terms used across GiveWell's CEAs
E34: Internal validity | F34: Describes an adjustment we make to the treatment effect of an intervention to account for the possibility that the treatment effects found in studies may not represent the true effect the intervention had on the populations studied.
E35: External validity | F35: Describes an adjustment we make to the treatment effect of an intervention to account for differences in the program implementation or populations treated in studies from the program implementation or populations treated by grantee programs.
E36: Leverage | F36: Describes a situation where a grantee's spending on a program causes other organizations or governments to contribute more to the program than they otherwise would have. In most cases, accounting for leverage increases cost-effectiveness
E37: Funging | F37: Describes a situation where a grantee's spending on a program causes other organizations or governments to contribute less to the program than they otherwise would have. In most cases, accounting for funging decreases cost-effectiveness.
E38: In-kind contributions | F38: Describes non-financial (e.g., staff time, office space) contributions to a program that might otherwise have been used for other activities or programs.
E39: Counterfactual | F39: In most cases, describes the state of the world that would exist if we did not provide funding to a grantee for a program. When discussing the "counterfactual value of other actors' spending," we are referring to how much benefit another organization's or government's spending would generate if it were spent on something other than the grantee program.
E40: Moral weights | F40: To compare cost-effectiveness across different programs, we use ‘moral weights’ to quantify the benefits of different program impacts (e.g. increased income vs reduced deaths). We benchmark the value of each benefit to a value of 1, which we define as the value of doubling someone’s consumption for one year.
E41: Philanthropic actors | F41: Non-governmental organizations (NGOs) providing funding to philanthropic programs.
A43: Unit and source key
C45: Unit labels used in the CEA
E46: # | F46: Number
...

Sheet Main CEA
I1: Against Malaria Foundation
I2: Chad | J2: DRC | K2: Guinea | L2: Nigeria | M2: Nigeria | N2: South Sudan | O2: Togo | P2: Uganda
A3: Main calculations | F3: unit | G3: type | H3: Overall | L3: GF states | M3: PMI states
E4: Final cost-effectiveness estimate (pulled from below for visibility) | F4: =F203 -> xbenchmark | G4: main | H4: =H203 -> - | I4: =I203 -> 4.8202994 | J4: =J203 -> 14.629025 | K4: =K203 -> 22.79223 | L4: =L203 -> 16.778736 | M4: =M203 -> 13.250427 | N4: =N203 -> 7.1630004 | O4: =O203 -> 8.8061654 | P4: =P203 -> 15.60304
A5: Costs
C7: GiveWell costs
E8: Grant size | F8: =Inputs!F8 -> $ | G8: input | H8: =Inputs!H8 -> 1000000 | I8: =Inputs!I8 -> - | J8: =Inputs!J8 -> - | K8: =Inputs!K8 -> - | L8: =Inputs!L8 -> - | M8: =Inputs!M8 -> - | N8: =Inputs!N8 -> - | O8: =Inputs!O8 -> - | P8: =Inputs!P8 -> -
C10: Cost breakdown
E11: Percentage of total costs covered by the grantee | F11: =Inputs!F11 -> % | G11: input | H11: =Inputs!H11 -> - | I11: =Inputs!I11 -> 0.9562847 | J11: =Inputs!J11 -> 0.9449092 | K11: =Inputs!K11 -> 0.9562847 | L11: =Inputs!L11 -> 0.9613383 | M11: =Inputs!M11 -> 0.9613383 | N11: =Inputs!N11 -> 0.936798 | O11: =Inputs!O11 -> 0.9595745 | P11: =Inputs!P11 -> 0.9553321
E12: Percentage of total costs covered by other philanthropic actors | F12: =Inputs!F12 -> % | G12: input | H12: =Inputs!H12 -> - | I12: =Inputs!I12 -> 0 | J12: =Inputs!J12 -> 0 | K12: =Inputs!K12 -> 0 | L12: =Inputs!L12 -> 0 | M12: =Inputs!M12 -> 0 | N12: =Inputs!N12 -> 0 | O12: =Inputs!O12 -> 0 | P12: =Inputs!P12 -> 0
E13: Percentage of total costs covered by domestic governments | F13: =Inputs!F13 -> % | G13: input | H13: =Inputs!H13 -> - | I13: =Inputs!I13 -> 0.0437153 | J13: =Inputs!J13 -> 0.0550908 | K13: =Inputs!K13 -> 0.0437153 | L13: =Inputs!L13 -> 0.0386617 | M13: =Inputs!M13 -> 0.0386617 | N13: =Inputs!N13 -> 0.0632021 | O13: =Inputs!O13 -> 0.0404255 | P13: =Inputs!P13 -> 0.0446679
C15: Total costs
E16: Total spending by all contributors | F16: $ | G16: calc | H16: - | I16: =IF(I8="-",$H8/I11,I8/I11) -> 1045713.7 | J16: =IF(J8="-",$H8/J11,J8/J11) -> 1058302.7 | K16: =IF(K8="-",$H8/K11,K8/K11) -> 1045713.7 | L16: =IF(L8="-",$H8/L11,L8/L11) -> 1040216.5 | M16: =IF(M8="-",$H8/M11,M8/M11) -> 1040216.5 | N16: =IF(N8="-",$H8/N11,N8/N11) -> 1067466 | O16: =IF(O8="-",$H8/O11,O8/O11) -> 1042128.6 | P16: =IF(P8="-",$H8/P11,P8/P11) -> 1046756.4
C18: Total spending attributable to different actors
E19: Total spending contributed by grantee | F19: $ | G19: calc | H19: - | I19: =I11*I$16 -> 1000000 | J19: =J11*J$16 -> 1000000 | K19: =K11*K$16 -> 1000000 | L19: =L11*L$16 -> 1000000 | M19: =M11*M$16 -> 1000000 | N19: =N11*N$16 -> 1000000 | O19: =O11*O$16 -> 1000000 | P19: =P11*P$16 -> 1000000
E20: Total spending contributed by other philanthropic actors | F20: $ | G20: calc | H20: - | I20: =I12*I$16 -> 0 | J20: =J12*J$16 -> 0 | K20: =K12*K$16 -> 0 | L20: =L12*L$16 -> 0 | M20: =M12*M$16 -> 0 | N20: =N12*N$16 -> 0 | O20: =O12*O$16 -> 0 | P20: =P12*P$16 -> 0
E21: Total spending contributed by domestic governments | F21: $ | G21: calc | H21: - | I21: =I13*I$16 -> 45713.688 | J21: =J13*J$16 -> 58302.745 | K21: =K13*K$16 -> 45713.688 | L21: =L13*L$16 -> 40216.54 | M21: =M13*M$16 -> 40216.54 | N21: =N13*N$16 -> 67466.092 | O21: =O13*O$16 -> 42128.568 | P21: =P13*P$16 -> 46756.411
C23: Upstream / downstream spending
E24: Total spending causally upstream of donations to grantee | F24: $ | G24: calc | H24: - | I24: =SUM(I19:I20) -> 1000000 | J24: =SUM(J19:J20) -> 1000000 | K24: =SUM(K19:K20) -> 1000000 | L24: =SUM(L19:L20) -> 1000000 | M24: =SUM(M19:M20) -> 1000000 | N24: =SUM(N19:N20) -> 1000000 | O24: =SUM(O19:O20) -> 1000000 | P24: =SUM(P19:P20) -> 1000000
E25: Total spending causally downstream of donations to grantee | F25: $ | G25: calc | H25: - | I25: =I21 -> 45713.688 | J25: =J21 -> 58302.745 | K25: =K21 -> 45713.688 | L25: =L21 -> 40216.54 | M25: =M21 -> 40216.54 | N25: =N21 -> 67466.092 | O25: =O21 -> 42128.568 | P25: =P21 -> 46756.411
C27: Cost per net
E28: Total cost per insecticide-treated net (ITN) distributed | F28: =Inputs!F16 -> $ | G28: input | H28: =Inputs!H16 -> - | I28: =Inputs!I16 -> 3.93785 | J28: =Inputs!J16 -> 5.85033 | K28: =Inputs!K16 -> 3.93785 | L28: =Inputs!L16 -> 4.34117 | M28: =Inputs!M16 -> 4.34117 | N28: =Inputs!N16 -> 5.32824 | O28: =Inputs!O16 -> 3.66624 | P28: =Inputs!P16 -> 4.44504
E29: Upstream costs per ITN distributed | F29: $ | G29: calc | H29: - | I29: =(I24/I16)*I28 -> 3.7657057 | J29: =(J24/J16)*J28 -> 5.5280306 | K29: =(K24/K16)*K28 -> 3.7657057 | L29: =(L24/L16)*L28 -> 4.173333 | M29: =(M24/M16)*M28 -> 4.173333 | N29: =(N24/N16)*N28 -> 4.9914846 | O29: =(O24/O16)*O28 -> 3.5180304 | P29: =(P24/P16)*P28 -> 4.2464894
A31: Outputs
C33: Net usage
E34: Number of nets distributed | F34: # | G34: calc | H34: - | I34: =I19/I29 -> 265554.47 | J34: =J19/J29 -> 180896.25 | K34: =K19/K29 -> 265554.47 | L34: =L19/L29 -> 239616.63 | M34: =M19/M29 -> 239616.63 | N34: =N19/N29 -> 200341.2 | O34: =O19/O29 -> 284249.96 | P34: =P19/P29 -> 235488.64
E35: Proportion of distributed nets that were used in trials from the Pryce et al. 2018 meta-analysis | F35: =Inputs!F21 -> % | G35: input | H35: =Inputs!H21 -> 0.7 | I35: =Inputs!I21 -> - | J35: =Inputs!J21 -> - | K35: =Inputs!K21 -> - | L35: =Inputs!L21 -> - | M35: =Inputs!M21 -> - | N35: =Inputs!N21 -> - | O35: =Inputs!O21 -> - | P35: =Inputs!P21 -> -
E36: Adjustment for net usage in program contexts | F36: =Inputs!F22 -> % | G36: input | H36: =Inputs!H22 -> -0.1 | I36: =Inputs!I22 -> - | J36: =Inputs!J22 -> - | K36: =Inputs!K22 -> - | L36: =Inputs!L22 -> - | M36: =Inputs!M22 -> - | N36: =Inputs!N22 -> - | O36: =Inputs!O22 -> - | P36: =Inputs!P22 -> -
E37: Proportion of distributed nets that are used in program contexts | F37: % | G37: calc | H37: =H35*(1+H36) -> 0.63 | I37: - | J37: - | K37: - | L37: - | M37: - | N37: - | O37: - | P37: -
E38: Number of nets used | F38: # | G38: calc | H38: - | I38: =I34*$H37 -> 167299.32 | J38: =J34*$H37 -> 113964.64 | K38: =K34*$H37 -> 167299.32 | L38: =L34*$H37 -> 150958.48 | M38: =M34*$H37 -> 150958.48 | N38: =N34*$H37 -> 126214.95 | O38: =O34*$H37 -> 179077.47 | P38: =P34*$H37 -> 148357.84
C40: Net coverage
E41: Number of people sleeping under each used net | F41: =Inputs!F25 -> # | G41: input | H41: =Inputs!H25 -> - | I41: =Inputs!I25 -> 1.93645 | J41: =Inputs!J25 -> 2.15114 | K41: =Inputs!K25 -> 1.99095 | L41: =Inputs!L25 -> 1.93645 | M41: =Inputs!M25 -> 1.93645 | N41: =Inputs!N25 -> 1.93645 | O41: =Inputs!O25 -> 1.72163 | P41: =Inputs!P25 -> 1.76505
E42: Total people sleeping under distributed nets | F42: # | G42: calc | H42: - | I42: =I38*I41 -> 323966.77 | J42: =J38*J41 -> 245153.89 | K42: =K38*K41 -> 333084.58 | L42: =L38*L41 -> 292323.55 | M42: =M38*M41 -> 292323.55 | N42: =N38*N41 -> 244408.95 | O42: =O38*O41 -> 308305.15 | P42: =P38*P41 -> 261859.01
E43: Effective coverage years provided per net | F43: ='Effective coverage'!F145 -> # | G43: supp | H43: ='Effective coverage'!H145 -> - | I43: ='Effective coverage'!I145 -> 1.9656086 | J43: ='Effective coverage'!J145 -> 1.1925167 | K43: ='Effective coverage'!K145 -> 1.9656086 | L43: ='Effective coverage'!L145 -> 1.9656086 | M43: ='Effective coverage'!M145 -> 1.317121 | N43: ='Effective coverage'!N145 -> 1.269016 | O43: ='Effective coverage'!O145 -> 1.9656086 | P43: ='Effective coverage'!P145 -> 1.9656086
E44: Total person-years of effective coverage provided | F44: # | G44: calc | H44: - | I44: =I42*I43 -> 636791.87 | J44: =J42*J43 -> 292350.09 | K44: =K42*K43 -> 654713.92 | L44: =L42*L43 -> 574593.68 | M44: =M42*M43 -> 385025.49 | N44: =N42*N43 -> 310158.86 | O44: =O42*O43 -> 606007.26 | P44: =P42*P43 -> 514712.32
C46: Age distribution of population
E47: Total national population | F47: =Inputs!F28 -> # | G47: =Inputs!G28 -> input | H47: =Inputs!H28 -> - | I47: =Inputs!I28 -> 16398860 | J47: =Inputs!J28 -> 87670444 | K47: =Inputs!K28 -> 12643149 | L47: =Inputs!L28 -> 2.1482379e+08 | M47: =Inputs!M28 -> 2.1482379e+08 | ... P47: =Inputs!P28 -> 41117856
E48: National population under age 5 | F48: =Inputs!F29 -> # | G48: =Inputs!G29 -> input | H48: =Inputs!H29 -> - | I48: =Inputs!I29 -> 3332666.6 | J48: =Inputs!J29 -> 13629465 | K48: =Inputs!K29 -> 2143394.9 | L48: =Inputs!L29 -> 33521638 | M48: =Inputs!M29 -> 33521638 | ... P48: =Inputs!P29 -> 7089749.8
E49: National population age 5-14 | F49: =Inputs!F30 -> # | G49: =Inputs!G30 -> input | H49: =Inputs!H30 -> - | I49: =Inputs!I30 -> 4977421 | J49: =Inputs!J30 -> 24065680 | K49: =Inputs!K30 -> 3569794.5 | L49: =Inputs!L30 -> 60226437 | M49: =Inputs!M30 -> 60226437 | ... P49: =Inputs!P30 -> 11987722
E50: Proportion of population under age 5 | F50: # | G50: calc | H50: - | I50: =I48/I47 -> 0.20322551 | J50: =J48/J47 -> 0.15546249 | K50: =K48/K47 -> 0.16953015 | L50: =L48/L47 -> 0.15604249 | M50: =M48/M47 -> 0.15604249 | N50: =N48/N47 -> 0.16335034 | O50: =O48/O47 -> 0.14073742 | P50: =P48/P47 -> 0.17242508
...

Sheet Effective coverage
I1: Against Malaria Foundation
I2: Chad | J2: DRC | K2: Guinea | L2: Nigeria | M2: Nigeria | N2: South Sudan | O2: Togo | P2: Uganda
A3: Supplemental calculations for effective coverage years provided per net | F3: unit | G3: type | H3: Overall | L3: GF states | M3: PMI states
E4: Final cost-effectiveness estimate (pulled from "Main calcs" sheet for visibility) | F4: ='Main CEA'!F203 -> xbenchmark | G4: main | H4: ='Main CEA'!H203 -> - | I4: ='Main CEA'!I203 -> 4.8202994 | J4: ='Main CEA'!J203 -> 14.629025 | K4: ='Main CEA'!K203 -> 22.79223 | L4: ='Main CEA'!L203 -> 16.778736 | M4: ='Main CEA'!M203 -> 13.250427 | N4: ='Main CEA'!N203 -> 7.1630004 | O4: ='Main CEA'!O203 -> 8.8061654 | P4: ='Main CEA'!P203 -> 15.60304
A5: Net survival
C7: Net coverage years lost to attrition
E8: Percentage of nets remaining in use two years after the CTN distributions in trials from the Pryce et al. 2018 meta-analysis | F8: =Inputs!F35 -> % | G8: =Inputs!G35 -> input | H8: =Inputs!H35 -> 1 | I8: =Inputs!I35 -> - | J8: =Inputs!J35 -> - | K8: =Inputs!K35 -> - | L8: =Inputs!L35 -> - | M8: =Inputs!M35 -> - | ... P8: =Inputs!P35 -> -
E9: Average percentage of nets remaining in use during the 1st year after an ITN distribution | F9: =Inputs!F36 -> % | G9: =Inputs!G36 -> input | H9: =Inputs!H36 -> 0.9539455 | I9: =Inputs!I36 -> - | J9: =Inputs!J36 -> - | K9: =Inputs!K36 -> - | L9: =Inputs!L36 -> - | M9: =Inputs!M36 -> - | ... P9: =Inputs!P36 -> -
E10: Average percentage of nets remaining in use during the 2nd year after an ITN distribution | F10: =Inputs!F37 -> % | G10: =Inputs!G37 -> input | H10: =Inputs!H37 -> 0.8345774 | I10: =Inputs!I37 -> - | J10: =Inputs!J37 -> - | K10: =Inputs!K37 -> - | L10: =Inputs!L37 -> - | M10: =Inputs!M37 -> - | ... P10: =Inputs!P37 -> -
E11: =Inputs!E38 -> Average percentage of nets remaining in use during the 3rd year after an ITN distribution | F11: =Inputs!F38 -> % | G11: =Inputs!G38 -> input | H11: =Inputs!H38 -> 0.6935533 | I11: =Inputs!I38 -> - | J11: =Inputs!J38 -> - | K11: =Inputs!K38 -> - | L11: =Inputs!L38 -> - | ... P11: =Inputs!P38 -> -
C13: Net coverage years lost due to physical decay
E14: Percentage of remaining nets lost due to physical damage at the midpoint of the 1st year after an ITN distribution | F14: =Inputs!F41 -> % | G14: =Inputs!G41 -> input | H14: =Inputs!H41 -> 0.0346098 | I14: =Inputs!I41 -> - | J14: =Inputs!J41 -> - | K14: =Inputs!K41 -> - | L14: =Inputs!L41 -> - | M14: =Inputs!M41 -> - | ... P14: =Inputs!P41 -> -
E15: Percentage of remaining nets lost due to physical damage at the midpoint of the 2nd year after an ITN distribution | F15: =Inputs!F42 -> % | G15: =Inputs!G42 -> input | H15: =Inputs!H42 -> 0.1536925 | I15: =Inputs!I42 -> - | J15: =Inputs!J42 -> - | K15: =Inputs!K42 -> - | L15: =Inputs!L42 -> - | M15: =Inputs!M42 -> - | ... P15: =Inputs!P42 -> -
E16: Percentage of remaining nets lost due to physical damage at the midpoint of the 3rd year after an ITN distribution | F16: =Inputs!F43 -> % | G16: =Inputs!G43 -> input | H16: =Inputs!H43 -> 0.3453212 | I16: =Inputs!I43 -> - | J16: =Inputs!J43 -> - | K16: =Inputs!K43 -> - | L16: =Inputs!L43 -> - | M16: =Inputs!M43 -> - | ... P16: =Inputs!P43 -> -
E17: Ratio of physical net decay in trials of CTN distributions from the Pryce et al. 2018 meta-analysis compared to physical net decay from grantee ITN distributions | F17: =Inputs!F44 -> % | G17: =Inputs!G44 -> input | H17: =Inputs!H44 -> 0.33 | I17: =Inputs!I44 -> - | J17: =Inputs!J44 -> - | K17: =Inputs!K44 -> - | L17: =Inputs!L44 -> - | M17: =Inputs!M44 -> - | ... P17: =Inputs!P44 -> -
E18: Percentage of remaining nets lost due to physical damage at the midpoint of the 1st year after a CTN distribution from the Pryce et al. 2018 meta-analysis | F18: % | G18: calc | H18: =H14*(1-H$17) -> 0.023188566 | I18: - | J18: - | K18: - | L18: - | M18: - | N18: - | O18: - | P18: -
E19: Percentage of remaining nets lost due to physical damage at the midpoint of the 2nd year after a CTN distribution from the Pryce et al. 2018 meta-analysis | F19: % | G19: calc | H19: =H15*(1-H$17) -> 0.10297397 | I19: - | J19: - | K19: - | L19: - | M19: - | N19: - | O19: - | P19: -
E20: Average percentage of remaining nets lost due to physical damage over the two-year period following a CTN distribution from the Pryce et al. 2018 meta-analysis | F20: % | G20: calc | H20: =AVERAGE(H18:H19) -> 0.06308127 | I20: - | J20: - | K20: - | L20: - | M20: - | N20: - | O20: - | P20: -
C22: Net coverage years lost due to insecticide decay
E23: Proportion of net coverage lost due to insecticide decay for CTNs distributed in trials from the Pryce et al. 2018 meta-analysis | F23: =Inputs!F47 -> % | G23: =Inputs!G47 -> input | H23: =Inputs!H47 -> 0 | I23: =Inputs!I47 -> - | J23: =Inputs!J47 -> - | K23: =Inputs!K47 -> - | L23: =Inputs!L47 -> - | M23: =Inputs!M47 -> - | ... P23: =Inputs!P47 -> -
E24: Proportion of net coverage lost due to insecticide decay for ITNs distributed in grantee distributions | F24: =Inputs!F48 -> % | G24: =Inputs!G48 -> input | H24: =Inputs!H48 -> 0 | I24: =Inputs!I48 -> - | J24: =Inputs!J48 -> - | K24: =Inputs!K48 -> - | L24: =Inputs!L48 -> - | M24: =Inputs!M48 -> - | ... P24: =Inputs!P48 -> -
C26: Total net coverage years lost
E27: Coverage years lost per year for CTNs distributed in trials from the Pryce et al. 2018 meta-analysis | F27: # | G27: calc | H27: =(1-H8)+(H8*H20)+(H8*H20*H23) -> 0.06308127 | I27: - | J27: - | K27: - | L27: - | M27: - | N27: - | O27: - | P27: -
E28: Coverage years lost during the 1st year after a grantee ITN distribution | F28: # | G28: calc | H28: =(1-H9)+(H9*H14)+(H9*H14*H$24) -> 0.079070363 | I28: - | J28: - | K28: - | L28: - | M28: - | N28: - | O28: - | P28: -
E29: Coverage years lost during the 2nd year after a grantee ITN distribution | F29: # | G29: calc | H29: =(1-H10)+(H10*H15)+(H10*H15*H$24) -> 0.29369089 | I29: - | J29: - | K29: - | L29: - | M29: - | N29: - | O29: - | P29: -
E30: Coverage years lost during the 3rd year after a grantee ITN distribution | F30: # | G30: calc | H30: =(1-H11)+(H11*H16)+(H11*H16*H$24) -> 0.54594536 | I30: - | J30: - | K30: - | L30: - | M30: - | N30: - | O30: - | P30: -
C32: Trial-equivalent coverage years provided per distributed net
E33: Effective net coverage years provided by a CTN distributed in a trial from the Pryce et al. 2018 meta-analysis (reference value) | F33: =Inputs!F51 -> # | G33: =Inputs!G51 -> input | H33: =Inputs!H51 -> 1 | I33: =Inputs!I51 -> - | J33: =Inputs!J51 -> - | K33: =Inputs!K51 -> - | L33: =Inputs!L51 -> - | M33: =Inputs!M51 -> - | ... P33: =Inputs!P51 -> -
E34: Effective coverage years provided per net in the 1st year after a grantee ITN distribution | F34: # | G34: calc | H34: =H$33-(H28-H$27) -> 0.98401091 | I34: - | J34: - | K34: - | L34: - | M34: - | N34: - | O34: - | P34: -
E35: Effective coverage years provided per net in the 2nd year after a grantee ITN distribution | F35: # | G35: calc | H35: =H$33-(H29-H$27) -> 0.76939038 | I35: - | J35: - | K35: - | L35: - | M35: - | N35: - | O35: - | P35: -
E36: Effective coverage years provided per net in the 3rd year after a grantee ITN distribution | F36: # | G36: calc | H36: =H$33-(H30-H$27) -> 0.51713591 | I36: - | J36: - | K36: - | L36: - | M36: - | N36: - | O36: - | P36: -
E37: Total effective coverage years provided per net over the three-year period following a grantee ITN distribution for reference ITNs | F37: # | G37: calc | H37: =SUM(H34:H36) -> 2.2705372 | I37: - | J37: - | K37: - | L37: - | M37: - | N37: - | O37: - | P37: -
C39: Adjustment for generic ITNs
E40: Total effective coverage years provided per net over the three-year period following a grantee ITN distribution of reference ITNs | F40: # | G40: calc | H40: =H37 -> 2.2705372 | I40: - | J40: - | K40: - | L40: - | M40: - | N40: - | O40: - | P40: -
E41: Adjustment for reduced net coverage provided by generic ITNs | F41: =Inputs!F54 -> % | G41: =Inputs!G54 -> input | H41: =Inputs!H54 -> -0.15 | I41: =Inputs!I54 -> - | J41: =Inputs!J54 -> - | K41: =Inputs!K54 -> - | L41: =Inputs!L54 -> - | M41: =Inputs!M54 -> - | ... P41: =Inputs!P54 -> -
E42: Total effective coverage years provided per net over the three-year period following a grantee ITN distribution for generic ITNs | F42: # | G42: calc | H42: =H37*(1+H41) -> 1.9299566 | I42: - | J42: - | K42: - | L42: - | M42: - | N42: - | O42: - | P42: -
C44: Breakdown of net types purchased for distributions
E45: Expected proportion of ITNs purchased that are generic ITNs | F45: =Inputs!F57 -> % | G45: =Inputs!G57 -> input | H45: =Inputs!H57 -> 0.465547 | I45: =Inputs!I57 -> - | J45: =Inputs!J57 -> - | K45: =Inputs!K57 -> - | L45: =Inputs!L57 -> - | M45: =Inputs!M57 -> - | ... P45: =Inputs!P57 -> -
C47: Effective coverage years per net, incorporating generic ITNs
E48: Overall effective coverage years provided per net over the three-year period following a grantee ITN distribution, before adjusting for lower net durability in DRC | F48: # | G48: calc | H48: =H40*(1-H45)+(H42*H45) -> 2.1119809 | I48: - | J48: - | K48: - | L48: - | M48: - | N48: - | O48: - | P48: -
...

Sheet Counterfactual malaria
I1: Against Malaria Foundation
I2: Chad | J2: DRC | K2: Guinea | L2: Nigeria | M2: Nigeria | N2: South Sudan | O2: Togo | P2: Uganda
A3: Supplemental calculations for counterfactual malaria mortality and incidence | F3: unit | G3: type | H3: Overall | L3: GF states | M3: PMI states
E4: Final cost-effectiveness estimate (pulled from "Main calcs" sheet for visibility) | F4: ='Main CEA'!F203 -> xbenchmark | G4: main | H4: ='Main CEA'!H203 -> - | I4: ='Main CEA'!I203 -> 4.8202994 | J4: ='Main CEA'!J203 -> 14.629025 | K4: ='Main CEA'!K203 -> 22.79223 | L4: ='Main CEA'!L203 -> 16.778736 | M4: ='Main CEA'!M203 -> 13.250427 | N4: ='Main CEA'!N203 -> 7.1630004 | O4: ='Main CEA'!O203 -> 8.8061654 | P4: ='Main CEA'!P203 -> 15.60304
A5: Counterfactual malaria mortality among 1-59-month-olds
C7: Population estimates
E8: Population age 1-11 months (2019) | F8: =Inputs!F85 -> # | G8: =Inputs!G85 -> input | H8: =Inputs!H85 -> - | I8: =Inputs!I85 -> 679765.58 | J8: =Inputs!J85 -> 2588275.6 | K8: =Inputs!K85 -> 418381.76 | L8: =Inputs!L85 -> 3254748 | M8: =Inputs!M85 -> 1982320 | ... P8: =Inputs!P85 -> 1389726.8
E9: Population age 12-59 months (2019) | F9: =Inputs!F86 -> # | G9: =Inputs!G86 -> input | H9: =Inputs!H86 -> - | I9: =Inputs!I86 -> 2593740.2 | J9: =Inputs!J86 -> 10821149 | K9: =Inputs!K86 -> 1689051.3 | L9: =Inputs!L86 -> 12757890 | M9: =Inputs!M86 -> 7939853 | ... P9: =Inputs!P86 -> 5581405.2
C11: Baseline malaria mortality
E12: Annual malaria mortality rate among 1-11-month-olds (2019) | F12: =Inputs!F89 -> per 100k | G12: =Inputs!G89 -> input | H12: =Inputs!H89 -> - | I12: =Inputs!I89 -> 206.31696 | J12: =Inputs!J89 -> 676.67097 | K12: =Inputs!K89 -> 597.02458 | L12: =Inputs!L89 -> 279.38 | M12: =Inputs!M89 -> 339.26 | ... P12: =Inputs!P89 -> 535.97224
E13: Annual malaria mortality rate among 12-59-month-olds (2019) | F13: =Inputs!F90 -> per 100k | G13: =Inputs!G90 -> input | H13: =Inputs!H90 -> - | I13: =Inputs!I90 -> 112.39657 | J13: =Inputs!J90 -> 216.90017 | K13: =Inputs!K90 -> 310.51042 | L13: =Inputs!L90 -> 268.21 | M13: =Inputs!M90 -> 278.52 | ... P13: =Inputs!P90 -> 160.12047
E14: Total malaria deaths among children aged 1-59 months per year (2019) | F14: # | G14: calc | H14: - | I14: =(I12*I8+I13*I9)/100000 -> 4317.7465 | J14: =(J12*J8+J13*J9)/100000 -> 40985.199 | K14: =(K12*K8+K13*K9)/100000 -> 7742.5222 | L14: =(L12*L8+L13*L9)/100000 -> 43311.052 | M14: =(M12*M8+M13*M9)/100000 -> 28839.297 | N14: =(N12*N8+N13*N9)/100000 -> 3747.2961 | O14: =(O12*O8+O13*O9)/100000 -> 1798.2641 | P14: =(P12*P8+P13*P9)/100000 -> 16385.522
E15: Annual malaria mortality rate among 1-59-month-olds (2019) | F15: % | G15: calc | H15: - | I15: =I14/SUM(I8:I9) -> 0.0013189977 | J15: =J14/SUM(J8:J9) -> 0.0030564473 | K15: =K14/SUM(K8:K9) -> 0.0036739114 | L15: =L14/SUM(L8:L9) -> 0.0027048043 | M15: =M14/SUM(M8:M9) -> 0.0029065506 | N15: =N14/SUM(N8:N9) -> 0.0025161796 | O15: =O14/SUM(O8:O9) -> 0.0016391362 | P15: =P14/SUM(P8:P9) -> 0.0023504822
C17: Adjusting for deaths averted by seasonal malaria chemoprevention (SMC)
E18: Target population of 3-59 month-olds for seasonal malaria chemoprevention programs (SMC) | F18: =Inputs!F93 -> # | G18: =Inputs!G93 -> input | H18: =Inputs!H93 -> - | I18: =Inputs!I93 -> - | J18: =Inputs!J93 -> - | K18: =Inputs!K93 -> - | L18: =Inputs!L93 -> 6450000 | M18: =Inputs!M93 -> 8960943 | ... P18: =Inputs!P93 -> -
E19: Total population age 1-59 months | F19: # | G19: calc | H19: - | I19: - | J19: - | K19: - | L19: =SUM(L8:L9) -> 16012638 | M19: =SUM(M8:M9) -> 9922173 | N19: =SUM(N8:N9) -> 1489280.1 | O19: =SUM(O8:O9) -> 1097080.4 | P19: -
E20: Proportion of total population age 1-59 months living in areas where SMC is implemented (calculated) | F20: % | G20: calc | H20: =IF(H18="-","-",H18/H19) -> - | I20: =IF(I18="-","-",I18/I19) -> - | J20: =IF(J18="-","-",J18/J19) -> - | K20: =IF(K18="-","-",K18/K19) -> - | L20: =IF(L18="-","-",L18/L19) -> 0.40280683 | M20: =IF(M18="-","-",M18/M19) -> 0.90312304 | N20: =IF(N18="-","-",N18/N19) -> - | O20: =IF(O18="-","-",O18/O19) -> 0.44664003 | P20: =IF(P18="-","-",P18/P19) -> -
E21: Proportion of total population age 1-59 months living in areas where SMC is implemented | F21: =Inputs!F94 -> % | G21: =Inputs!G94 -> input | H21: =Inputs!H94 -> - | I21: =Inputs!I94 -> - | J21: =Inputs!J94 -> - | K21: =Inputs!K94 -> - | L21: =Inputs!L94 -> - | M21: =Inputs!M94 -> - | ... Q21: =Inputs!Q94
E22: Probability that available bed nets would be targeted across the country evenly in the absence of grantee support | F22: =Inputs!F95 -> % | G22: =Inputs!G95 -> input | H22: =Inputs!H95 -> - | I22: =Inputs!I95 -> - | J22: =Inputs!J95 -> - | K22: =Inputs!K95 -> - | L22: =Inputs!L95 -> - | M22: =Inputs!M95 -> - | N22: - | O22: =Inputs!O95 -> 0.7 | P22: =Inputs!P95 -> -
E23: Probability that available bed nets would be targeted at non-SMC areas in the absence of grantee support | F23: =Inputs!F96 -> % | G23: =Inputs!G96 -> input | H23: =Inputs!H96 -> - | I23: =Inputs!I96 -> - | J23: =Inputs!J96 -> - | K23: =Inputs!K96 -> - | L23: =Inputs!L96 -> - | M23: =Inputs!M96 -> - | N23: - | O23: =Inputs!O96 -> 0.3 | P23: =Inputs!P96 -> -
E24: Proportion of counterfactually distributed nets distributed in areas where SMC is implemented | F24: % | G24: calc | H24: - | I24: 1 | J24: =IF(J22="-",IF(J20="-",IF(J21="-","-",J21),J20),(J20*J22)+J23) -> - | K24: =IF(K22="-",IF(K20="-",IF(K21="-","-",K21),K20),(K20*K22)+K23) -> - | L24: =IF(L22="-",IF(L20="-",IF(L21="-","-",L21),L20),(L20*L22)+L23) -> 0.40280683 | M24: =IF(M22="-",IF(M20="-",IF(M21="-","-",M21),M20),(M20*M22)+M23) -> 0.90312304 | N24: =IF(N22="-",IF(N20="-",IF(N21="-","-",N21),N20),(N20*N22)+N23) -> 0.3 | O24: =IF(O22="-",IF(O20="-",IF(O21="-","-",O21),O20),(O20*O22)+O23) -> 0.61264802 | P24: =IF(P22="-",IF(P20="-",IF(P21="-","-",P21),P20),(P20*P22)+P23) -> -
E25: Malaria-attributable deaths averted by SMC per year among 1-59-month-olds living in areas where SMC is implemented | F25: =Inputs!F97 -> per 1k | G25: =Inputs!G97 -> input | H25: =Inputs!H97 -> - | I25: =Inputs!I97 -> 0.91339 | J25: =Inputs!J97 -> 0 | K25: =Inputs!K97 -> 0 | L25: =Inputs!L97 -> 1.57538 | M25: =Inputs!M97 -> 1.57538 | ... P25: =Inputs!P97 -> 0
E26: Malaria-attributable mortality reduction as a result of seasonal malaria chemoprevention (SMC) | F26: ppt | G26: calc | H26: - | I26: =IF(I24="-",0,(I24*I25/1000)) -> 0.00091339 | J26: =IF(J24="-",0,(J24*J25/1000)) -> 0 | K26: =IF(K24="-",0,(K24*K25/1000)) -> 0 | L26: =IF(L24="-",0,(L24*L25/1000)) -> 0.00063457383 | M26: =IF(M24="-",0,(M24*M25/1000)) -> 0.001422762 | N26: =IF(N24="-",0,(N24*N25/1000)) -> 0.000434442 | O26: =IF(O24="-",0,(O24*O25/1000)) -> 0.00071024897 | P26: =IF(P24="-",0,(P24*P25/1000)) -> 0
A28: Counterfactual malaria incidence
C30: Malaria incidence among people under age 15
E31: Malaria incidence among people under age 5 | F31: =Inputs!F100 -> per 100k | G31: =Inputs!G100 -> input | H31: =Inputs!H100 -> - | I31: =Inputs!I100 -> 22099.7 | J31: =Inputs!J100 -> 87914.34 | K31: =Inputs!K100 -> 71510.277 | L31: =Inputs!L100 -> 61766.056 | M31: =Inputs!M100 -> 75404.464 | ... P31: =Inputs!P100 -> 65525.524
E32: Malaria incidence among people age 5 to 14 | F32: =Inputs!F101 -> per 100k | G32: =Inputs!G101 -> input | H32: =Inputs!H101 -> - | I32: =Inputs!I101 -> 22099.7 | J32: =Inputs!J101 -> 35845.966 | K32: =Inputs!K101 -> 29839.074 | L32: =Inputs!L101 -> 26873.555 | M32: =Inputs!M101 -> 32080.311 | ... P32: =Inputs!P101 -> 27394.999
E33: Expected reduction in malaria incidence among people under age 5 sleeping under nets | F33: ='Main CEA'!F67 -> % | G33: main | H33: ='Main CEA'!H67 -> - | I33: ='Main CEA'!I67 -> 0.24020784 | J33: ='Main CEA'!J67 -> 0.55831846 | K33: ='Main CEA'!K67 -> 0.46006843 | L33: ='Main CEA'!L67 -> 0.50167397 | M33: ='Main CEA'!M67 -> 0.50167397 | N33: ='Main CEA'!N67 -> 0.40188586 | O33: ='Main CEA'!O67 -> 0.38926519 | P33: ='Main CEA'!P67 -> 0.51346742
E34: Baseline proportion of 1-59-month-old children sleeping under nets | F34: =Inputs!F137 -> % | G34: =Inputs!G137 -> input | H34: =Inputs!H137 -> - | I34: =Inputs!I137 -> 0.313 | J34: =Inputs!J137 -> 0.591 | K34: =Inputs!K137 -> 0.586 | L34: =Inputs!L137 -> 0.51 | M34: =Inputs!M137 -> 0.471 | ... P34: =Inputs!P137 -> 0.704
E35: Expected increase in malaria incidence in the absence of an ITN distribution | F35: % | G35: calc | H35: - | I35: =1/((1-I33)*I34+(1-I34))-1 -> 0.081297403 | J35: =1/((1-J33)*J34+(1-J34))-1 -> 0.49246205 | K35: =1/((1-K33)*K34+(1-K34))-1 -> 0.369113 | L35: =1/((1-L33)*L34+(1-L34))-1 -> 0.34382182 | M35: =1/((1-M33)*M34+(1-M34))-1 -> 0.30939487 | N35: =1/((1-N33)*N34+(1-N34))-1 -> 0.24770985 | O35: =1/((1-O33)*O34+(1-O34))-1 -> 0.44815425 | P35: =1/((1-P33)*P34+(1-P34))-1 -> 0.56612426
E36: Malaria incidence among people under age 5 in the absence of a distribution | F36: % | G36: calc | H36: - | I36: =I31*(1+I$35)/100000 -> 0.23896348 | J36: =J31*(1+J$35)/100000 -> 1.3120882 | K36: =K31*(1+K$35)/100000 -> 0.9790565 | L36: =L31*(1+L$35)/100000 -> 0.83002573 | M36: =M31*(1+M$35)/100000 -> 0.98734218 | N36: =N31*(1+N$35)/100000 -> 0.73521426 | O36: =O31*(1+O$35)/100000 -> 1.0648694 | P36: =P31*(1+P$35)/100000 -> 1.0262111
E37: Malaria incidence among people age 5 to 14 in the absence of a distribution | F37: % | G37: calc | H37: - | I37: =I32*(1+I$35)/100000 -> 0.23896348 | J37: =J32*(1+J$35)/100000 -> 0.53498743 | K37: =K32*(1+K$35)/100000 -> 0.40853064 | L37: =L32*(1+L$35)/100000 -> 0.3611327 | M37: =M32*(1+M$35)/100000 -> 0.42005795 | N37: =N32*(1+N$35)/100000 -> 0.31164979 | O37: =O32*(1+O$35)/100000 -> 0.44668425 | P37: =P32*(1+P$35)/100000 -> 0.42903972

Sheet Insecticide resistance
I1: Against Malaria Foundation
I2: Chad | J2: DRC | K2: Guinea | L2: Nigeria | M2: Nigeria | N2: South Sudan | O2: Togo | P2: Uganda
A3: Supplemental calculations for the insecticide resistance adjustment | F3: unit | G3: type | H3: Overall | L3: GF states | M3: PMI states
E4: Final cost-effectiveness estimate (pulled from "Main calcs" sheet for visibility) | F4: ='Main CEA'!F203 -> xbenchmark | G4: main | H4: ='Main CEA'!H203 -> - | I4: ='Main CEA'!I203 -> 4.8202994 | J4: ='Main CEA'!J203 -> 14.629025 | K4: ='Main CEA'!K203 -> 22.79223 | L4: ='Main CEA'!L203 -> 16.778736 | M4: ='Main CEA'!M203 -> 13.250427 | N4: ='Main CEA'!N203 -> 7.1630004 | O4: ='Main CEA'!O203 -> 8.8061654 | P4: ='Main CEA'!P203 -> 15.60304
A5: Insecticide resistance for standard nets
C7: Resistance to pyrethroid insecticides
E8: Average mosquito mortality rate found in pyrethroid bioassays (2015-2019) | F8: =Inputs!F106 -> % | G8: =Inputs!G106 -> input | H8: =Inputs!H106 -> - | I8: =Inputs!I106 -> 0.2369133 | J8: =Inputs!J106 -> 0.5206558 | K8: =Inputs!K106 -> 0.7017647 | L8: =Inputs!L106 -> 0.7498112 | M8: =Inputs!M106 -> 0.7498112 | ... P8: =Inputs!P106 -> 0.4379605
E9: Average year pyrethroid bioassays were conducted | F9: =Inputs!F107 -> year | G9: =Inputs!G107 -> input | H9: =Inputs!H107 -> - | I9: =Inputs!I107 -> 2014.93 | J9: =Inputs!J107 -> 2016.56 | K9: =Inputs!K107 -> 2016.97 | L9: =Inputs!L107 -> 2017.41 | M9: =Inputs!M107 -> 2017.41 | ... P9: =Inputs!P107 -> 2016.11
E10: Expected year of ITN distribution | F10: =Inputs!F108 -> year | G10: =Inputs!G108 -> input | H10: =Inputs!H108 -> - | I10: =Inputs!I108 -> 2026 | J10: =Inputs!J108 -> 2024 | K10: =Inputs!K108 -> 2025 | L10: =Inputs!L108 -> 2023 | M10: =Inputs!M108 -> 2023 | ... P10: =Inputs!P108 -> 2023
E11: Number of years between bioassay data collection and the expected year of ITN distribution | F11: # | G11: calc | H11: - | I11: =I10-I9 -> 11.07 | J11: =J10-J9 -> 7.44 | K11: =K10-K9 -> 8.03 | L11: =L10-L9 -> 5.59 | M11: =M10-M9 -> 5.59 | N11: =N10-N9 -> 3 | O11: =O10-O9 -> 7.53 | P11: =P10-P9 -> 6.89
E12: Expected annual change in mosquito mortality rates over time | F12: =Inputs!F109 -> ppt | G12: =Inputs!G109 -> input | H12: =Inputs!H109 -> -0.0083333333 | I12: =Inputs!I109 -> - | J12: =Inputs!J109 -> - | K12: =Inputs!K109 -> - | L12: =Inputs!L109 -> - | M12: =Inputs!M109 -> - | ... P12: =Inputs!P109 -> -
E13: Estimated change in mosquito mortality rates between bioassay data collection and the expected year of ITN distribution | F13: % | G13: calc | H13: - | I13: =$H12*I11 -> -0.09225 | J13: =$H12*J11 -> -0.062 | K13: =$H12*K11 -> -0.066916667 | L13: =$H12*L11 -> -0.046583333 | M13: =$H12*M11 -> -0.046583333 | N13: =$H12*N11 -> -0.025 | O13: =$H12*O11 -> -0.06275 | P13: =$H12*P11 -> -0.057416667
E14: Estimated mosquito mortality rate in the year of ITN distribution | F14: % | G14: calc | H14: - | I14: =MAX(I8+I13,0) -> 0.1446633 | J14: =MAX(J8+J13,0) -> 0.4586558 | K14: =MAX(K8+K13,0) -> 0.63484803 | L14: =MAX(L8+L13,0) -> 0.70322787 | M14: =MAX(M8+M13,0) -> 0.70322787 | N14: =MAX(N8+N13,0) -> 0.492 | O14: =MAX(O8+O13,0) -> 0.1657974 | P14: =MAX(P8+P13,0) -> 0.38054383
C16: Role of insecticide in the protective effect of nets
E17: Proportion of the protective effect of ITNs that is due to the physical barrier of the net | F17: =Inputs!F112 -> % | G17: =Inputs!G112 -> input | H17: =Inputs!H112 -> 0.2702179 | I17: =Inputs!I112 -> - | J17: =Inputs!J112 -> - | K17: =Inputs!K112 -> - | L17: =Inputs!L112 -> - | M17: =Inputs!M112 -> - | ... P17: =Inputs!P112 -> -
E18: Proportion of the protective effect of ITNs that is due to pyrethroid insecticide | F18: % | G18: calc | H18: =1-H17 -> 0.7297821 | I18: - | J18: - | K18: - | L18: - | M18: - | N18: - | O18: - | P18: -
C20: ITN effectiveness compared to trial contexts
E21: Effectiveness of ITNs in upcoming distributions relative to nets in studies included in Cochrane reviews | F21: % | G21: calc | H21: - | I21: =$H17+(I14*$H18) -> 0.37579059 | J21: =$H17+(J14*$H18) -> 0.60493669 | K21: =$H17+(K14*$H18) -> 0.73351863 | L21: =$H17+(L14*$H18) -> 0.78342101 | M21: =$H17+(M14*$H18) -> 0.78342101 | N21: =$H17+(N14*$H18) -> 0.62927069 | O21: =$H17+(O14*$H18) -> 0.39121387 | P21: =$H17+(P14*$H18) -> 0.54793198
E22: Reduction in effectiveness caused by resistance to pyrethroid insecticide | F22: % | G22: calc | H22: - | I22: =1-I21 -> 0.62420941 | J22: =1-J21 -> 0.39506331 | K22: =1-K21 -> 0.26648137 | L22: =1-L21 -> 0.21657899 | M22: =1-M21 -> 0.21657899 | N22: =1-N21 -> 0.37072931 | O22: =1-O21 -> 0.60878613 | P22: =1-P21 -> 0.45206802
A24: Insecticide resistance for PBO nets
C26: Resistance to pyrethroid insecticides plus a piperonyl-butoxide (PBO) synergist
E27: Average mosquito mortality rate found in bioassays of pyrethroid plus PBO (2015-2019) | F27: =Inputs!F115 -> % | G27: =Inputs!G115 -> input | H27: =Inputs!H115 -> - | I27: =Inputs!I115 -> 0.54575 | J27: =Inputs!J115 -> 0.9597 | K27: =Inputs!K115 -> 0.8975 | L27: =Inputs!L115 -> 0.9255039 | M27: =Inputs!M115 -> 0.9255039 | ... P27: =Inputs!P115 -> 0.9541395
E28: Average mosquito mortality rate found in the same bioassays of pyrethroid only | F28: =Inputs!F116 -> % | G28: =Inputs!G116 -> input | H28: =Inputs!H116 -> - | I28: =Inputs!I116 -> 0.4292125 | J28: =Inputs!J116 -> 0.5559 | K28: =Inputs!K116 -> 0.6 | L28: =Inputs!L116 -> 0.691197 | M28: =Inputs!M116 -> 0.691197 | ... P28: =Inputs!P116 -> 0.5084116
E29: Initial proportion of resistance that remains when using PBO | F29: % | G29: calc | H29: - | I29: =(1-I27)/(1-I28) -> 0.79583032 | J29: =(1-J27)/(1-J28) -> 0.090745328 | K29: =(1-K27)/(1-K28) -> 0.25625 | L29: =(1-L27)/(1-L28) -> 0.2412415 | M29: =(1-M27)/(1-M28) -> 0.2412415 | N29: =(1-N27)/(1-N28) -> 0.099602731 | O29: =(1-O27)/(1-O28) -> 0.081035453 | P29: =(1-P27)/(1-P28) -> 0.093290444
E30: Reduction in effectiveness due to insecticide resistance in areas where PBO nets are effective | F30: % | G30: calc | H30: - | I30: =I22*I29 -> 0.49676478 | J30: =J22*J29 -> 0.035850149 | K30: =K22*K29 -> 0.068285851 | L30: =L22*L29 -> 0.052247841 | M30: =M22*M29 -> 0.052247841 | N30: =N22*N29 -> 0.036925651 | O30: =O22*O29 -> 0.049333259 | P30: =P22*P29 -> 0.042173626
C32: External validity adjustments for country representativeness
E33: Proportion of bioassay test sites with confirmed pyrethroid insecticide resistance (2015-2019) | F33: =Inputs!F117 -> % | G33: =Inputs!G117 -> input | H33: =Inputs!H117 -> - | I33: =Inputs!I117 -> 1 | J33: =Inputs!J117 -> 0.8051948 | K33: =Inputs!K117 -> 0.7647059 | L33: =Inputs!L117 -> 0.6246787 | M33: =Inputs!M117 -> 0.6246787 | ... P33: =Inputs!P117 -> 0.9868421
E34: Proportion of test sites detected to have relevant resistance mechanism (2015-2019) | F34: =Inputs!F118 -> % | G34: =Inputs!G118 -> input | H34: =Inputs!H118 -> - | I34: =Inputs!I118 -> 0.7142857 | J34: =Inputs!J118 -> 1 | K34: =Inputs!K118 -> 0.7916667 | L34: =Inputs!L118 -> 0.7916667 | M34: =Inputs!M118 -> 0.7916667 | ... P34: =Inputs!P118 -> 0.8333333
E35: Estimated proportion of country where PBO nets are more effective than standard ITNs | F35: % | G35: calc | H35: - | I35: =I33*I34 -> 0.7142857 | J35: =J33*J34 -> 0.8051948 | K35: =K33*K34 -> 0.6053922 | L35: =L33*L34 -> 0.49453733 | M35: =M33*M34 -> 0.49453733 | N35: =N33*N34 -> 0.81341373 | O35: =O33*O34 -> 0.7916667 | P35: =P33*P34 -> 0.82236838
A37: Insecticide resistance for Dual AI nets
C39: Resistance to insecticides used in Dual AI nets
E40: Reduction in effectiveness due to insecticide resistance with chlorfenapyr nets | F40: =Inputs!F121 -> % | G40: =Inputs!G121 -> input | H40: =Inputs!H121 -> 0 | I40: =Inputs!I121 -> - | J40: =Inputs!J121 -> - | K40: =Inputs!K121 -> - | L40: =Inputs!L121 -> - | M40: =Inputs!M121 -> - | ... P40: =Inputs!P121 -> -
E41: Reduction in effectiveness due to insecticide resistance with other Dual AI nets | F41: % | G41: calc | H41: =H22 -> - | I41: =I22 -> 0.62420941 | J41: =J22 -> 0.39506331 | K41: =K22 -> 0.26648137 | L41: =L22 -> 0.21657899 | M41: =M22 -> 0.21657899 | N41: =N22 -> 0.37072931 | O41: =O22 -> 0.60878613 | P41: =P22 -> 0.45206802
A43: Insecticide resistance adjustment
C45: Breakdown of nets purchased
E46: Expected proportion of standard ITNs purchased for distributions | F46: =Inputs!F127 -> % | G46: =Inputs!G127 -> input | H46: =Inputs!H127 -> - | I46: =Inputs!I127 -> 0.7 | J46: =Inputs!J127 -> 0 | K46: =Inputs!K127 -> 0.7 | L46: =Inputs!L127 -> 0 | M46: =Inputs!M127 -> 0 | ... P46: =Inputs!P127 -> 0
E47: Expected proportion of PBO nets purchased for distributions | F47: =Inputs!F124 -> % | G47: =Inputs!G124 -> input | H47: =Inputs!H124 -> - | I47: =Inputs!I124 -> 0.3 | J47: =Inputs!J124 -> 0.5 | K47: =Inputs!K124 -> 0.3 | L47: =Inputs!L124 -> 1 | M47: =Inputs!M124 -> 1 | ... P47: =Inputs!P124 -> 1
E48: Expected proportion of chlorfenapyr nets purchased for distributions | F48: =Inputs!F125 -> % | G48: =Inputs!G125 -> input | H48: =Inputs!H125 -> - | I48: =Inputs!I125 -> 0 | J48: =Inputs!J125 -> 0.45 | K48: =Inputs!K125 -> 0 | L48: =Inputs!L125 -> 0 | M48: =Inputs!M125 -> 0 | ... P48: =Inputs!P125 -> 0
E49: Expected proportion of other Dual AI nets purchased for distributions | F49: =Inputs!F126 -> % | G49: =Inputs!G126 -> input | H49: =Inputs!H126 -> - | I49: =Inputs!I126 -> 0 | J49: =Inputs!J126 -> 0.05 | K49: =Inputs!K126 -> 0 | L49: =Inputs!L126 -> 0 | M49: =Inputs!M126 -> 0 | ... P49: =Inputs!P126 -> 0
C51: Final net breakdown
...

Sheet LeverageFunging
I1: Against Malaria Foundation
I2: Chad | J2: DRC | K2: Guinea | L2: Nigeria | M2: Nigeria | N2: South Sudan | O2: Togo | P2: Uganda
A3: Supplemental calculations for the leverage/funging adjustment | F3: unit | G3: type | H3: Overall | L3: GF states | M3: PMI states
E4: Final cost-effectiveness estimate (pulled from "Main calcs" sheet for visibility) | F4: ='Main CEA'!F203 -> xbenchmark | G4: main | H4: ='Main CEA'!H203 -> - | I4: ='Main CEA'!I203 -> 4.8202994 | J4: ='Main CEA'!J203 -> 14.629025 | K4: ='Main CEA'!K203 -> 22.79223 | L4: ='Main CEA'!L203 -> 16.778736 | M4: ='Main CEA'!M203 -> 13.250427 | N4: ='Main CEA'!N203 -> 7.1630004 | O4: ='Main CEA'!O203 -> 8.8061654 | P4: ='Main CEA'!P203 -> 15.60304
A5: Costs
C7: GiveWell costs
E8: Grant size | F8: =Inputs!F8 -> $ | G8: =Inputs!G8 -> input | H8: =Inputs!H8 -> 1000000 | I8: =Inputs!I8 -> - | J8: =Inputs!J8 -> - | K8: =Inputs!K8 -> - | L8: =Inputs!L8 -> - | M8: =Inputs!M8 -> - | ... P8: =Inputs!P8 -> -
C10: Cost breakdown
E11: Percentage of total costs covered by the grantee | F11: =Inputs!F11 -> % | G11: =Inputs!G11 -> input | H11: =Inputs!H11 -> - | I11: =Inputs!I11 -> 0.9562847 | J11: =Inputs!J11 -> 0.9449092 | K11: =Inputs!K11 -> 0.9562847 | L11: =Inputs!L11 -> 0.9613383 | M11: =Inputs!M11 -> 0.9613383 | ... P11: =Inputs!P11 -> 0.9553321
E12: Percentage of total costs covered by other philanthropic actors | F12: =Inputs!F12 -> % | G12: =Inputs!G12 -> input | H12: =Inputs!H12 -> - | I12: =Inputs!I12 -> 0 | J12: =Inputs!J12 -> 0 | K12: =Inputs!K12 -> 0 | L12: =Inputs!L12 -> 0 | M12: =Inputs!M12 -> 0 | ... P12: =Inputs!P12 -> 0
E13: Percentage of total costs covered by domestic governments | F13: =Inputs!F13 -> % | G13: =Inputs!G13 -> input | H13: =Inputs!H13 -> - | I13: =Inputs!I13 -> 0.0437153 | J13: =Inputs!J13 -> 0.0550908 | K13: =Inputs!K13 -> 0.0437153 | L13: =Inputs!L13 -> 0.0386617 | M13: =Inputs!M13 -> 0.0386617 | ... P13: =Inputs!P13 -> 0.0446679
C15: Total costs
E16: Total spending by all contributors | F16: ='Main CEA'!F16 -> $ | G16: main | H16: ='Main CEA'!H16 -> - | I16: ='Main CEA'!I16 -> 1045713.7 | J16: ='Main CEA'!J16 -> 1058302.7 | K16: ='Main CEA'!K16 -> 1045713.7 | L16: ='Main CEA'!L16 -> 1040216.5 | M16: ='Main CEA'!M16 -> 1040216.5 | N16: ='Main CEA'!N16 -> 1067466 | O16: ='Main CEA'!O16 -> 1042128.6 | P16: ='Main CEA'!P16 -> 1046756.4
C18: Total spending attributable to different actors
E19: Total spending contributed by grantee | F19: ='Main CEA'!F19 -> $ | G19: main | H19: ='Main CEA'!H19 -> - | I19: ='Main CEA'!I19 -> 1000000 | J19: ='Main CEA'!J19 -> 1000000 | K19: ='Main CEA'!K19 -> 1000000 | L19: ='Main CEA'!L19 -> 1000000 | M19: ='Main CEA'!M19 -> 1000000 | N19: ='Main CEA'!N19 -> 1000000 | O19: ='Main CEA'!O19 -> 1000000 | P19: ='Main CEA'!P19 -> 1000000
E20: Total spending contributed by other philanthropic actors | F20: ='Main CEA'!F20 -> $ | G20: main | H20: ='Main CEA'!H20 -> - | I20: ='Main CEA'!I20 -> 0 | J20: ='Main CEA'!J20 -> 0 | K20: ='Main CEA'!K20 -> 0 | L20: ='Main CEA'!L20 -> 0 | M20: ='Main CEA'!M20 -> 0 | N20: ='Main CEA'!N20 -> 0 | O20: ='Main CEA'!O20 -> 0 | P20: ='Main CEA'!P20 -> 0
E21: Total spending contributed by domestic governments | F21: ='Main CEA'!F21 -> $ | G21: main | H21: ='Main CEA'!H21 -> - | I21: ='Main CEA'!I21 -> 45713.688 | J21: ='Main CEA'!J21 -> 58302.745 | K21: ='Main CEA'!K21 -> 45713.688 | L21: ='Main CEA'!L21 -> 40216.54 | M21: ='Main CEA'!M21 -> 40216.54 | N21: ='Main CEA'!N21 -> 67466.092 | O21: ='Main CEA'!O21 -> 42128.568 | P21: ='Main CEA'!P21 -> 46756.411
C23: Upstream / downstream spending
E24: Total spending causally upstream of donations to grantee | F24: ='Main CEA'!F24 -> $ | G24: main | H24: ='Main CEA'!H24 -> - | I24: ='Main CEA'!I24 -> 1000000 | J24: ='Main CEA'!J24 -> 1000000 | K24: ='Main CEA'!K24 -> 1000000 | L24: ='Main CEA'!L24 -> 1000000 | M24: ='Main CEA'!M24 -> 1000000 | N24: ='Main CEA'!N24 -> 1000000 | O24: ='Main CEA'!O24 -> 1000000 | P24: ='Main CEA'!P24 -> 1000000
E25: Total spending causally downstream of donations to grantee | F25: ='Main CEA'!F25 -> $ | G25: main | H25: ='Main CEA'!H25 -> - | I25: ='Main CEA'!I25 -> 45713.688 | J25: ='Main CEA'!J25 -> 58302.745 | K25: ='Main CEA'!K25 -> 45713.688 | L25: ='Main CEA'!L25 -> 40216.54 | M25: ='Main CEA'!M25 -> 40216.54 | N25: ='Main CEA'!N25 -> 67466.092 | O25: ='Main CEA'!O25 -> 42128.568 | P25: ='Main CEA'!P25 -> 46756.411
A27: Counterfactual funding scenarios
C29: Probability of scenarios in the absence of philanthropic funding
E30: Scenario 1: Domestic governments would replace philanthropic costs | F30: =Inputs!F195 -> % | G30: =Inputs!G195 -> input | H30: =Inputs!H195 -> - | I30: =Inputs!I195 -> 0 | J30: =Inputs!J195 -> 0 | K30: =Inputs!K195 -> 0 | L30: =Inputs!L195 -> 0 | M30: =Inputs!M195 -> 0 | ... P30: =Inputs!P195 -> 0
E31: Scenario 2: Global Fund and/or PMI would replace philanthropic costs | F31: =Inputs!F196 -> % | G31: =Inputs!G196 -> input | H31: =Inputs!H196 -> - | I31: =Inputs!I196 -> 0.4 | J31: =Inputs!J196 -> 0.2 | K31: =Inputs!K196 -> 0.35 | L31: =Inputs!L196 -> 0.35 | M31: =Inputs!M196 -> 0.2 | ... P31: =Inputs!P196 -> 0.4
E32: Scenario 3: Other upstream costs would stay the same (downstream costs would shrink in proportion to the total size of the program) | F32: =Inputs!F197 -> % | G32: =Inputs!G197 -> input | H32: =Inputs!H197 -> - | I32: =Inputs!I197 -> 0 | J32: =Inputs!J197 -> 0 | K32: =Inputs!K197 -> 0 | L32: =Inputs!L197 -> 0 | M32: =Inputs!M197 -> 0 | ... P32: =Inputs!P197 -> 0
E33: Scenario 4: Distributions would go unfunded | F33: % | G33: calc | H33: - | I33: =1-SUM(I30:I32) -> 0.6 | J33: =1-SUM(J30:J32) -> 0.8 | K33: =1-SUM(K30:K32) -> 0.65 | L33: =1-SUM(L30:L32) -> 0.65 | M33: =1-SUM(M30:M32) -> 0.8 | N33: =1-SUM(N30:N32) -> 0.85 | O33: =1-SUM(O30:O32) -> 0.4 | P33: =1-SUM(P30:P32) -> 0.6
C35: Proportion of the program that would still occur in each scenario
E36: Scenario 1: Domestic governments would replace philanthropic costs | F36: =Inputs!F200 -> % | G36: =Inputs!G200 -> input | H36: =Inputs!H200 -> 1 | I36: =Inputs!I200 -> - | J36: =Inputs!J200 -> - | K36: =Inputs!K200 -> - | L36: =Inputs!L200 -> - | M36: =Inputs!M200 -> - | ... P36: =Inputs!P200 -> -
E37: Scenario 2: Global Fund and/or PMI would replace philanthropic costs | F37: =Inputs!F201 -> % | G37: =Inputs!G201 -> input | H37: =Inputs!H201 -> 1 | I37: =Inputs!I201 -> - | J37: =Inputs!J201 -> - | K37: =Inputs!K201 -> - | L37: =Inputs!L201 -> - | M37: =Inputs!M201 -> - | ... P37: =Inputs!P201 -> -
E38: Scenario 3: Other upstream costs would stay the same (downstream costs would shrink in proportion to the total size of the program) | F38: % | G38: calc | H38: - | I38: =I20/I24 -> 0 | J38: =J20/J24 -> 0 | K38: =K20/K24 -> 0 | L38: =L20/L24 -> 0 | M38: =M20/M24 -> 0 | N38: =N20/N24 -> 0 | O38: =O20/O24 -> 0 | P38: =P20/P24 -> 0
E39: Scenario 4: Distributions would go unfunded | F39: =Inputs!F202 -> % | G39: =Inputs!G202 -> input | H39: =Inputs!H202 -> 0 | I39: =Inputs!I202 -> - | J39: =Inputs!J202 -> - | K39: =Inputs!K202 -> - | L39: =Inputs!L202 -> - | M39: =Inputs!M202 -> - | ... P39: =Inputs!P202 -> -
A41: Value of spending
C43: Cost-effectiveness of the program (before leverage and funging)
E44: Units of value generated per dollar spent (before final adjustments) | F44: ='Main CEA'!F143 -> UoV | G44: main | H44: ='Main CEA'!H143 -> - | I44: ='Main CEA'!I143 -> 0.011373971 | J44: ='Main CEA'!J143 -> 0.040377722 | K44: ='Main CEA'!K143 -> 0.082100138 | L44: ='Main CEA'!L143 -> 0.054831566 | M44: ='Main CEA'!M143 -> 0.036271711 | N44: ='Main CEA'!N143 -> 0.019397973 | O44: ='Main CEA'!O143 -> 0.038052084 | P44: ='Main CEA'!P143 -> 0.057820168
E45: Total supplemental grantee-level adjustment | F45: ='Main CEA'!F172 -> % | G45: main | H45: ='Main CEA'!H172 -> -0.04 | I45: ='Main CEA'!I172 -> - | J45: ='Main CEA'!J172 -> - | K45: ='Main CEA'!K172 -> - | L45: ='Main CEA'!L172 -> - | M45: ='Main CEA'!M172 -> - | N45: ='Main CEA'!N172 -> - | O45: ='Main CEA'!O172 -> - | P45: ='Main CEA'!P172 -> -
E46: Total supplemental intervention-level adjustment | F46: ='Main CEA'!F189 -> % | G46: main | H46: ='Main CEA'!H189 -> - | I46: ='Main CEA'!I189 -> 0.529 | J46: ='Main CEA'!J189 -> 0.479 | K46: ='Main CEA'!K189 -> 0.379 | L46: ='Main CEA'!L189 -> 0.479 | M46: ='Main CEA'!M189 -> 0.479 | N46: ='Main CEA'!N189 -> 0.379 | O46: ='Main CEA'!O189 -> 0.379 | P46: ='Main CEA'!P189 -> 0.379
E47: Units of value generated per dollar donated to grantee (after supplemental adjustments) | F47: UoV | G47: calc | H47: - | I47: =I44*(1+$H45)*(1+I46) -> 0.016695169 | J47: =J44*(1+$H45)*(1+J46) -> 0.057329905 | K47: =K44*(1+$H45)*(1+K46) -> 0.10868745 | L47: =L44*(1+$H45)*(1+L46) -> 0.077852051 | M47: =M44*(1+$H45)*(1+M46) -> 0.051500026 | N47: =N44*(1+$H45)*(1+N46) -> 0.025679813 | O47: =O44*(1+$H45)*(1+O46) -> 0.050374871 | P47: =P44*(1+$H45)*(1+P46) -> 0.076544651
C49: Lives saved by the program (before leverage and funging)
E50: Total lives saved (before final adjustments) | F50: ='Main CEA'!F154 -> # | G50: main | H50: ='Main CEA'!H154 -> - | I50: ='Main CEA'!I154 -> 69.001061 | J50: ='Main CEA'!J154 -> 250.66427 | K50: ='Main CEA'!K154 -> 588.1917 | L50: ='Main CEA'!L154 -> 392.17081 | M50: ='Main CEA'!M154 -> 243.78345 | N50: ='Main CEA'!N154 -> 122.9351 | O50: ='Main CEA'!O154 -> 260.73544 | P50: ='Main CEA'!P154 -> 363.81499
E51: Total supplemental grantee-level adjustment | F51: ='Main CEA'!F172 -> % | G51: main | H51: ='Main CEA'!H172 -> -0.04 | I51: ='Main CEA'!I172 -> - | J51: ='Main CEA'!J172 -> - | K51: ='Main CEA'!K172 -> - | L51: ='Main CEA'!L172 -> - | M51: ='Main CEA'!M172 -> - | N51: ='Main CEA'!N172 -> - | O51: ='Main CEA'!O172 -> - | P51: ='Main CEA'!P172 -> -
...

Sheet Inputs
I1: Against Malaria Foundation
I2: Chad | J2: DRC | K2: Guinea | L2: Nigeria | M2: Nigeria | N2: South Sudan | O2: Togo | P2: Uganda
A3: Inputs | F3: unit | G3: type | H3: Overall | L3: GF states | M3: PMI states | R3: Source | S3: GW analysis and discussion
E4: Final cost-effectiveness estimate (pulled from "Main calcs" sheet for visibility) | F4: ='Main CEA'!F203 -> xbenchmark | G4: main | H4: ='Main CEA'!H203 -> - | I4: ='Main CEA'!I203 -> 4.8202994 | J4: ='Main CEA'!J203 -> 14.629025 | K4: ='Main CEA'!K203 -> 22.79223 | L4: ='Main CEA'!L203 -> 16.778736 | M4: ='Main CEA'!M203 -> 13.250427 | N4: ='Main CEA'!N203 -> 7.1630004 | O4: ='Main CEA'!O203 -> 8.8061654 | P4: ='Main CEA'!P203 -> 15.60304
A5: Costs
C7: GiveWell costs
E8: Grant size | F8: $ | G8: input | H8: 1000000 | I8: - | J8: - | K8: - | L8: - | M8: - | N8: - | O8: - | P8: - | R8: Arbitrary value
C10: Cost breakdown
E11: Percentage of total costs covered by the grantee | F11: % | G11: input | H11: - | I11: 0.9562847 | J11: 0.9449092 | K11: 0.9562847 | L11: 0.9613383 | M11: 0.9613383 | N11: 0.936798 | O11: 0.9595745 | P11: 0.9553321 | R11: GW analysis | S11: GW's analysis of AMF cost per net [unpublished]
E12: Percentage of total costs covered by other philanthropic actors | F12: % | G12: input | H12: - | I12: =K12 -> 0 | J12: 0 | K12: 0 | L12: 0 | M12: 0 | N12: 0 | O12: 0 | P12: 0 | R12: GW analysis | S12: GW's analysis of AMF cost per net [unpublished]
E13: Percentage of total costs covered by domestic governments | F13: % | G13: input | H13: - | I13: =K13 -> 0.0437153 | J13: 0.0550908 | K13: 0.0437153 | L13: 0.0386617 | M13: 0.0386617 | N13: 0.0632021 | O13: 0.0404255 | P13: 0.0446679 | R13: GW analysis | S13: GW's analysis of AMF cost per net [unpublished]
C15: Cost per net
E16: Total cost per insecticide-treated net (ITN) distributed | F16: $ | G16: input | H16: - | I16: =K16 -> 3.93785 | J16: 5.85033 | K16: 3.93785 | L16: 4.34117 | M16: 4.34117 | N16: 5.32824 | O16: 3.66624 | P16: 4.44504 | R16: GW analysis | S16: GW's analysis of AMF cost per net [unpublished]
A18: Outputs
C20: Net usage
E21: Proportion of distributed nets that were used in trials from the Pryce et al. 2018 meta-analysis | F21: % | G21: input | H21: 0.7 | I21: - | J21: - | K21: - | L21: - | M21: - | N21: - | O21: - | P21: - | R21: GW analysis | S21: Updated GiveWell summary of ITN RCTs
E22: Adjustment for net usage in program contexts | F22: % | G22: input | H22: -0.1 | I22: - | J22: - | K22: - | L22: - | M22: - | N22: - | O22: - | P22: - | R22: GW guesstimate
C24: Net coverage
E25: Number of people sleeping under each used net | F25: # | G25: input | H25: - | I25: 1.93645 | J25: 2.15114 | K25: 1.99095 | L25: 1.93645 | M25: 1.93645 | N25: 1.93645 | O25: 1.72163 | P25: 1.76505 | R25: GW analysis | S25: GW's analysis of the number of people covered per net
C27: Age distribution of population
E28: Total national population | F28: # | G28: input | H28: - | I28: =IFERROR(__xludf.DUMMYFUNCTION("FILTER('GBD estimates'!$H$4:$H$2400,'GBD estimates'!$B$4:$B$2400=I$2,'GBD estimates'!$D$4:$D$2400=""All Ages"")"),1.639885974E7) -> 16398860 | J28: =IFERROR(__xludf.DUMMYFUNCTION("FILTER('GBD estimates'!$H$4:$H$2400,'GBD estimates'!$B$4:$B$2400=J$2,'GBD estimates'!$D$4:$D$2400=""All Ages"")"),8.767044378E7) -> 87670444 | K28: =IFERROR(__xludf.DUMMYFUNCTION("FILTER('GBD estimates'!$H$4:$H$2400,'GBD estimates'!$B$4:$B$2400=K$2,'GBD estimates'!$D$4:$D$2400=""All Ages"")"),1.264314893E7) -> 12643149 | L28: =IFERROR(__xludf.DUMMYFUNCTION("FILTER('GBD estimates'!$H$4:$H$2400,'GBD estimates'!$B$4:$B$2400=L$2,'GBD estimates'!$D$4:$D$2400=""All Ages"")"),2.148237857E8) -> 2.1482379e+08 | M28: =IFERROR(__xludf.DUMMYFUNCTION("FILTER('GBD estimates'!$H$4:$H$2400,'GBD estimates'!$B$4:$B$2400=M$2,'GBD estimates'!$D$4:$D$2400=""All Ages"")"),2.148237857E8) -> 2.1482379e+08 | N28: =IFERROR(__xludf.DUMMYFUNCTION("FILTER('GBD estimates'!$H$4:$H$2400,'GBD estimates'!$B$4:$B$2400=N$2,'GBD estimates'!$D$4:$D$2400=""All Ages"")"),9282963.047) -> 9282963 | O28: =IFERROR(__xludf.DUMMYFUNCTION("FILTER('GBD estimates'!$H$4:$H$2400,'GBD estimates'!$B$4:$B$2400=O$2,'GBD estimates'!$D$4:$D$2400=""All Ages"")"),7921526.585) -> 7921526.6 | P28: =IFERROR(__xludf.DUMMYFUNCTION("FILTER('GBD estimates'!$H$4:$H$2400,'GBD estimates'!$B$4:$B$2400=P$2,'GBD estimates'!$D$4:$D$2400=""All Ages"")"),4.111785624E7) -> 41117856 | R28: GBD 2019
