Workbook
Name BDT_to_USD_2017: #REF!
Name BDT_to_USD_2014: #REF!
Name lesser_lean_season_duration: #REF!
Name nls_household_size: #REF!
Name primary_lean_season_duration: #REF!

Sheet Start here
A1: Notes on how to engage with our cost-effectiveness analysis
A2: This workbook contains our cost-effectiveness analysis. Cost-effectiveness is one factor we use to assess which opportunities are the highest-priority to support. We also consider other factors such as urgency, quality of implementation, and more. If you're a donor interested in supporting the top charity we believe will do the most good at the time your donation is granted, please consider supporting the Top Charities Fund. On the "Moral weights and discount rate" sheet, we've included GiveWell and conventional estimates for a few parameters. If you'd like to see how our results would change based on different inputs for these parameters, you can make a copy of this spreadsheet and enter your own values in the "Anyone" column. Expanding the formula bar at the top of the page (by clicking and dragging the bottom boundary) may make it easier to read the contents of explanatory cells.
A6: Notes on text color coding
A7: Blue text: direct input
A8: Green text: pulling from another cell in this workbook
A9: Black text: calculation
A11: Index
A12: Moral weights and discount rate | B12: Allows staff members or anyone else to supply discount rates and numbers used to trade off different good outcomes
A13: AMF | B13: Cost-effectiveness analysis for long-lasting insecticide-treated net distributions by the Against Malaria Foundation.
A14: GiveDirectly | B14: Cost-effectiveness analysis for unconditional cash transfers by GiveDirectly.
A15: Deworm the World | B15: Cost-effectiveness analysis for deworming by Deworm the World
A16: Unlimit Health | B16: Cost-effectiveness analysis for deworming by Unlimit Health
A17: Sightsavers | B17: Cost-effectiveness analysis for deworming by Sightsavers
A18: Malaria Consortium | B18: Cost-effectiveness analysis for seasonal malaria chemoprevention by Malaria Consortium
A19: Helen Keller International | B19: Cost-effectiveness analysis for vitamin A supplementation by Helen Keller International
A20: New Incentives | B20: Cost-effectiveness analysis for conditional cash transfers for immunization by New Incentives
A21: Value of counterfactual spending by other actors | B21: Used in the leverage and funging adjustments to our cost-effectiveness analyses
A22: Supplemental intervention-level adjustments | B22: Intervention-level adjustments for outcomes not explicitly modeled in our cost-effectiveness analyses
A24: Helpful GiveWell references
A25: =HYPERLINK("https://docs.google.com/document/d/1ZKq-MNU-xtn_48uN33L6VvBEZRAduvjwWMeaEffL4K4/","Guide to GiveWell cost-effectiveness analyses") -> Guide to GiveWell cost-effectiveness analyses
A26: =HYPERLINK("http://www.givewell.org/charities/top-charities","Full reviews of our top charities") -> Full reviews of our top charities
A27: =HYPERLINK("http://www.givewell.org/international/technical/criteria/cost-effectiveness/cost-effectiveness-models","Past versions of our cost-effectiveness analyses") -> Past versions of our cost-effectiveness analyses
A28: =HYPERLINK("http://www.givewell.org/international/technical/criteria/cost-effectiveness","Discussion of cost-effectiveness as a criterion") -> Discussion of cost-effectiveness as a criterion
A29: =HYPERLINK("http://www.givewell.org/international/technical/criteria/cost-effectiveness#MoreonGiveWellsviewsoncosteffectivenessestimates","Blog posts discussing cost-effectiveness") -> Blog posts discussing cost-effectiveness

Sheet Moral weights and discount rate
A1: Moral weights and discount rate | B1: Active | C1: GiveWell 2020 | D1: Anyone | E1: Conventional | F1: Alex | G1: Andrew | H1: Caitlin | I1: Dan | J1: Isabel | K1: James | L1: Josh | M1: Marinella | N1: Michael | O1: Natalie | P1: Nicole | Q1: Olivia | R1: Stephan | S1: Tom | T1: Notes
A2: Moral weights
A4: Consumption Increases
A5: Value assigned to doubling consumption for one person for one year | B5: {=index($A$1:$V$39,match($A5,$A$1:$A$39,0),match($A$17,$A$1:$T$1,0))} -> 1 | C5: 1 | E5: =1/2.5 -> 0.4
A7: Averting deaths
A8: Value assigned to averting the death of an individual under 5 from malaria | B8: =index($A$1:$V$39,match($A8,$A$1:$A$39,0),match($A$17,$A$1:$T$1,0)) -> 116.25262 | C8: 116.25262 | E8: 36.53 | T8: Lopez et al. 2006
A9: Value assigned to averting the death of an individual 5 or older from malaria | B9: =index($A$1:$V$39,match($A9,$A$1:$A$39,0),match($A$17,$A$1:$T$1,0)) -> 73.191405 | C9: 73.191405 | E9: 29.77 | T9: Lopez et al. 2006
A10: Value assigned to averting the death of a 6- to 59-month-old child (VAS) | B10: =index($A$1:$V$39,match($A10,$A$1:$A$39,0),match($A$17,$A$1:$T$1,0)) -> 118.73259 | C10: 118.73259 | E10: 36.53 | T10: Lopez et al. 2006
A11: Value assigned to averting the death of an individual under 5 from vaccine-preventable diseases | B11: =index($A$1:$V$39,match($A11,$A$1:$A$39,0),match($A$17,$A$1:$T$1,0)) -> 116.25262 | C11: =C8 -> 116.25262 | E11: 36.53 | T11: Lopez et al. 2006
A12: Value assigned to averting the death of an individual 5-14 years old from vaccine-preventable diseases | B12: =index($A$1:$V$39,match($A12,$A$1:$A$39,0),match($A$17,$A$1:$T$1,0)) -> 133.7 | C12: 133.7 | E12: 36.9 | T12: Lopez et al. 2006
A13: Value assigned to averting the death of an individual 15-49 years old from vaccine-preventable diseases | B13: =index($A$1:$V$39,match($A13,$A$1:$A$39,0),match($A$17,$A$1:$T$1,0)) -> 103.58571 | C13: 103.58571 | E13: 29.77 | T13: Lopez et al. 2006
A14: Value assigned to averting the death of an individual 50-74 years old from vaccine-preventable diseases | B14: =index($A$1:$V$39,match($A14,$A$1:$A$39,0),match($A$17,$A$1:$T$1,0)) -> 42.44 | C14: 42.44 | E14: 11.85 | T14: Lopez et al. 2006
A16: Active column pulls from:
A17: GiveWell 2020
A19: Derived value assignments
A20: Value assigned to increasing consumption by 10% for one person for one year | B20: =B5*(ln(1.1)/ln(2)) -> 0.13750352 | C20: =if(C5>0,C5*(ln(1.1)/ln(2)),"") -> 0.13750352 | D20: =if(D5>0,D5*(ln(1.1)/ln(2)),"") | E20: =E5*(ln(1.1)/ln(2)) -> 0.05500141
A21: Value assigned to increasing consumption by 25% for one person for one year | B21: =B5*(ln(1.25)/ln(2)) -> 0.32192809 | C21: =if(C5>0,C5*(ln(1.25)/ln(2)),"") -> 0.32192809 | D21: =if(D5>0,D5*(ln(1.25)/ln(2)),"") | E21: =E5*(ln(1.25)/ln(2)) -> 0.12877124
A22: Value assigned to increasing ln(consumption) by one unit for one person for one year | B22: =B5/ln(2) -> 1.442695 | C22: =if(C5>0,C5/ln(2),"") -> 1.442695 | D22: =if(D5>0,D5/ln(2),"") | E22: =E5/ln(2) -> 0.57707802
A24: Value assigned to increasing consumption by 10% for 100 people for one year | B24: =100*B5*(ln(1.1)/ln(2)) -> 13.750352 | C24: =if(C5>0,100*C5*(ln(1.1)/ln(2)),"") -> 13.750352 | D24: =if(D5>0,100*D5*(ln(1.1)/ln(2)),"") | E24: =100*E5*(ln(1.1)/ln(2)) -> 5.5001409
A25: Value assigned to increasing consumption by 25% for 100 people for one year | B25: =100*B5*(ln(1.25)/ln(2)) -> 32.192809 | C25: =if(C5>0,100*C5*(ln(1.25)/ln(2)),"") -> 32.192809 | D25: =if(D5>0,100*D5*(ln(1.25)/ln(2)),"") | E25: =100*E5*(ln(1.25)/ln(2)) -> 12.877124
A27: Implications
A28: Value of an age 5+ life saved relative to an under-5 life saved | B28: =iferror(B9/B8, " ") -> 0.62958931 | C28: =iferror(C9/C8, " ") -> 0.62958931 | D28: =iferror(D9/D8, " ") | E28: =iferror(E9/E8, " ") -> 0.81494662
A29: Value of doubling consumption for one person for one year relative to saving the life of a child under-5 (AMF) | B29: =iferror(B5/B8, " ") -> 0.008601957 | C29: =iferror(C5/C8, " ") -> 0.008601957 | D29: =iferror(D5/D8, " ") | E29: =iferror(E5/E8, " ") -> 0.010949904
B30: =iferror(B8/#REF!, " ") | C30: =iferror(C8/#REF!, " ") | D30: =iferror(D8/#REF!, " ") | E30: =iferror(E8/#REF!, " ")
A31: Discount rate
A32: Improving circumstances over time | B32: =index($A$1:$V$39,match($A32,$A$1:$A$39,0),match($A$17,$A$1:$T$1,0)) -> 0.017 | C32: 0.017
A33: Compounding non-monetary benefits | B33: =index($A$1:$V$39,match($A33,$A$1:$A$39,0),match($A$17,$A$1:$T$1,0)) -> 0.009 | C33: 0.009
A34: Temporal uncertainty | B34: =index($A$1:$V$39,match($A34,$A$1:$A$39,0),match($A$17,$A$1:$T$1,0)) -> 0.014 | C34: 0.014
A35: Pure time preference (donors) | B35: =index($A$1:$V$39,match($A35,$A$1:$A$39,0),match($A$17,$A$1:$T$1,0)) -> 0 | C35: 0
A36: Pure time preference (program participants) | B36: =index($A$1:$V$39,match($A36,$A$1:$A$39,0),match($A$17,$A$1:$T$1,0)) -> 0 | C36: 0
A37: Overall discount rate | B37: =index($A$1:$V$39,match($A37,$A$1:$A$39,0),match($A$17,$A$1:$T$1,0)) -> 0.04 | C37: =sum(C32:C36) -> 0.04 | E37: =C37 -> 0.04

Sheet AMF
A1: Long-lasting insecticide-treated net (LLIN) distributions - Against Malaria Foundation (AMF) | B1: DRC | C1: Guinea | D1: Togo | E1: Uganda | F1: Nigeria (PMI states) | G1: Nigeria (Global Fund states) | H1: Chad | I1: South Sudan
A5: Funding allocation
A7: Percentage of total costs covered by AMF | B7: 0.5039085 | C7: 0.6365521 | D7: 0.6534446 | E7: 0.5993375 | F7: 0.6809358 | G7: 0.6809358 | H7: 0.6365521 | I7: 0.4300644
A8: Percentage of total costs covered by other philanthropic actors | B8: 0 | C8: 0 | D8: 0 | E8: 0 | F8: 0 | G8: 0 | H8: 0 | I8: 0
A10: Number of people covered
A12: Costs
A13: Donation to AMF (arbitrary size) | B13: 100000 | C13: 100000 | D13: 100000 | E13: 100000 | F13: 100000 | G13: 100000 | H13: 100000 | I13: 100000
A14: Total spending by all contributors | B14: =B13/B7 -> 198448.73 | C14: =C13/C7 -> 157096.33 | D14: =D13/D7 -> 153035.16 | E14: =E13/E7 -> 166850.9 | F14: =F13/F7 -> 146856.72 | G14: =G13/G7 -> 146856.72 | H14: =H13/H7 -> 157096.33 | I14: =I13/I7 -> 232523.32
A15: Cost per long-lasting insecticide-treated net (LLIN) distributed | B15: 5.85033 | C15: 3.93785 | D15: 3.66624 | E15: 4.44504 | F15: 4.34286 | G15: 4.34286 | H15: 3.93785 | I15: 5.32824
A17: Net usage
A18: Number of nets distributed | B18: =B14/B15 -> 33920.946 | C18: =C14/C15 -> 39893.935 | D18: =D14/D15 -> 41741.719 | E18: =E14/E15 -> 37536.422 | F18: =F14/F15 -> 33815.67 | G18: =G14/G15 -> 33815.67 | H18: =H14/H15 -> 39893.935 | I18: =I14/I15 -> 43639.798
A19: Proportion of distributed nets used in trials from Pryce et al. 2018 meta-analysis | B19: 0.7 | C19: 0.7 | D19: 0.7 | E19: 0.7 | F19: 0.7 | G19: 0.7 | H19: 0.7 | I19: 0.7
A20: Adjustment for net usage in program contexts | B20: 0.9 | C20: 0.9 | D20: 0.9 | E20: 0.9 | F20: 0.9 | G20: 0.9 | H20: 0.9 | I20: 0.9
A21: Proportion of distributed nets used in program contexts | B21: =B19*B20 -> 0.63 | C21: =C19*C20 -> 0.63 | D21: =D19*D20 -> 0.63 | E21: =E19*E20 -> 0.63 | F21: =F19*F20 -> 0.63 | G21: =G19*G20 -> 0.63 | H21: =H19*H20 -> 0.63 | I21: =I19*I20 -> 0.63
A22: Number of nets used | B22: =B18*B21 -> 21370.196 | C22: =C18*C21 -> 25133.179 | D22: =D18*D21 -> 26297.283 | E22: =E18*E21 -> 23647.946 | F22: =F18*F21 -> 21303.872 | G22: =G18*G21 -> 21303.872 | H22: =H18*H21 -> 25133.179 | I22: =I18*I21 -> 27493.072
A24: Net coverage
A25: Number of people sleeping under each used net | B25: 2.15114 | C25: 1.99095 | D25: 1.72163 | E25: 1.76505 | F25: 1.93645 | G25: 1.93645 | H25: 1.93645 | I25: 1.93645
A26: Total number of people sleeping under distributed nets | B26: =B22*B25 -> 45970.283 | C26: =C22*C25 -> 50038.903 | D26: =D22*D25 -> 45274.192 | E26: =E22*E25 -> 41739.807 | F26: =F22*F25 -> 41253.884 | G26: =G22*G25 -> 41253.884 | H26: =H22*H25 -> 48669.145 | I26: =I22*I25 -> 53238.96
A27: Equivalent coverage-years for an LLIN over a 36-month distribution | B27: =2.11*(1-0.173704447529312) -> 1.7434836 | C27: 2.11 | D27: 2.11 | E27: 2.11 | F27: 2.11 | G27: 2.11 | H27: 2.11 | I27: 2.11
A28: Adjustment for net coverage years lost due to residual nets from previous distributions | B28: 0.97 | C28: 0.97 | D28: 0.97 | E28: 0.97 | F28: 0.98 | G28: 0.97 | H28: 0.97 | I28: 0.97
A29: Adjustment for program impact being to move distributions closer together | B29: =1-29.74486% -> 0.7025514 | C29: 1 | D29: 1 | E29: 1 | F29: =1-35.0995389911857% -> 0.64900461 | G29: 1 | H29: 1 | I29: =1-36.86111% -> 0.6313889
A30: Total person-years of effective coverage | B30: =B26*B27*B28*B29 -> 54619.143 | C30: =C26*C27*C28*C29 -> 102414.62 | D30: =D26*D27*D28*D29 -> 92662.688 | E30: =E26*E27*E28*E29 -> 85428.863 | F30: =F26*F27*F28*F29 -> 55363.196 | G30: =G26*G27*G28*G29 -> 84434.324 | H30: =H26*H27*H28*H29 -> 99611.138 | I30: =I26*I27*I28*I29 -> 68798.774
A32: Age distribution of net coverage
A34: Percent of population under 5 years old (used for mortality effects and development effects) | B34: =13629465.1519444/87670443.7766788 -> 0.15546249 | C34: =2143394.87689442/12643148.9336671 -> 0.16953015 | D34: =1114855.20710404/7921526.58517355 -> 0.14073742 | E34: =7089749.81596238/41117856.2413241 -> 0.17242508 | F34: =33521637.830718/214823785.7115 -> 0.15604249 | G34: =33521637.830718/214823785.7115 -> 0.15604249 | H34: =3332666.56158174/16398859.7420741 -> 0.20322551 | I34: =1516375.15541563/9282963.04697691 -> 0.16335034
A35: Percent of population ages 5-9 | B35: =12763832.6557654/87670443.7766788 -> 0.14558878 | C35: =1933404.91137462/12643148.9336671 -> 0.15292115 | D35: =1074824.79732476/7921526.58517355 -> 0.13568405 | E35: =6314355.69254718/41117856.2413241 -> 0.15356724 | F35: =31315804.4739165/214823785.7115 -> 0.14577438 | G35: =31315804.4739165/214823785.7115 -> 0.14577438 | H35: =2751338.52652141/16398859.7420741 -> 0.16777621 | I35: =1342387.97845529/9282963.04697691 -> 0.1446077
A36: Percent of population ages 10-14 | B36: =11301847.5012717/87670443.7766788 -> 0.12891286 | C36: =1636389.58910505/12643148.9336671 -> 0.12942896 | D36: =957955.990123928/7921526.58517355 -> 0.12093073 | E36: =5673366.42359162/41117856.2413241 -> 0.13797817 | F36: =28910632.0515107/214823785.7115 -> 0.13457836 | G36: =28910632.0515107/214823785.7115 -> 0.13457836 | H36: =2226082.47505384/16398859.7420741 -> 0.13574617 | I36: =1309739.90536986/9282963.04697691 -> 0.14109072
A37: Percent of population ages 5-14 (used for development effects only) | B37: =24065680.1570372/87670443.7766788 -> 0.27450164 | C37: =3569794.50047968/12643148.9336671 -> 0.28235011 | D37: =2032780.78744869/7921526.58517355 -> 0.25661478 | E37: =11987722.1161388/41117856.2413241 -> 0.29154541 | F37: =60226436.5254272/214823785.7115 -> 0.28035274 | G37: =60226436.5254272/214823785.7115 -> 0.28035274 | H37: =4977421.00157526/16398859.7420741 -> 0.30352238 | I37: =2652127.88382515/9282963.04697691 -> 0.28569842
A39: Person-years of coverage for under 5s | B39: =B30*B34 -> 8491.2278 | C39: =C30*C34 -> 17362.366 | D39: =D30*D34 -> 13041.108 | E39: =E30*E34 -> 14730.079 | F39: =F30*F34 -> 8639.0108 | G39: =G30*G34 -> 13175.342 | H39: =H30*H34 -> 20243.524 | I39: =I30*I34 -> 11238.303
A40: Person-years of coverage for ages 5-14 | B40: =B30*B37 -> 14993.044 | C40: =C30*C37 -> 28916.78 | D40: =D30*D37 -> 23778.615 | E40: =E30*E37 -> 24906.393 | F40: =F30*F37 -> 15521.224 | G40: =G30*G37 -> 23671.394 | H40: =H30*H37 -> 30234.21 | I40: =I30*I37 -> 19655.701
A41: Person-years of coverage for under 15s | B41: =B40+B39 -> 23484.272 | C41: =C40+C39 -> 46279.146 | D41: =D40+D39 -> 36819.723 | E41: =E40+E39 -> 39636.471 | F41: =F40+F39 -> 24160.234 | G41: =G40+G39 -> 36846.736 | H41: =H40+H39 -> 50477.734 | I41: =I40+I39 -> 30894.004
A43: Mortality reduction in children under 5
A45: Effect of bednet distributions on mortality
A46: Reduction in malaria incidence for children under 5 receiving nets (from Pryce et al. 2018 meta-analysis) | B46: 0.45 | C46: 0.45 | D46: 0.45 | E46: 0.45 | F46: 0.45 | G46: 0.45 | H46: 0.45 | I46: 0.45
A47: Reduction in malaria incidence for children under 5 sleeping under nets | B47: =B46/B19 -> 0.64285714 | C47: =C46/C19 -> 0.64285714 | D47: =D46/D19 -> 0.64285714 | E47: =E46/E19 -> 0.64285714 | F47: =F46/F19 -> 0.64285714 | G47: =G46/G19 -> 0.64285714 | H47: =H46/H19 -> 0.64285714 | I47: =I46/I19 -> 0.64285714
A48: Internal validity adjustment — Nets | B48: 0.95 | C48: 0.95 | D48: 0.95 | E48: 0.95 | F48: 0.95 | G48: 0.95 | H48: 0.95 | I48: 0.95
A49: External validity adjustment — Nets | B49: 0.95 | C49: 0.95 | D49: 0.95 | E49: 0.95 | F49: 0.95 | G49: 0.95 | H49: 0.95 | I49: 0.95
A50: Efficacy reduction due to insecticide resistance | B50: 0.0376862 | C50: 0.2070199 | D50: 0.3290476 | E50: 0.11499111 | F50: 0.13530442 | G50: 0.13530442 | H50: 0.585957 | I50: 0.3067736
A51: Ratio of the reduction in malaria mortality to the reduction in malaria incidence | B51: 1 | C51: 1 | D51: 1 | E51: 1 | F51: 1 | G51: 1 | H51: 1 | I51: 1
A52: Expected reduction in malaria mortality among children treated | B52: =B47*B48*B49*(1-B50)*B51 -> 0.55831385 | C52: =C47*C48*C49*(1-C50)*C51 -> 0.46007006 | D52: =D47*D48*D49*(1-D50)*D51 -> 0.38927221 | E52: =E47*E48*E49*(1-E50)*E51 -> 0.51346319 | F52: =F47*F48*F49*(1-F50)*F51 -> 0.50167785 | G52: =G47*G48*G49*(1-G50)*G51 -> 0.50167785 | H52: =H47*H48*H49*(1-H50)*H51 -> 0.24021888 | I52: =I47*I48*I49*(1-I50)*I51 -> 0.4021951
A54: Counterfactual mortality in the absence of bednets
...

Sheet GiveDirectly
A1: Cash Transfers - GiveDirectly | B1: Overall
A3: Size of transfer
A4: Arbitrary donation size | B4: 100000
A5: Transfers as a percentage of total cost | B5: 0.83
A6: Total funding available for cash transfers out of hypothetical donation | B6: =B4*B5 -> 83000
A7: Total size of transfer per household (nominal USD) | B7: 1000
A8: Average household size | B8: 4.7
A9: Size of transfer per person (nominal USD) | B9: =B7/B8 -> 212.76596
A11: Investment returns
A12: Percentage of transfers invested | B12: 0.39
A13: Amount invested (nominal USD) | B13: =B9*B12 -> 82.978723
A14: Total increase in consumption per person made possible by funds transferred (nominal USD) | B14: =(1-B12)*B9 -> 129.78723
A15: Return on investment | B15: 0.1
A16: Annual increase in consumption per person made possible by investment returns (nominal USD) | B16: =B13*B15 -> 8.2978723
A18: Present value of transfer
A19: Baseline annual consumption per capita (in nominal USD) | B19: 285.92229
A20: Total immediate increase in ln(consumption) per person made possible by funds transferred | B20: =LN(B19+B14)-LN(B19) -> 0.3742667
A21: Future annual increase in ln(consumption) per person — from returns on investments | B21: =LN(B19+B16)-LN(B19) -> 0.028608278
A22: Discount rate | B22: {=index('Moral weights and discount rate'!1:39,match("Overall discount rate",'Moral weights and discount rate'!A:A,0), match("Active",'Moral weights and discount rate'!1:1,0))} -> 0.04
A23: Duration of investment benefits (in years) | B23: 10
A24: Present value of future increases in ln(consumption) per person (excluding the last year of expected benefits) | B24: =PV(B22,B23-1,-B21) -> 0.21271203
A25: Percent of investment returned when benefits end | B25: 0.2
A26: Present value of ln(consumption) increase in the last year of expected benefits | B26: =(LN(B19+B13*(B15+B25))-LN(B19))/(1+B22)^B23 -> 0.056396595
A27: Present value of all future increases in ln(consumption) | B27: =B26+B24 -> 0.26910863
A28: Total present value of cash transfer in terms of increases in ln(consumption) | B28: =B27+B20 -> 0.64337533
A29: Discount to the benefits of cash from potential negative spillover effects on consumption | B29: 0.05
A30: Total present value of cash transfer accounting for spillovers | B30: =(1-B29)*B28 -> 0.61120656
A31: Total units of increase in ln(consumption) per household | B31: =B30*B8 -> 2.8726708
A33: Number of transfers made | B33: =B6/B7 -> 83
A34: Total units of increase in ln(consumption) | B34: =B31*B33 -> 238.43168
A35: Value assigned to increasing ln(consumption) by one unit for one person for one year | B35: {=index('Moral weights and discount rate'!$A$1:$ZU$39,match($A35,'Moral weights and discount rate'!$A$1:$A$39,0),match('Moral weights and discount rate'!$A$17,'Moral weights and discount rate'!$A$1:$ZU1,0))} -> 1.442695
A37: Total units of value generated | B37: =B34*B35 -> 343.9842
A38: Units of value generated per dollar spent | B38: =B37/B4 -> 0.003439842
A40: Contribution of each outcome to overall cost-effectiveness
A42: Percent of cash's modeled benefits coming from short-term consumption increases | B42: =if(B12<>"", iferror(B20/(B20+B27)," "), "") -> 0.58172373
A43: Percent of cash's modeled benefits coming from investment returns in the future | B43: =if(B12<>"", iferror(B27/(B27+B20)," "), "") -> 0.41827627
A45: Initial cost-effectiveness estimate in multiples of cash transfers | B45: {=B37/index(GiveDirectly!B:B,match("Total units of value generated, after accounting for all adjustments",GiveDirectly!A:A,0))} -> 1.0254307
A47: Supplemental charity-level adjustments — GiveDirectly
A49: Risk of wastage
A50: Double treatment | B50: 0
...

Sheet Deworm the World
A1: Deworming - Deworm the World | B1: Kenya | C1: Azad Jammu and Kashmir, Pakistan | D1: Balochistan, Pakistan | E1: Gilgit-Baltistan, Pakistan | F1: Islamabad Capital Territory, Pakistan | G1: Khyber Pakhtunkhwa, Pakistan | H1: Punjab, Pakistan | I1: Sindh, Pakistan | J1: Lagos, Nigeria | K1: Oyo, Nigeria | L1: Ogun, Nigeria | M1: Rivers, Nigeria | N1: Cross River, Nigeria
A5: Long-term income effects from deworming
A7: Treatment effect of deworming on ln(income) in the Miguel and Kremer 2004 study population | B7: 0.109 | C7: 0.109 | D7: 0.109 | E7: 0.109 | F7: 0.109 | G7: 0.109 | H7: 0.109 | I7: 0.109 | J7: 0.109 | K7: 0.109 | L7: 0.109 | M7: 0.109 | N7: 0.109
A8: Coverage in the treatment group (Miguel and Kremer) | B8: 0.75 | C8: 0.75 | D8: 0.75 | E8: 0.75 | F8: 0.75 | G8: 0.75 | H8: 0.75 | I8: 0.75 | J8: 0.75 | K8: 0.75 | L8: 0.75 | M8: 0.75 | N8: 0.75
A9: Coverage in the control group (Miguel and Kremer) | B9: 0.05 | C9: 0.05 | D9: 0.05 | E9: 0.05 | F9: 0.05 | G9: 0.05 | H9: 0.05 | I9: 0.05 | J9: 0.05 | K9: 0.05 | L9: 0.05 | M9: 0.05 | N9: 0.05
A10: Estimated treatment effect on the treated | B10: =B7/((B8-B9)-B9*B7) -> 0.15693615 | C10: =C7/((C8-C9)-C9*C7) -> 0.15693615 | D10: =D7/((D8-D9)-D9*D7) -> 0.15693615 | E10: =E7/((E8-E9)-E9*E7) -> 0.15693615 | F10: =F7/((F8-F9)-F9*F7) -> 0.15693615 | G10: =G7/((G8-G9)-G9*G7) -> 0.15693615 | H10: =H7/((H8-H9)-H9*H7) -> 0.15693615 | I10: =I7/((I8-I9)-I9*I7) -> 0.15693615 | ... N10: =N7/((N8-N9)-N9*N7) -> 0.15693615
A11: Replicability adjustment for deworming | B11: 0.13 | C11: 0.13 | D11: 0.13 | E11: 0.13 | F11: 0.13 | G11: 0.13 | H11: 0.13 | I11: 0.13 | J11: 0.13 | K11: 0.13 | L11: 0.13 | M11: 0.13 | N11: 0.13
A12: Adjustment for years of treatment in Miguel and Kremer vs. years of treatment in charities' programs | B12: 0.9 | C12: 0.9 | D12: 0.9 | E12: 0.9 | F12: 0.9 | G12: 0.9 | H12: 0.9 | I12: 0.9 | J12: 0.9 | K12: 0.9 | L12: 0.9 | M12: 0.9 | N12: 0.9
A13: Additional years of treatment assigned to the treatment group from Miguel and Kremer | B13: 2.41 | C13: 2.41 | D13: 2.41 | E13: 2.41 | F13: 2.41 | G13: 2.41 | H13: 2.41 | I13: 2.41 | J13: 2.41 | K13: 2.41 | L13: 2.41 | M13: 2.41 | N13: 2.41
A14: Estimated annual treatment effect on the treated after adjustments | B14: =B10*B11/B13*B12 -> 0.0076188917 | C14: =C10*C11/C13*C12 -> 0.0076188917 | D14: =D10*D11/D13*D12 -> 0.0076188917 | E14: =E10*E11/E13*E12 -> 0.0076188917 | F14: =F10*F11/F13*F12 -> 0.0076188917 | G14: =G10*G11/G13*G12 -> 0.0076188917 | H14: =H10*H11/H13*H12 -> 0.0076188917 | I14: =I10*I11/I13*I12 -> 0.0076188917 | ... N14: =N10*N11/N13*N12 -> 0.0076188917
A16: Discount rate | B16: {=index('Moral weights and discount rate'!$1:$39,match("Overall discount rate",'Moral weights and discount rate'!$A:$A,0), match("Active",'Moral weights and discount rate'!$1:$1,0))} -> 0.04 | C16: {=index('Moral weights and discount rate'!$1:$39,match("Overall discount rate",'Moral weights and discount rate'!$A:$A,0), match("Active",'Moral weights and discount rate'!$1:$1,0))} -> 0.04 | D16: {=index('Moral weights and discount rate'!$1:$39,match("Overall discount rate",'Moral weights and discount rate'!$A:$A,0), match("Active",'Moral weights and discount rate'!$1:$1,0))} -> 0.04 | E16: {=index('Moral weights and discount rate'!$1:$39,match("Overall discount rate",'Moral weights and discount rate'!$A:$A,0), match("Active",'Moral weights and discount rate'!$1:$1,0))} -> 0.04 | F16: {=index('Moral weights and discount rate'!$1:$39,match("Overall discount rate",'Moral weights and discount rate'!$A:$A,0), match("Active",'Moral weights and discount rate'!$1:$1,0))} -> 0.04 | G16: {=index('Moral weights and discount rate'!$1:$39,match("Overall discount rate",'Moral weights and discount rate'!$A:$A,0), match("Active",'Moral weights and discount rate'!$1:$1,0))} -> 0.04 | H16: {=index('Moral weights and discount rate'!$1:$39,match("Overall discount rate",'Moral weights and discount rate'!$A:$A,0), match("Active",'Moral weights and discount rate'!$1:$1,0))} -> 0.04 | I16: {=index('Moral weights and discount rate'!$1:$39,match("Overall discount rate",'Moral weights and discount rate'!$A:$A,0), match("Active",'Moral weights and discount rate'!$1:$1,0))} -> 0.04 | ... N16: {=index('Moral weights and discount rate'!$1:$39,match("Overall discount rate",'Moral weights and discount rate'!$A:$A,0), match("Active",'Moral weights and discount rate'!$1:$1,0))} -> 0.04
A17: Average number of years between deworming and the beginning of long-term benefits | B17: 8 | C17: 8 | D17: 8 | E17: 8 | F17: 8 | G17: 8 | H17: 8 | I17: 8 | J17: 8 | K17: 8 | L17: 8 | M17: 8 | N17: 8
A18: Benefit on one year's income (discounted back because of delay between deworming and working for income) | B18: =B14/(1+B16)^B17 -> 0.0055670496 | C18: =C14/(1+C16)^C17 -> 0.0055670496 | D18: =D14/(1+D16)^D17 -> 0.0055670496 | E18: =E14/(1+E16)^E17 -> 0.0055670496 | F18: =F14/(1+F16)^F17 -> 0.0055670496 | G18: =G14/(1+G16)^G17 -> 0.0055670496 | H18: =H14/(1+H16)^H17 -> 0.0055670496 | I18: =I14/(1+I16)^I17 -> 0.0055670496 | ... N18: =N14/(1+N16)^N17 -> 0.0055670496
A19: Duration of long-term benefits of deworming (in years) | B19: 40 | C19: 40 | D19: 40 | E19: 40 | F19: 40 | G19: 40 | H19: 40 | I19: 40 | J19: 40 | K19: 40 | L19: 40 | M19: 40 | N19: 40
A21: Present value of lifetime benefits from a year of deworming (before decay adjustment, in terms of increases in ln(income)) | B21: =pv(B16,B19,-B18,,1) -> 0.11459485 | C21: =pv(C16,C19,-C18,,1) -> 0.11459485 | D21: =pv(D16,D19,-D18,,1) -> 0.11459485 | E21: =pv(E16,E19,-E18,,1) -> 0.11459485 | F21: =pv(F16,F19,-F18,,1) -> 0.11459485 | G21: =pv(G16,G19,-G18,,1) -> 0.11459485 | H21: =pv(H16,H19,-H18,,1) -> 0.11459485 | I21: =pv(I16,I19,-I18,,1) -> 0.11459485 | ... N21: =pv(N16,N19,-N18,,1) -> 0.11459485
A22: Adjustment for benefits decaying over time | B22: -0.1 | C22: -0.1 | D22: -0.1 | E22: -0.1 | F22: -0.1 | G22: -0.1 | H22: -0.1 | I22: -0.1 | J22: -0.1 | K22: -0.1 | L22: -0.1 | M22: -0.1 | N22: -0.1
A23: Present value of lifetime benefits from a year of deworming (after decay adjustment, in terms of increases in ln(income)) | B23: =B21*(1+B22) -> 0.10313536 | C23: =C21*(1+C22) -> 0.10313536 | D23: =D21*(1+D22) -> 0.10313536 | E23: =E21*(1+E22) -> 0.10313536 | F23: =F21*(1+F22) -> 0.10313536 | G23: =G21*(1+G22) -> 0.10313536 | H23: =H21*(1+H22) -> 0.10313536 | I23: =I21*(1+I22) -> 0.10313536 | ... N23: =N21*(1+N22) -> 0.10313536
A25: Multiplier for resource sharing within households | B25: 2 | C25: 2 | D25: 2 | E25: 2 | F25: 2 | G25: 2 | H25: 2 | I25: 2 | J25: 2 | K25: 2 | L25: 2 | M25: 2 | N25: 2
A27: Adjusted long-term benefits per year of deworming per person assigned to treatment in terms of ln(consumption) | B27: =B25*B23 -> 0.20627072 | C27: =C25*C23 -> 0.20627072 | D27: =D25*D23 -> 0.20627072 | E27: =E25*E23 -> 0.20627072 | F27: =F25*F23 -> 0.20627072 | G27: =G25*G23 -> 0.20627072 | H27: =H25*H23 -> 0.20627072 | I27: =I25*I23 -> 0.20627072 | ... N27: =N25*N23 -> 0.20627072
A29: Funding allocation
A31: Percentage of total costs covered by Deworm the World | B31: 0.6082843 | C31: 0.4014779 | D31: 0.4014779 | E31: 0.4014779 | F31: 0.4014779 | G31: 0.4014779 | H31: 0.4014779 | I31: 0.4014779 | J31: 0.6735345 | K31: 0.6084396 | L31: 0.62703532 | M31: 0.6220757 | N31: 0.58940161
A32: Percentage of total costs covered by other philanthropic actors | B32: 0.0234169 | C32: 0.2573664 | D32: 0.2573664 | E32: 0.2573664 | F32: 0.2573664 | G32: 0.2573664 | H32: 0.2573664 | I32: 0.2573664 | J32: 0 | K32: 0.0090019 | L32: 0 | M32: 0.023113655 | N32: 0.035189769
A33: Percentage of total costs covered by domestic governments (financial costs) | B33: 0.009947 | C33: 0 | D33: 0 | E33: 0 | F33: 0 | G33: 0 | H33: 0 | I33: 0 | J33: 0 | K33: 0 | L33: 0 | M33: 0 | N33: 0.0015079661
A34: Percentage of total costs covered by domestic governments (in-kind costs) | B34: 0.3 | C34: 0.3 | D34: 0.3 | E34: 0.3 | F34: 0.3 | G34: 0.3 | H34: 0.3 | I34: 0.3 | J34: 0.2999999 | K34: 0.3000001 | L34: 0.3 | M34: 0.3 | N34: 0.3
A35: Percentage of total costs covered by drug donations | B35: 0.0583518 | C35: 0.0411558 | D35: 0.0411558 | E35: 0.0411558 | F35: 0.0411558 | G35: 0.0411558 | H35: 0.0411558 | I35: 0.0411558 | J35: 0.0264655 | K35: 0.0825584 | L35: 0.072964622 | M35: 0.054810638 | N35: 0.073900651
A37: Number of children dewormed per year
A39: Donation to Deworm the World (arbitrary size) | B39: 100000 | C39: 100000 | D39: 100000 | E39: 100000 | F39: 100000 | G39: 100000 | H39: 100000 | I39: 100000 | J39: 100000 | K39: 100000 | L39: 100000 | M39: 100000 | N39: 100000
A40: Total spending by all contributors | B40: =B39/B31 -> 164396.81 | C40: =C39/C31 -> 249079.71 | D40: =D39/D31 -> 249079.71 | E40: =E39/E31 -> 249079.71 | F40: =F39/F31 -> 249079.71 | G40: =G39/G31 -> 249079.71 | H40: =H39/H31 -> 249079.71 | I40: =I39/I31 -> 249079.71 | ... N40: =N39/N31 -> 169663.6
A41: Proportion of deworming going to children — DtW | B41: 1 | C41: 1 | D41: 1 | E41: 1 | F41: 1 | G41: 1 | H41: 1 | I41: 1 | J41: 1 | K41: 1 | L41: 1 | M41: 1 | N41: 1
A42: Worm burden adjustment — DtW | B42: 0.20523514 | C42: 0.0355752 | D42: 0.0128676 | E42: 0.1264055 | F42: 0.0075692 | G42: 0.0531569 | H42: 0.0075692 | I42: 0.0128676 | J42: 0.070053262 | K42: 0.11076949 | L42: 0.20523514 | M42: 0.083261082 | N42: 0.12338307
A43: Present value of lifetime benefits from a year of deworming — in terms of increases in ln(consumption) — DtW | B43: =B27*B41*B42 -> 0.042334002 | C43: =C27*C41*C42 -> 0.0073381223 | D43: =D27*D41*D42 -> 0.0026542092 | E43: =E27*E41*E42 -> 0.026073754 | F43: =F27*F41*F42 -> 0.0015613044 | G43: =G27*G41*G42 -> 0.010964712 | H43: =H27*H41*H42 -> 0.0015613044 | I43: =I27*I41*I42 -> 0.0026542092 | ... N43: =N27*N41*N42 -> 0.025450316
A44: Value assigned to increasing ln(consumption) by one unit for one person for one year | B44: {=index('Moral weights and discount rate'!$A$1:$ZU$39,match($A44,'Moral weights and discount rate'!$A$1:$A$39,0),match('Moral weights and discount rate'!$A$17,'Moral weights and discount rate'!$A$1:$ZU1,0))} -> 1.442695 | C44: {=index('Moral weights and discount rate'!$A$1:$ZU$39,match($A44,'Moral weights and discount rate'!$A$1:$A$39,0),match('Moral weights and discount rate'!$A$17,'Moral weights and discount rate'!$A$1:$ZU1,0))} -> 1.442695 | D44: {=index('Moral weights and discount rate'!$A$1:$ZU$39,match($A44,'Moral weights and discount rate'!$A$1:$A$39,0),match('Moral weights and discount rate'!$A$17,'Moral weights and discount rate'!$A$1:$ZU1,0))} -> 1.442695 | E44: {=index('Moral weights and discount rate'!$A$1:$ZU$39,match($A44,'Moral weights and discount rate'!$A$1:$A$39,0),match('Moral weights and discount rate'!$A$17,'Moral weights and discount rate'!$A$1:$ZU1,0))} -> 1.442695 | F44: {=index('Moral weights and discount rate'!$A$1:$ZU$39,match($A44,'Moral weights and discount rate'!$A$1:$A$39,0),match('Moral weights and discount rate'!$A$17,'Moral weights and discount rate'!$A$1:$ZU1,0))} -> 1.442695 | G44: {=index('Moral weights and discount rate'!$A$1:$ZU$39,match($A44,'Moral weights and discount rate'!$A$1:$A$39,0),match('Moral weights and discount rate'!$A$17,'Moral weights and discount rate'!$A$1:$ZU1,0))} -> 1.442695 | H44: {=index('Moral weights and discount rate'!$A$1:$ZU$39,match($A44,'Moral weights and discount rate'!$A$1:$A$39,0),match('Moral weights and discount rate'!$A$17,'Moral weights and discount rate'!$A$1:$ZU1,0))} -> 1.442695 | I44: {=index('Moral weights and discount rate'!$A$1:$ZU$39,match($A44,'Moral weights and discount rate'!$A$1:$A$39,0),match('Moral weights and discount rate'!$A$17,'Moral weights and discount rate'!$A$1:$ZU1,0))} -> 1.442695 | ... N44: {=index('Moral weights and discount rate'!$A$1:$ZU$39,match($A44,'Moral weights and discount rate'!$A$1:$A$39,0),match('Moral weights and discount rate'!$A$17,'Moral weights and discount rate'!$A$1:$ZU1,0))} -> 1.442695
A45: Units of value from each year of deworming — DtW | B45: =(B43*B44) -> 0.061075054 | C45: =(C43*C44) -> 0.010586673 | D45: =(D43*D44) -> 0.0038292144 | E45: =(E43*E44) -> 0.037616476 | F45: =(F43*F44) -> 0.0022524861 | G45: =(G43*G44) -> 0.015818736 | H45: =(H43*H44) -> 0.0022524861 | I45: =(I43*I44) -> 0.0038292144 | ... N45: =(N43*N44) -> 0.036717045
A46: Cost per child dewormed (per year) — DtW | B46: 0.64757 | C46: 0.74247 | D46: 0.74247 | E46: 0.74247 | F46: 0.74247 | G46: 0.74247 | H46: 0.74247 | I46: 0.74247 | J46: 0.75506 | K46: 0.78975 | L46: 1.5182461 | M46: 0.74800772 | N46: 1.1612276
A47: Total number of children dewormed (per year) — DtW | B47: =B40/B46 -> 253867.25 | C47: =C40/C46 -> 335474.45 | D47: =D40/D46 -> 335474.45 | E47: =E40/E46 -> 335474.45 | F47: =F40/F46 -> 335474.45 | G47: =G40/G46 -> 335474.45 | H47: =H40/H46 -> 335474.45 | I47: =I40/I46 -> 335474.45 | ... N47: =N40/N46 -> 146107.1
A49: Intuition check
A51: Aggregate adjustment to Miguel and Kremer development effect — DtW | B51: =product(B11:B12,B42) -> 0.024012512 | C51: =product(C11:C12,C42) -> 0.0041622984 | D51: =product(D11:D12,D42) -> 0.0015055092 | E51: =product(E11:E12,E42) -> 0.014789444 | F51: =product(F11:F12,F42) -> 0.0008855964 | G51: =product(G11:G12,G42) -> 0.0062193573 | H51: =product(H11:H12,H42) -> 0.0008855964 | I51: =product(I11:I12,I42) -> 0.0015055092 | ... N51: =product(N11:N12,N42) -> 0.01443582
A53: Initial results
A55: =A43 -> Present value of lifetime benefits from a year of deworming — in terms of increases in ln(consumption) — DtW | B55: =B43 -> 0.042334002 | C55: =C43 -> 0.0073381223 | D55: =D43 -> 0.0026542092 | E55: =E43 -> 0.026073754 | F55: =F43 -> 0.0015613044 | G55: =G43 -> 0.010964712 | H55: =H43 -> 0.0015613044 | ... N55: =N43 -> 0.025450316
A56: =A44 -> Value assigned to increasing ln(consumption) by one unit for one person for one year | B56: =B44 -> 1.442695 | C56: =C44 -> 1.442695 | D56: =D44 -> 1.442695 | E56: =E44 -> 1.442695 | F56: =F44 -> 1.442695 | G56: =G44 -> 1.442695 | H56: =H44 -> 1.442695 | ... N56: =N44 -> 1.442695
...

Sheet Unlimit Health
A1: Deworming - Unlimit Health (formerly known as the SCI Foundation (SCI)) | B1: Overall | C1: Ethiopia | D1: DRC | E1: Madagascar | F1: Tanzania | G1: Cote d'Ivoire | H1: Uganda | I1: Liberia | J1: Burundi | K1: Pemba, Zanzibar | L1: Unguja, Zanzibar | M1: Sudan | N1: Niger | O1: Mauritania | P1: Malawi
A5: Funding allocation
A7: Percentage of funding to be allocated to each country with marginal donations | B7: =sum(C7:P7) -> 1 | C7: 0.23409826 | D7: 0.073032089 | E7: 0.13149468 | F7: 0.16606921 | G7: 0.05870865 | H7: 0.12965205 | I7: 0.012521109 | J7: 0.037635034 | K7: 0.003980788 | L7: 0.01496666 | M7: 0.095184572 | N7: 0.013281741 | O7: 0.0079960109 | P7: 0.021379152
A8: Percentage of total costs covered by Unlimit Health | B8: =B15/B16 -> 0.3881312 | C8: 0.3881312 | D8: 0.3881312 | E8: 0.3881312 | F8: 0.3881312 | G8: 0.3881312 | H8: 0.3881312 | I8: 0.3881312 | J8: 0.3881312 | K8: 0.3881312 | L8: 0.3881312 | M8: 0.3881312 | N8: 0.3881312 | O8: 0.3881312 | P8: 0.3881312
A9: Percentage of total costs covered by domestic governments (financial costs) | B9: =sumproduct(C9:I9,$C$16:$I$16)/sum($C$16:$I$16) -> 0 | C9: 0 | D9: 0 | E9: 0 | F9: 0 | G9: 0 | H9: 0 | I9: 0 | J9: 0 | K9: 0 | L9: 0 | M9: 0 | N9: 0 | O9: 0 | P9: 0
A10: Percentage of total costs covered by domestic governments (in-kind costs) | B10: =sumproduct(C10:I10,$C$16:$I$16)/sum($C$16:$I$16) -> 0.3 | C10: 0.3 | D10: 0.3 | E10: 0.3 | F10: 0.3 | G10: 0.3 | H10: 0.3 | I10: 0.3 | J10: 0.3 | K10: 0.3 | L10: 0.3 | M10: 0.3 | N10: 0.3 | O10: 0.3 | P10: 0.3
A11: Percentage of total costs covered by drug donations | B11: =sumproduct(C11:I11,$C$16:$I$16)/sum($C$16:$I$16) -> 0.3118688 | C11: 0.3118688 | D11: 0.3118688 | E11: 0.3118688 | F11: 0.3118688 | G11: 0.3118688 | H11: 0.3118688 | I11: 0.3118688 | J11: 0.3118688 | K11: 0.3118688 | L11: 0.3118688 | M11: 0.3118688 | N11: 0.3118688 | O11: 0.3118688 | P11: 0.3118688
A13: Number of children dewormed per year with hypothetical donation (Unlimit Health)
A15: Donation to Unlimit Health (arbitrary size) | B15: 100000 | C15: =100000*C7 -> 23409.826 | D15: =100000*D7 -> 7303.2089 | E15: =100000*E7 -> 13149.468 | F15: =100000*F7 -> 16606.921 | G15: =100000*G7 -> 5870.865 | H15: =100000*H7 -> 12965.205 | I15: =100000*I7 -> 1252.1109 | J15: =100000*J7 -> 3763.5034 | ... P15: =100000*P7 -> 2137.9152
A16: Total amount spent on the program by all contributors | B16: =sum(C16:P16) -> 257644.84 | C16: =C15/C8 -> 60314.207 | D16: =D15/D8 -> 18816.341 | E16: =E15/E8 -> 33878.925 | F16: =F15/F8 -> 42786.874 | G16: =G15/G8 -> 15125.98 | H16: =H15/H8 -> 33404.181 | I16: =I15/I8 -> 3225.9991 | J16: =J15/J8 -> 9696.472 | ... P16: =P15/P8 -> 5508.228
A17: Proportion of deworming going to children — Unlimit Health | B17: =sumproduct(C17:P17,C25:P25) -> 0.7862708 | C17: 0.72849882 | D17: 0.93731113 | E17: 1 | F17: 0.90816869 | G17: 1 | H17: 0.45794467 | I17: 0.70588969 | J17: 1 | K17: 0.25308255 | L17: 0.25308255 | M17: 0.72033591 | N17: 0.38242939 | O17: 1 | P17: 0.65353516
A18: Worm burden adjustment — Unlimit Health | B18: =sumproduct(C18:P18,C25:P25) -> 0.092104387 | C18: 0.05674557 | D18: 0.20523514 | E18: 0.20523514 | F18: 0.069440209 | G18: 0.092644434 | H18: 0.0090417406 | I18: 0.16756656 | J18: 0.12586874 | K18: 0.033399067 | L18: 0.0061850125 | M18: 0.075454864 | N18: 0.043687841 | O18: 0.20523514 | P18: 0.10463036
A19: Adjusted long-term benefits per year of deworming per person treated in terms of ln(consumption) | B19: ='Deworm the World'!$B$27 -> 0.20627072 | C19: ='Deworm the World'!$B$27 -> 0.20627072 | D19: ='Deworm the World'!$B$27 -> 0.20627072 | E19: ='Deworm the World'!$B$27 -> 0.20627072 | F19: ='Deworm the World'!$B$27 -> 0.20627072 | G19: ='Deworm the World'!$B$27 -> 0.20627072 | H19: ='Deworm the World'!$B$27 -> 0.20627072 | I19: ='Deworm the World'!$B$27 -> 0.20627072 | ... P19: ='Deworm the World'!$B$27 -> 0.20627072
A20: Present value of lifetime benefits from a year of deworming — in terms of increases in ln(consumption) — Unlimit Health | B20: =B19*B17*B18 -> 0.014937918 | C20: =C19*C17*C18 -> 0.0085270421 | D20: =D19*D17*D18 -> 0.039680131 | E20: =E19*E17*E18 -> 0.042334002 | F20: =F19*F17*F18 -> 0.013008138 | G20: =G19*G17*G18 -> 0.019109835 | H20: =H19*H17*H18 -> 0.00085408805 | I20: =I19*I17*I18 -> 0.024398425 | ... P20: =P19*P17*P18 -> 0.014104713
A21: Value assigned to increasing ln(consumption) by one unit for one person for one year | B21: {=index('Moral weights and discount rate'!$A$1:$ZU$39,match($A21,'Moral weights and discount rate'!$A$1:$A$39,0),match('Moral weights and discount rate'!$A$17,'Moral weights and discount rate'!$A$1:$ZU$1,0))} -> 1.442695 | C21: {=index('Moral weights and discount rate'!$A$1:$ZU$39,match($A21,'Moral weights and discount rate'!$A$1:$A$39,0),match('Moral weights and discount rate'!$A$17,'Moral weights and discount rate'!$A$1:$ZU$1,0))} -> 1.442695 | D21: {=index('Moral weights and discount rate'!$A$1:$ZU$39,match($A21,'Moral weights and discount rate'!$A$1:$A$39,0),match('Moral weights and discount rate'!$A$17,'Moral weights and discount rate'!$A$1:$ZU$1,0))} -> 1.442695 | E21: {=index('Moral weights and discount rate'!$A$1:$ZU$39,match($A21,'Moral weights and discount rate'!$A$1:$A$39,0),match('Moral weights and discount rate'!$A$17,'Moral weights and discount rate'!$A$1:$ZU$1,0))} -> 1.442695 | F21: {=index('Moral weights and discount rate'!$A$1:$ZU$39,match($A21,'Moral weights and discount rate'!$A$1:$A$39,0),match('Moral weights and discount rate'!$A$17,'Moral weights and discount rate'!$A$1:$ZU$1,0))} -> 1.442695 | G21: {=index('Moral weights and discount rate'!$A$1:$ZU$39,match($A21,'Moral weights and discount rate'!$A$1:$A$39,0),match('Moral weights and discount rate'!$A$17,'Moral weights and discount rate'!$A$1:$ZU$1,0))} -> 1.442695 | H21: {=index('Moral weights and discount rate'!$A$1:$ZU$39,match($A21,'Moral weights and discount rate'!$A$1:$A$39,0),match('Moral weights and discount rate'!$A$17,'Moral weights and discount rate'!$A$1:$ZU$1,0))} -> 1.442695 | I21: {=index('Moral weights and discount rate'!$A$1:$ZU$39,match($A21,'Moral weights and discount rate'!$A$1:$A$39,0),match('Moral weights and discount rate'!$A$17,'Moral weights and discount rate'!$A$1:$ZU$1,0))} -> 1.442695 | ... P21: {=index('Moral weights and discount rate'!$A$1:$ZU$39,match($A21,'Moral weights and discount rate'!$A$1:$A$39,0),match('Moral weights and discount rate'!$A$17,'Moral weights and discount rate'!$A$1:$ZU$1,0))} -> 1.442695
A22: Units of value from each year of deworming — Unlimit Health | B22: =(B20*$B$21) -> 0.02155086 | C22: =(C20*C21) -> 0.012301921 | D22: =(D20*D21) -> 0.057246328 | E22: =(E20*E21) -> 0.061075054 | F22: =(F20*F21) -> 0.018766776 | G22: =(G20*G21) -> 0.027569664 | H22: =(H20*H21) -> 0.0012321886 | I22: =(I20*I21) -> 0.035199486 | J22: =(J20*J21) -> 0.037456743 | ... P22: =(P20*P21) -> 0.0203488
A23: Cost per person dewormed (per year) — Unlimit Health | B23: 1.0289662 | C23: 1.0289662 | D23: 1.0289662 | E23: 1.0289662 | F23: 1.0289662 | G23: 1.0289662 | H23: 1.0289662 | I23: 1.0289662 | J23: 1.0289662 | K23: 1.0289662 | L23: 1.0289662 | M23: 1.0289662 | N23: 1.0289662 | O23: 1.0289662 | P23: 1.0289662
A24: Total number of children dewormed (per year) — Unlimit Health | B24: =sum(C24:P24) -> 250391.93 | C24: =C16/C23 -> 58616.314 | D24: =D16/D23 -> 18286.646 | E24: =E16/E23 -> 32925.206 | F24: =F16/F23 -> 41582.389 | G24: =G16/G23 -> 14700.172 | H24: =H16/H23 -> 32463.827 | I24: =I16/I23 -> 3135.1846 | J24: =J16/J23 -> 9423.5086 | ... P24: =P16/P23 -> 5353.167
A25: Percentage of children dewormed (per year) in each country | B25: =sum(C25:P25) -> 1 | C25: =C24/$B$24 -> 0.23409826 | D25: =D24/$B$24 -> 0.073032089 | E25: =E24/$B$24 -> 0.13149468 | F25: =F24/$B$24 -> 0.16606921 | G25: =G24/$B$24 -> 0.05870865 | H25: =H24/$B$24 -> 0.12965205 | I25: =I24/$B$24 -> 0.012521109 | J25: =J24/$B$24 -> 0.037635034 | ... P25: =P24/$B$24 -> 0.021379152
A28: Intuition check
A30: Aggregate adjustment to Miguel and Kremer development effect — Unlimit Health | B30: =product('Deworm the World'!$B$11:$B$12,B18) -> 0.010776213 | C30: =product('Deworm the World'!$B$11:$B$12,C18) -> 0.0066392317 | D30: =product('Deworm the World'!$B$11:$B$12,D18) -> 0.024012512 | E30: =product('Deworm the World'!$B$11:$B$12,E18) -> 0.024012512 | F30: =product('Deworm the World'!$B$11:$B$12,F18) -> 0.0081245045 | G30: =product('Deworm the World'!$B$11:$B$12,G18) -> 0.010839399 | H30: =product('Deworm the World'!$B$11:$B$12,H18) -> 0.0010578837 | I30: =product('Deworm the World'!$B$11:$B$12,I18) -> 0.019605287 | ... P30: =product('Deworm the World'!$B$11:$B$12,P18) -> 0.012241752
A32: Initial results
A34: =A20 -> Present value of lifetime benefits from a year of deworming — in terms of increases in ln(consumption) — Unlimit Health | B34: =B20 -> 0.014937918 | C34: =C20 -> 0.0085270421 | D34: =D20 -> 0.039680131 | E34: =E20 -> 0.042334002 | F34: =F20 -> 0.013008138 | G34: =G20 -> 0.019109835 | H34: =H20 -> 0.00085408805 | ... P34: =P20 -> 0.014104713
A35: =A21 -> Value assigned to increasing ln(consumption) by one unit for one person for one year | B35: =B21 -> 1.442695 | C35: =C21 -> 1.442695 | D35: =D21 -> 1.442695 | E35: =E21 -> 1.442695 | F35: =F21 -> 1.442695 | G35: =G21 -> 1.442695 | H35: =H21 -> 1.442695 | ... P35: =P21 -> 1.442695
A36: =A24 -> Total number of children dewormed (per year) — Unlimit Health | B36: =B24 -> 250391.93 | C36: =C24 -> 58616.314 | D36: =D24 -> 18286.646 | E36: =E24 -> 32925.206 | F36: =F24 -> 41582.389 | G36: =G24 -> 14700.172 | H36: =H24 -> 32463.827 | ... P36: =P24 -> 5353.167
A37: Total units of value generated, before accounting for leverage and funging | B37: =sum(C37:P37) -> 6105.3201 | C37: =product(C34:C36) -> 721.09328 | D37: =product(D34:D36) -> 1046.8433 | E37: =product(E34:E36) -> 2010.9088 | F37: =product(F34:F36) -> 780.36739 | G37: =product(G34:G36) -> 405.27879 | H37: =product(H34:H36) -> 40.001557 | I37: =product(I34:I36) -> 110.35689 | J37: =product(J34:J36) -> 352.97393 | ... P37: =product(P34:P36) -> 108.93052
A38: Units of value generated per dollar spent, before accounting for leverage/funging | B38: =B37/B16 -> 0.023696652 | C38: =C37/C16 -> 0.011955612 | D38: =D37/D16 -> 0.055634798 | E38: =E37/E16 -> 0.059355742 | F38: =F37/F16 -> 0.018238477 | G38: =G37/G16 -> 0.026793555 | H38: =H37/H16 -> 0.0011975015 | I38: =I37/I16 -> 0.034208592 | ... P38: =P37/P16 -> 0.019775965
A40: Initial cost-effectiveness estimate in multiples of cash transfers | B40: {=B38/index(GiveDirectly!$B:$B,match("Units of value generated per philanthropic dollar spent, after accounting for all adjustments",GiveDirectly!$A:$A,0))} -> 7.0640669 | C40: {=C38/index(GiveDirectly!$B:$B,match("Units of value generated per philanthropic dollar spent, after accounting for all adjustments",GiveDirectly!$A:$A,0))} -> 3.5640159 | D40: {=D38/index(GiveDirectly!$B:$B,match("Units of value generated per philanthropic dollar spent, after accounting for all adjustments",GiveDirectly!$A:$A,0))} -> 16.584956 | E40: {=E38/index(GiveDirectly!$B:$B,match("Units of value generated per philanthropic dollar spent, after accounting for all adjustments",GiveDirectly!$A:$A,0))} -> 17.694185 | F40: {=F38/index(GiveDirectly!$B:$B,match("Units of value generated per philanthropic dollar spent, after accounting for all adjustments",GiveDirectly!$A:$A,0))} -> 5.4369629 | G40: {=G38/index(GiveDirectly!$B:$B,match("Units of value generated per philanthropic dollar spent, after accounting for all adjustments",GiveDirectly!$A:$A,0))} -> 7.9872662 | H40: {=H38/index(GiveDirectly!$B:$B,match("Units of value generated per philanthropic dollar spent, after accounting for all adjustments",GiveDirectly!$A:$A,0))} -> 0.35697999 | I40: {=I38/index(GiveDirectly!$B:$B,match("Units of value generated per philanthropic dollar spent, after accounting for all adjustments",GiveDirectly!$A:$A,0))} -> 10.197718 | ... P40: {=P38/index(GiveDirectly!$B:$B,match("Units of value generated per philanthropic dollar spent, after accounting for all adjustments",GiveDirectly!$A:$A,0))} -> 5.8952943
A42: Supplemental charity-level adjustments — Unlimit Health
A44: Risk of wastage
A45: Double treatment | B45: 0 | C45: 0 | D45: 0 | E45: 0 | F45: 0 | G45: 0 | H45: 0 | I45: 0 | J45: 0 | K45: 0 | L45: 0 | M45: 0 | N45: 0 | O45: 0 | P45: 0
A46: Ineffective goods | B46: 0 | C46: 0 | D46: 0 | E46: 0 | F46: 0 | G46: 0 | H46: 0 | I46: 0 | J46: 0 | K46: 0 | L46: 0 | M46: 0 | N46: 0 | O46: 0 | P46: 0
A47: Goods purchased and left in storage until they expire / Cash doesn't reach recipients or is taken back from them inappropriately | B47: 0 | C47: 0 | D47: 0 | E47: 0 | F47: 0 | G47: 0 | H47: 0 | I47: 0 | J47: 0 | K47: 0 | L47: 0 | M47: 0 | N47: 0 | O47: 0 | P47: 0
A48: Total adjustment for risk of wastage | B48: =SUM(B45:B47) -> 0 | C48: =SUM(C45:C47) -> 0 | D48: =SUM(D45:D47) -> 0 | E48: =SUM(E45:E47) -> 0 | F48: =SUM(F45:F47) -> 0 | G48: =SUM(G45:G47) -> 0 | H48: =SUM(H45:H47) -> 0 | I48: =SUM(I45:I47) -> 0 | ... P48: =SUM(P45:P47) -> 0
A50: Quality of monitoring and evaluation
A51: Misappropriation without monitoring results | B51: 0.1 | C51: 0.1 | D51: 0.1 | E51: 0.1 | F51: 0.1 | G51: 0.1 | H51: 0.1 | I51: 0.1 | J51: 0.1 | K51: 0.1 | L51: 0.1 | M51: 0.1 | N51: 0.1 | O51: 0.1 | P51: 0.1
A52: False monitoring results | B52: 0.05 | C52: 0.05 | D52: 0.05 | E52: 0.05 | F52: 0.05 | G52: 0.05 | H52: 0.05 | I52: 0.05 | J52: 0.05 | K52: 0.05 | L52: 0.05 | M52: 0.05 | N52: 0.05 | O52: 0.05 | P52: 0.05
A53: Total adjustment for quality of monitoring and evaluation | B53: =sum(B50:B52) -> 0.15 | C53: =sum(C50:C52) -> 0.15 | D53: =sum(D50:D52) -> 0.15 | E53: =sum(E50:E52) -> 0.15 | F53: =sum(F50:F52) -> 0.15 | G53: =sum(G50:G52) -> 0.15 | H53: =sum(H50:H52) -> 0.15 | I53: =sum(I50:I52) -> 0.15 | ... P53: =sum(P50:P52) -> 0.15
A55: Confidence in funds being used for intended purpose
A56: Change of priorities | B56: 0 | C56: 0 | D56: 0 | E56: 0 | F56: 0 | G56: 0 | H56: 0 | I56: 0 | J56: 0 | K56: 0 | L56: 0 | M56: 0 | N56: 0 | O56: 0 | P56: 0
...

Sheet Sightsavers
B1: Senegal | C1: Chad, Priority 1 areas | D1: Chad, Priority 2 areas | E1: Bas Uele, DRC | F1: Haut Katanga, DRC | G1: Haut Lomami, DRC | H1: Haut Uele, DRC | I1: Ituri, DRC | J1: Kasai, DRC | K1: Kasai Central, DRC | L1: Kasai Oriental, DRC | M1: Kinshasa, DRC | N1: Kongo Central, DRC | O1: Lomami, DRC | P1: Mai Ndombe, DRC | Q1: Nord Ubangi, DRC | R1: Sud Kivu, DRC | S1: Tanganyika, DRC | T1: Tshopo, DRC | U1: West, Cameroon | V1: North, Cameroon | W1: Far-North, Cameroon | X1: East, Cameroon | Y1: Adamoua, Cameroon | Z1: Littoral, Cameroon | AA1: South, Cameroon | AB1: Benue State | AC1: Kebbi State | AD1: Kogi State | AE1: Kwara State | AF1: Sokoto State | AG1: Taraba State | AH1: Yobe State | AI1: Kaduna State | AJ1: Kano State | AK1: Katsina State | AL1: Niger State | AM1: Adamawa State | AN1: Zamfara State | AO1: Guinea-Bissau
A5: Funding allocation
A7: Percentage of total costs covered by Sightsavers | B7: 0.5983684 | C7: 0.4287292 | D7: 0.5182276 | E7: 0.4511091 | F7: 0.4511091 | G7: 0.4511091 | H7: 0.4511091 | I7: 0.4511091 | J7: 0.4511091 | K7: 0.4511091 | L7: 0.4511091 | M7: 0.4511091 | N7: 0.4511091 | O7: 0.4511091 | P7: 0.4511091 | Q7: 0.4511091 | R7: 0.4511091 | S7: 0.4511091 | T7: 0.4511091 | U7: 0.466908 | V7: 0.466908 | W7: 0.466908 | X7: 0.466908 | Y7: 0.466908 | Z7: 0.466908 | AA7: 0.466908 | AB7: 0.3969397 | AC7: 0.3396181 | AD7: 0.3396181 | AE7: 0.3396181 | AF7: 0.3396181 | AG7: 0.4020451 | AH7: 0.4577311 | AI7: 0.4257635 | AJ7: 0.4257635 | AK7: 0.4257635 | AL7: 0.4257635 | AM7: 0.4257635 | AN7: 0.4257635 | AO7: 0.6650286
A8: Percentage of total costs covered by domestic governments | B8: 0.3 | C8: 0.3 | D8: 0.3 | E8: 0.3 | F8: 0.3 | G8: 0.3 | H8: 0.3 | I8: 0.3 | J8: 0.3 | K8: 0.3 | L8: 0.3 | M8: 0.3 | N8: 0.3 | O8: 0.3 | P8: 0.3 | Q8: 0.3 | R8: 0.3 | S8: 0.3 | T8: 0.3 | U8: 0.3 | V8: 0.3 | W8: 0.3 | X8: 0.3 | Y8: 0.3 | Z8: 0.3 | AA8: 0.3 | AB8: 0.3 | AC8: 0.3 | AD8: 0.3 | AE8: 0.3 | AF8: 0.3 | AG8: 0.3 | AH8: 0.3 | AI8: 0.3 | AJ8: 0.3 | AK8: 0.3 | AL8: 0.3 | AM8: 0.3 | AN8: 0.3 | AO8: 0.3
A9: Percentage of total costs covered by drug donations | B9: 0.1016316 | C9: 0.2712708 | D9: 0.1817724 | E9: 0.2488909 | F9: 0.2488909 | G9: 0.2488909 | H9: 0.2488909 | I9: 0.2488909 | J9: 0.2488909 | K9: 0.2488909 | L9: 0.2488909 | M9: 0.2488909 | N9: 0.2488909 | O9: 0.2488909 | P9: 0.2488909 | Q9: 0.2488909 | R9: 0.2488909 | S9: 0.2488909 | T9: 0.2488909 | U9: 0.233092 | V9: 0.233092 | W9: 0.233092 | X9: 0.233092 | Y9: 0.233092 | Z9: 0.233092 | AA9: 0.233092 | AB9: 0.3030603 | AC9: 0.3603819 | AD9: 0.3603819 | AE9: 0.3603819 | AF9: 0.3603819 | AG9: 0.2979549 | AH9: 0.2422689 | AI9: 0.2742365 | AJ9: 0.2742365 | AK9: 0.2742365 | AL9: 0.2742365 | AM9: 0.2742365 | AN9: 0.2742365 | AO9: 0.0349714
A11: Number of children dewormed per year with hypothetical donation (Sightsavers)
A13: Donation to Sightsavers (arbitrary size) | B13: 100000 | C13: 100000 | D13: 100000 | E13: 100000 | F13: 100000 | G13: 100000 | H13: 100000 | I13: 100000 | J13: 100000 | K13: 100000 | L13: 100000 | M13: 100000 | N13: 100000 | O13: 100000 | P13: 100000 | Q13: 100000 | R13: 100000 | S13: 100000 | T13: 100000 | U13: 100000 | V13: 100000 | W13: 100000 | X13: 100000 | Y13: 100000 | Z13: 100000 | AA13: 100000 | AB13: 100000 | AC13: 100000 | AD13: 100000 | AE13: 100000 | AF13: 100000 | AG13: 100000 | AH13: 100000 | AI13: 100000 | AJ13: 100000 | AK13: 100000 | AL13: 100000 | AM13: 100000 | AN13: 100000 | AO13: 100000
A14: Total amount spent on the program by all contributors | B14: =B13/B7 -> 167121.12 | C14: =C13/C7 -> 233247.47 | D14: =D13/D7 -> 192965.41 | E14: =E13/E7 -> 221675.87 | F14: =F13/F7 -> 221675.87 | G14: =G13/G7 -> 221675.87 | H14: =H13/H7 -> 221675.87 | I14: =I13/I7 -> 221675.87 | ... AO14: =AO13/AO7 -> 150369.47
A15: Proportion of deworming going to children — Sightsavers | B15: 1 | C15: 1 | D15: 1 | E15: 1 | F15: 1 | G15: 1 | H15: 1 | I15: 1 | J15: 1 | K15: 1 | L15: 1 | M15: 1 | N15: 1 | O15: 1 | P15: 1 | Q15: 1 | R15: 1 | S15: 1 | T15: 1 | U15: 1 | V15: 1 | W15: 1 | X15: 1 | Y15: 1 | Z15: 1 | AA15: 1 | AB15: 1 | AC15: 1 | AD15: 1 | AE15: 1 | AF15: 1 | AG15: 1 | AH15: 1 | AI15: 1 | AJ15: 1 | AK15: 1 | AL15: 1 | AM15: 1 | AN15: 1 | AO15: 1
A16: Worm burden adjustment — Sightsavers | B16: 0.0503918 | C16: 0.1790904 | D16: 0.1793355 | E16: 0.1502089 | F16: 0.107008 | G16: 0.0825506 | H16: 0.0593199 | I16: 0.1232411 | J16: 0.0365127 | K16: 0.0281174 | L16: 0.1976973 | M16: 0.0090277 | N16: 0.1976973 | O16: 0.1761263 | P16: 0.019004 | Q16: 0.1077984 | R16: 0.0628656 | S16: 0.0481668 | T16: 0.1000329 | U16: 0.0382545 | V16: 0.1189598 | W16: 0.093283 | X16: 0.050537 | Y16: 0.05922 | Z16: 0.0122405 | AA16: 0.067867 | AB16: 0.0827056 | AC16: 0.0861491 | AD16: 0.0732903 | AE16: 0.1063387 | AF16: 0.1069378 | AG16: 0.0379111 | AH16: 0.0499738 | AI16: 0.1794266 | AJ16: 0.0927923 | AK16: 0.0535485 | AL16: 0.1946866 | AM16: 0.1230215 | AN16: 0.1946866 | AO16: 0.013708
A17: Adjusted long-term benefits per year of deworming per person treated in terms of ln(consumption) | B17: ='Deworm the World'!$B$27 -> 0.20627072 | C17: ='Deworm the World'!$B$27 -> 0.20627072 | D17: ='Deworm the World'!$B$27 -> 0.20627072 | E17: ='Deworm the World'!$B$27 -> 0.20627072 | F17: ='Deworm the World'!$B$27 -> 0.20627072 | G17: ='Deworm the World'!$B$27 -> 0.20627072 | H17: ='Deworm the World'!$B$27 -> 0.20627072 | I17: ='Deworm the World'!$B$27 -> 0.20627072 | ... AO17: ='Deworm the World'!$B$27 -> 0.20627072
A18: Present value of lifetime benefits from a year of deworming — in terms of increases in ln(consumption) | B18: =B16*B15*B17 -> 0.010394353 | C18: =C16*C15*C17 -> 0.036941107 | D18: =D16*D15*D17 -> 0.036991664 | E18: =E16*E15*E17 -> 0.030983699 | F18: =F16*F15*F17 -> 0.022072618 | G18: =G16*G15*G17 -> 0.017027772 | H18: =H16*H15*H17 -> 0.012235959 | I18: =I16*I15*I17 -> 0.025421031 | ... AO18: =AO16*AO15*AO17 -> 0.0028275591
A19: Value assigned to increasing ln(consumption) by one unit for one person for one year | B19: {=index('Moral weights and discount rate'!$A$1:$ZU$39,match($A19,'Moral weights and discount rate'!$A$1:$A$39,0),match('Moral weights and discount rate'!$A$17,'Moral weights and discount rate'!$A$1:$ZU$1,0))} -> 1.442695 | C19: {=index('Moral weights and discount rate'!$A$1:$ZU$39,match($A19,'Moral weights and discount rate'!$A$1:$A$39,0),match('Moral weights and discount rate'!$A$17,'Moral weights and discount rate'!$A$1:$ZU$1,0))} -> 1.442695 | D19: {=index('Moral weights and discount rate'!$A$1:$ZU$39,match($A19,'Moral weights and discount rate'!$A$1:$A$39,0),match('Moral weights and discount rate'!$A$17,'Moral weights and discount rate'!$A$1:$ZU$1,0))} -> 1.442695 | E19: {=index('Moral weights and discount rate'!$A$1:$ZU$39,match($A19,'Moral weights and discount rate'!$A$1:$A$39,0),match('Moral weights and discount rate'!$A$17,'Moral weights and discount rate'!$A$1:$ZU$1,0))} -> 1.442695 | F19: {=index('Moral weights and discount rate'!$A$1:$ZU$39,match($A19,'Moral weights and discount rate'!$A$1:$A$39,0),match('Moral weights and discount rate'!$A$17,'Moral weights and discount rate'!$A$1:$ZU$1,0))} -> 1.442695 | G19: {=index('Moral weights and discount rate'!$A$1:$ZU$39,match($A19,'Moral weights and discount rate'!$A$1:$A$39,0),match('Moral weights and discount rate'!$A$17,'Moral weights and discount rate'!$A$1:$ZU$1,0))} -> 1.442695 | H19: {=index('Moral weights and discount rate'!$A$1:$ZU$39,match($A19,'Moral weights and discount rate'!$A$1:$A$39,0),match('Moral weights and discount rate'!$A$17,'Moral weights and discount rate'!$A$1:$ZU$1,0))} -> 1.442695 | I19: {=index('Moral weights and discount rate'!$A$1:$ZU$39,match($A19,'Moral weights and discount rate'!$A$1:$A$39,0),match('Moral weights and discount rate'!$A$17,'Moral weights and discount rate'!$A$1:$ZU$1,0))} -> 1.442695 | ... AO19: {=index('Moral weights and discount rate'!$A$1:$ZU$39,match($A19,'Moral weights and discount rate'!$A$1:$A$39,0),match('Moral weights and discount rate'!$A$17,'Moral weights and discount rate'!$A$1:$ZU$1,0))} -> 1.442695
A20: Units of value from each year of deworming — Sightsavers | B20: =(B18*B19) -> 0.014995882 | C20: =(C18*C19) -> 0.053294751 | D20: =(D18*D19) -> 0.05336769 | E20: =(E18*E19) -> 0.044700028 | F20: =(F18*F19) -> 0.031844056 | G20: =(G18*G19) -> 0.024565882 | H20: =(H18*H19) -> 0.017652757 | I20: =(I18*I19) -> 0.036674795 | ... AO20: =(AO18*AO19) -> 0.0040793055
A21: Cost per person dewormed (per year) — Sightsavers | B21: 1.51904 | C21: 1.26664 | D21: 1.7252 | E21: 1.27013 | F21: 1.27013 | G21: 1.27013 | H21: 1.27013 | I21: 1.27013 | J21: 1.27013 | K21: 1.27013 | L21: 1.27013 | M21: 1.27013 | N21: 1.27013 | O21: 1.27013 | P21: 1.27013 | Q21: 1.27013 | R21: 1.27013 | S21: 1.27013 | T21: 1.27013 | U21: 0.8544 | V21: 0.8544 | W21: 0.8544 | X21: 0.8544 | Y21: 0.8544 | Z21: 0.8544 | AA21: 0.8544 | AB21: 0.93964 | AC21: 0.81978 | AD21: 0.81978 | AE21: 0.81978 | AF21: 0.81978 | AG21: 1.05855 | AH21: 1.41189 | AI21: 0.96164 | AJ21: 0.96164 | AK21: 0.96164 | AL21: 0.96164 | AM21: 0.96164 | AN21: 0.96164 | AO21: 5.32065
A22: Total number of children dewormed (per year) | B22: =B14/B21 -> 110017.59 | C22: =C14/C21 -> 184146.61 | D22: =D14/D21 -> 111851.04 | E22: =E14/E21 -> 174530.06 | F22: =F14/F21 -> 174530.06 | G22: =G14/G21 -> 174530.06 | H22: =H14/H21 -> 174530.06 | I22: =I14/I21 -> 174530.06 | ... AO22: =AO14/AO21 -> 28261.485
A24: Intuition check
A26: Aggregate adjustment to Miguel and Kremer development effect — Sightsavers | B26: =product('Deworm the World'!$B$11:$B$12,B16) -> 0.0058958406 | C26: =product('Deworm the World'!$B$11:$B$12,C16) -> 0.020953577 | D26: =product('Deworm the World'!$B$11:$B$12,D16) -> 0.020982253 | E26: =product('Deworm the World'!$B$11:$B$12,E16) -> 0.017574441 | F26: =product('Deworm the World'!$B$11:$B$12,F16) -> 0.012519936 | G26: =product('Deworm the World'!$B$11:$B$12,G16) -> 0.0096584202 | H26: =product('Deworm the World'!$B$11:$B$12,H16) -> 0.0069404283 | I26: =product('Deworm the World'!$B$11:$B$12,I16) -> 0.014419209 | ... AO26: =product('Deworm the World'!$B$11:$B$12,AO16) -> 0.001603836
A28: Initial results
A30: =A18 -> Present value of lifetime benefits from a year of deworming — in terms of increases in ln(consumption) | B30: =B18 -> 0.010394353 | C30: =C18 -> 0.036941107 | D30: =D18 -> 0.036991664 | E30: =E18 -> 0.030983699 | F30: =F18 -> 0.022072618 | G30: =G18 -> 0.017027772 | H30: =H18 -> 0.012235959 | ... AO30: =AO18 -> 0.0028275591
A31: =A19 -> Value assigned to increasing ln(consumption) by one unit for one person for one year | B31: =B19 -> 1.442695 | C31: =C19 -> 1.442695 | D31: =D19 -> 1.442695 | E31: =E19 -> 1.442695 | F31: =F19 -> 1.442695 | G31: =G19 -> 1.442695 | H31: =H19 -> 1.442695 | ... AO31: =AO19 -> 1.442695
A32: =A22 -> Total number of children dewormed (per year) | B32: =B22 -> 110017.59 | C32: =C22 -> 184146.61 | D32: =D22 -> 111851.04 | E32: =E22 -> 174530.06 | F32: =F22 -> 174530.06 | G32: =G22 -> 174530.06 | H32: =H22 -> 174530.06 | ... AO32: =AO22 -> 28261.485
