Workbook
Name BDT_to_USD_2017: #REF!
Name BDT_to_USD_2014: #REF!
Name lesser_lean_season_duration: #REF!
Name nls_household_size: #REF!
Name primary_lean_season_duration: #REF!

Sheet Start here
A1: Notes on how to engage with our cost-effectiveness analysis
A2: This workbook contains our cost-effectiveness analysis. Cost-effectiveness is one factor we use to assess which opportunities are the highest-priority to support. We also consider other factors such as urgency, quality of implementation, and more. If you're a donor interested in supporting the top charity we believe will do the most good at the time your donation is granted, please consider supporting the Top Charities Fund. On the "Moral weights and discount rate" sheet, we've included GiveWell and conventional estimates for a few parameters. If you'd like to see how our results would change based on different inputs for these parameters, you can make a copy of this spreadsheet and enter your own values in the "Anyone" column. Expanding the formula bar at the top of the page (by clicking and dragging the bottom boundary) may make it easier to read the contents of explanatory cells.
A6: Notes on text color coding
A7: Blue text: direct input
A8: Green text: pulling from another cell in this workbook
A9: Black text: calculation
A11: Index
A12: Moral weights and discount rate | B12: Allows staff members or anyone else to supply discount rates and numbers used to trade off different good outcomes
A13: AMF | B13: Cost-effectiveness analysis for long-lasting insecticide-treated net distributions by the Against Malaria Foundation.
A14: GiveDirectly | B14: Cost-effectiveness analysis for unconditional cash transfers by GiveDirectly.
A15: Deworm the World | B15: Cost-effectiveness analysis for deworming by Deworm the World
A16: Unlimit Health | B16: Cost-effectiveness analysis for deworming by Unlimit Health
A17: Sightsavers | B17: Cost-effectiveness analysis for deworming by Sightsavers
A18: Malaria Consortium | B18: Cost-effectiveness analysis for seasonal malaria chemoprevention by Malaria Consortium
A19: Helen Keller International | B19: Cost-effectiveness analysis for vitamin A supplementation by Helen Keller International
A20: New Incentives | B20: Cost-effectiveness analysis for conditional cash transfers for immunization by New Incentives
A21: Value of counterfactual spending by other actors | B21: Used in the leverage and funging adjustments to our cost-effectiveness analyses
A22: Supplemental intervention-level adjustments | B22: Intervention-level adjustments for outcomes not explicitly modeled in our cost-effectiveness analyses
A24: Helpful GiveWell references
A25: =HYPERLINK("https://docs.google.com/document/d/1ZKq-MNU-xtn_48uN33L6VvBEZRAduvjwWMeaEffL4K4/","Guide to GiveWell cost-effectiveness analyses") -> Guide to GiveWell cost-effectiveness analyses
A26: =HYPERLINK("http://www.givewell.org/charities/top-charities","Full reviews of our top charities") -> Full reviews of our top charities
A27: =HYPERLINK("http://www.givewell.org/international/technical/criteria/cost-effectiveness/cost-effectiveness-models","Past versions of our cost-effectiveness analyses") -> Past versions of our cost-effectiveness analyses
A28: =HYPERLINK("http://www.givewell.org/international/technical/criteria/cost-effectiveness","Discussion of cost-effectiveness as a criterion") -> Discussion of cost-effectiveness as a criterion
A29: =HYPERLINK("http://www.givewell.org/international/technical/criteria/cost-effectiveness#MoreonGiveWellsviewsoncosteffectivenessestimates","Blog posts discussing cost-effectiveness") -> Blog posts discussing cost-effectiveness

Sheet Index
A1: Index
A2: New CEA | B2: New cost-effectiveness analysis (CEA) of GiveDirectly's Cash for Poverty Relief program
A3: Analysis
A4: Baseline | B4: Calculation of our best guess of baseline consumption of GiveDirectly's recipients
A5: Consumption | B5: Investment returns function given assumptions about amount invested and ROI
A6: GE | B6: Adjustments to the headline economic multiplier estimate from Egger et al.
A7: Spillover | B7: Bottom-up reconstruction of the Egger et al. multiplier
A8: Mortality | B8: Comparison of Egger et al. mortality estimate with cross-country data
A9: Development | B9: Sense check of how development effects might contribute to cost-effectiveness
A10: RFMF | B10: Estimate of program reach across countries currently targeted by the Cash for Poverty Relief program
A11: Uncertainty
A12: Inputs | B12: Inputs for Monte Carlo simulations of our GiveDirectly model
A13: Sims | B13: Simulations of our GiveDirectly CEA based on the inputs in the previous tab
A14: Raw
A15: WB | B15: Poverty, food insecurity, and other data from the World Bank
A16: IHME | B16: Child mortality data from the Institute for Health Metrics and Evaluation
A17: UNICEF | B17: Child mortality data from UNICEF
A18: Equivalence | B18: Adult equivalence conversion factor calculations
A19: Papers | B19: Papers which estimate economic mutlipliers
A20: u5m papers | B20: Papers which estimate under-5 mortality
A21: GD data
A22: Summ | B22: Overview of data sent to us by GiveDirectly
A23: Historic | B23: Historic funding allocation data across GiveDirectly programs
A24: Flex | B24: Flex and unrestricted funding data across programs
A25: Country | B25: Estimate of program reach across countries currently targeted by the Cash for Poverty Relief program

Sheet New CEA
A1: What is this? This tab outlines our current (new) CEA of GiveDirectly
B2: Kenya | C2: Malawi | D2: Mozambique | E2: Rwanda | F2: Uganda
A3: Program reach
A4: Arbitrary donation (nominal USD) | B4: 1000000 | C4: 1000000 | D4: 1000000 | E4: 1000000 | F4: 1000000
A5: Total size of transfer per household (nominal USD) | B5: 865 | C5: 1000 | D5: 1000 | E5: 1100 | F5: 955
A6: Transfers as a percentage of total cost | B6: 0.84 | C6: 0.84 | D6: 0.75 | E6: 0.85 | F6: 0.71
A7: Number of households receiving transfer | B7: =(B4*B6)/B5 -> 971.09827 | C7: =(C4*C6)/C5 -> 840 | D7: =(D4*D6)/D5 -> 750 | E7: =(E4*E6)/E5 -> 772.72727 | F7: =(F4*F6)/F5 -> 743.4555
A8: PPP adjustment (2017) | B8: =Baseline!B22 -> 2.3689924 | C8: =Baseline!C22 -> 2.9315863 | D8: =Baseline!D22 -> 2.8119848 | E8: =Baseline!E22 -> 2.7940238 | F8: =Baseline!F22 -> 2.961996
A9: Total size of transfer per household (PPP 2017) | B9: =B8*B5 -> 2049.1784 | C9: =C8*C5 -> 2931.5863 | D9: =D8*D5 -> 2811.9848 | E9: =E8*E5 -> 3073.4262 | F9: =F8*F5 -> 2828.7061
A10: Average household size | B10: =Baseline!B4 -> 4.2 | C10: =Baseline!C4 -> 4.5 | D10: =Baseline!D4 -> 4.4 | E10: =Baseline!E4 -> 4.3 | F10: =Baseline!F4 -> 4.8
A11: Size of transfer per person (PPP 2017) | B11: =B9/B10 -> 487.89962 | C11: =C9/C10 -> 651.46361 | D11: =D9/D10 -> 639.08746 | E11: =E9/E10 -> 714.75028 | F11: =F9/F10 -> 589.31378
A12: Number of people reached | B12: =B10*B7 -> 4078.6127 | C12: =C10*C7 -> 3780 | D12: =D10*D7 -> 3300 | E12: =E10*E7 -> 3322.7273 | F12: =F10*F7 -> 3568.5864
A13: Consumption gains to recipients
A14: Baseline annual consumption per capita (PPP 2017) | B14: =Baseline!B35 -> 651.96604 | C14: =Baseline!C35 -> 469.98486 | D14: =Baseline!D35 -> 449.78149 | E14: =Baseline!E35 -> 532.64139 | F14: =Baseline!F35 -> 625.55328
A15: Percentage of transfers invested | B15: 0.43 | C15: =$B15 -> 0.43 | D15: =$B15 -> 0.43 | E15: =$B15 -> 0.43 | F15: =$B15 -> 0.43
A16: Percentage of transfers consumed in year 1 | B16: =1-B15 -> 0.57 | C16: =1-C15 -> 0.57 | D16: =1-D15 -> 0.57 | E16: =1-E15 -> 0.57 | F16: =1-F15 -> 0.57
A17: Implied increase in consumption per person in year 1 | B17: =B16*B11 -> 278.10278 | C17: =C16*C11 -> 371.33426 | D17: =D16*D11 -> 364.27985 | E17: =E16*E11 -> 407.40766 | F17: =F16*F11 -> 335.90885
A18: Percentage increase in consumption over baseline | B18: =((B17+B14)/B14)-1 -> 0.42656023 | C18: =((C17+C14)/C14)-1 -> 0.79009835 | D18: =((D17+D14)/D14)-1 -> 0.80990406 | E18: =((E17+E14)/E14)-1 -> 0.76488172 | F18: =((F17+F14)/F14)-1 -> 0.53697881
A19: Immediate increase in ln(consumption) per person | B19: =ln(1+B18)-ln(1) -> 0.35526612 | C19: =ln(1+C18)-ln(1) -> 0.58227056 | D19: =ln(1+D18)-ln(1) -> 0.59327384 | E19: =ln(1+E18)-ln(1) -> 0.56808367 | F19: =ln(1+F18)-ln(1) -> 0.42981868
A20: Value assigned to increasing ln(consumption) by one unit for one person for one year | B20: 1.442695 | C20: 1.442695 | D20: 1.442695 | E20: 1.442695 | F20: 1.442695
A21: Units of value from year 1 consumption gains per person | B21: =B19*B20 -> 0.51254066 | C21: =C19*C20 -> 0.84003885 | D21: =D19*D20 -> 0.85591322 | E21: =E19*E20 -> 0.8195715 | F21: =F19*F20 -> 0.62009728
A22: Units of value from year 1 consumption gains given program reach | B22: =B21*B12 -> 2090.4549 | C22: =C21*C12 -> 3175.3469 | D22: =D21*D12 -> 2824.5136 | E22: =E21*E12 -> 2723.2126 | F22: =F21*F12 -> 2212.8707
A23: Value of year 2-10 consumption returns as % of year 1 consumption returns | B23: =Consumption!B23 -> 1.2304527 | C23: =Consumption!B37 -> 1.3605831 | D23: =Consumption!B50 -> 1.3976761 | E23: =Consumption!B63 -> 1.3404766 | F23: =Consumption!B76 -> 1.2680226
A24: Units of value from year 1-10 consumption gains | B24: =B22+(B22*B23) -> 4662.6608 | C24: =C22+(C22*C23) -> 7495.6702 | D24: =D22+(D22*D23) -> 6772.2688 | E24: =E22+(E22*E23) -> 6373.6154 | F24: =F22+(F22*F23) -> 5018.8407
A25: Distributional adjustment (accounting for consumption gains accruing to richer recipients) | B25: 0.9 | C25: 0.9 | D25: 0.9 | E25: 0.9 | F25: 0.9
A26: Units of value from year 1-10 consumption gains post adjustments | B26: =B24*B25 -> 4196.3947 | C26: =C24*C25 -> 6746.1032 | D26: =D24*D25 -> 6095.0419 | E26: =E24*E25 -> 5736.2538 | F26: =F24*F25 -> 4516.9566
A27: Units of value from recipient consumption gains per $ donated | B27: =B26/B4 -> 0.0041963947 | C27: =C26/C4 -> 0.0067461032 | D27: =D26/D4 -> 0.0060950419 | E27: =E26/E4 -> 0.0057362538 | F27: =F26/F4 -> 0.0045169566
A28: Previous GiveDirectly cost-effectiveness estimate (units of value per $) | B28: 0.003355 | C28: 0.003355 | D28: 0.003355 | E28: 0.003355 | F28: 0.003355
A29: Initial CE from recipient consumption gains (x previous benchmark) | B29: =B27/B28 -> 1.2507883 | C29: =C27/C28 -> 2.010761 | D29: =D27/D28 -> 1.816704 | E29: =E27/E28 -> 1.7097627 | F29: =F27/F28 -> 1.3463358
A30: Spillovers to non-recipients/general equilibrium effects
A31: Egger et al. economic multiplier | B31: 2.5 | C31: 2.5 | D31: 2.5 | E31: 2.5 | F31: 2.5
A32: Double-counting adjustment (stripping out recipient consumption gains) | B32: =GE!$B$7 -> 0.7032 | C32: =GE!$B$7 -> 0.7032 | D32: =GE!$B$7 -> 0.7032 | E32: =GE!$B$7 -> 0.7032 | F32: =GE!$B$7 -> 0.7032
A33: IV adjustment (regressing Egger et al. towards prior) | B33: 0.6 | C33: 0.6 | D33: 0.6 | E33: 0.6 | F33: 0.6
A34: EV adjustment (generalizing the multiplier to current program conditions) | B34: 0.8 | C34: 0.7 | D34: 0.7 | E34: 0.75 | F34: 0.75
A35: Distributional adjustment (accounting for consumption spillovers accruing to richer non-recipients) | B35: 0.8 | C35: 0.8 | D35: 0.8 | E35: 0.8 | F35: 0.8
A36: Spillover/general equilibrium benefits (as % of recipient consumption benefits), post adjustments | B36: =B31*B35*B32*B33*B34 -> 0.675072 | C36: =C31*C35*C32*C33*C34 -> 0.590688 | D36: =D31*D35*D32*D33*D34 -> 0.590688 | E36: =E31*E35*E32*E33*E34 -> 0.63288 | F36: =F31*F35*F32*F33*F34 -> 0.63288
A37: Units of value from non-recipient spillovers | B37: =B26*B36 -> 2832.8686 | C37: =C26*C36 -> 3984.8422 | D37: =D26*D36 -> 3600.2681 | E37: =E26*E36 -> 3630.3603 | F37: =F26*F36 -> 2858.6915
A38: Units of value from consumption gains and non-recipient spillovers | B38: =B26+B37 -> 7029.2633 | C38: =C26+C37 -> 10730.945 | D38: =D26+D37 -> 9695.3101 | E38: =E26+E37 -> 9366.6142 | F38: =F26+F37 -> 7375.6481
A39: Initial CE from consumption gains and spillovers (x previous benchmark) | B39: =(B38/B4)/B28 -> 2.0951604 | C39: =(C38/C4)/C28 -> 3.1984934 | D39: =(D38/D4)/D28 -> 2.8898093 | E39: =(E38/E4)/E28 -> 2.7918373 | F39: =(F38/F4)/F28 -> 2.1984048
A40: Mortality benefits
...

Sheet Analysis
A1: Analysis
A2: Baseline | B2: Calculation of our best guess of baseline consumption of GiveDirectly's recipients
A3: Consumption | B3: Investment returns function given assumptions about amount invested and ROI
A4: GE | B4: Adjustments to the headline economic multiplier estimate from Egger et al.
A5: Spillover | B5: Bottom-up reconstruction of the Egger et al. multiplier
A6: Mortality | B6: Comparison of Egger et al. mortality estimate with cross-country data
A7: Development | B7: Sense check of how development effects might contribute to cost-effectiveness
A8: RFMF | B8: Estimate of program reach across countries currently targeted by the Cash for Poverty Relief program

Sheet Baseline
A1: What is this? This tab calculates our best guess of baseline consumption of GiveDirectly's recipients in the 5 countries they have live Poverty Relief programs
A2: Notes: latest consumption surveys sourced from World Bank PIP | B2: Kenya | C2: Malawi | D2: Mozambique | E2: Rwanda | F2: Uganda | G2: Notes
A3: Demographics
A4: Average rural household size | B4: 4.2 | C4: 4.5 | D4: 4.4 | E4: 4.3 | F4: 4.8
A6: Consumption - Government consumption survey data
A7: Annual consumption per adult equivalent in lowest quintile (local currency, latest year available) | B7: =SUM(3398*12)*(32088/41428) -> 31582.994 | E7: 86000 | F7: =sum(36758*12) -> 441096
A8: Step 1: convert from adult equivalent to per capita terms
A9: Implied adjustment to get measures in per capita terms | B9: =Equivalence!B90 -> 0.84912187 | E9: =Equivalence!E90 -> 0.9254366 | F9: =Equivalence!F90 -> 0.92119457
A10: Annual consumption per capita in lowest quintile (local currency, latest year available) | B10: =B7*B9 -> 26817.811 | C10: 76823 | D10: =224*12 -> 2688 | E10: =E7*E9 -> 79587.548 | F10: =F7*F9 -> 406335.24
A11: Year data was collected | B11: 2021 | C11: 2019 | D11: 2019 | E11: 2016 | F11: 2019
A12: Year prices are expressed in | B12: 2021 | C12: 2019 | D12: 2019 | E12: 2014 | F12: 2010
A13: Step 2: account for economic growth since data collection year
A14: Years since data collection | B14: =2024-B11 -> 3 | C14: =2024-C11 -> 5 | D14: =2024-D11 -> 5 | E14: =2024-E11 -> 8 | F14: =2024-F11 -> 5
A15: Estimated consumption growth per year | B15: 0.02 | C15: 0.01 | D15: 0.01 | E15: 0.02 | F15: 0.02
A16: Estimated annual consumption per capita in lowest quintile (local currency, 2024, not PPP adjusted) | B16: =B10*(1+B15)^B14 -> 28459.276 | C16: =C10*(1+C15)^C14 -> 80741.745 | D16: =D10*(1+D15)^D14 -> 2825.115 | E16: =E10*(1+E15)^E14 -> 93249.497 | F16: =F10*(1+F15)^F14 -> 448626.94
A17: Step 3: covert to USD
A18: Official exchange rate in 2017 | B18: {=INDEX(WB!$E$13:$BO$17,MATCH(B$2,WB!$A$13:$A$17,0),MATCH(2017,WB!$E$12:$BO$12,0))} -> 103.41 | C18: {=INDEX(WB!$E$13:$BO$17,MATCH(C$2,WB!$A$13:$A$17,0),MATCH(2017,WB!$E$12:$BO$12,0))} -> 730.2725 | D18: {=INDEX(WB!$E$13:$BO$17,MATCH(D$2,WB!$A$13:$A$17,0),MATCH(2017,WB!$E$12:$BO$12,0))} -> 63.58432 | E18: {=INDEX(WB!$E$13:$BO$17,MATCH(E$2,WB!$A$13:$A$17,0),MATCH(2017,WB!$E$12:$BO$12,0))} -> 831.5543 | F18: {=INDEX(WB!$E$13:$BO$17,MATCH(F$2,WB!$A$13:$A$17,0),MATCH(2017,WB!$E$12:$BO$12,0))} -> 3611.224 | G18: NB: this is the nominal exchange rate
A19: LCU conversion factor in 2017 | B19: {=INDEX(WB!$E$4:$BO$8,MATCH(B$2,WB!$A$4:$A$8,0),MATCH(2017,WB!$E$3:$BO$3,0))} -> 43.65147 | C19: {=INDEX(WB!$E$4:$BO$8,MATCH(C$2,WB!$A$4:$A$8,0),MATCH(2017,WB!$E$3:$BO$3,0))} -> 249.1049 | D19: {=INDEX(WB!$E$4:$BO$8,MATCH(D$2,WB!$A$4:$A$8,0),MATCH(2017,WB!$E$3:$BO$3,0))} -> 22.6119 | E19: {=INDEX(WB!$E$4:$BO$8,MATCH(E$2,WB!$A$4:$A$8,0),MATCH(2017,WB!$E$3:$BO$3,0))} -> 297.6189 | F19: {=INDEX(WB!$E$4:$BO$8,MATCH(F$2,WB!$A$4:$A$8,0),MATCH(2017,WB!$E$3:$BO$3,0))} -> 1219.186 | G19: This takes into account cost-of-living differentials
A20: Annual consumption per capita (nominal USD 2017) | B20: =B16/B18 -> 275.20816 | C20: =C16/C18 -> 110.56386 | D20: =D16/D18 -> 44.431001 | E20: =E16/E18 -> 112.13879 | F20: =F16/F18 -> 124.23127
A21: Bottom quintile annual consumption per capita (2017 PPP) | B21: =B16/B19 -> 651.96604 | C21: =C16/C19 -> 324.12749 | D21: =D16/D19 -> 124.9393 | E21: =E16/E19 -> 313.31847 | F21: =F16/F19 -> 367.97252
A22: Implied PPP adjustment | B22: =B21/B20 -> 2.3689924 | C22: =C21/C20 -> 2.9315863 | D22: =D18/D19 -> 2.8119848 | E22: =E21/E20 -> 2.7940238 | F22: =F21/F20 -> 2.961996
A24: Consumption - RCT data
A25: Annual consumption per capita (nominal) | C25: =((13.96+19.18)/C4)*12 -> 88.373333 | E25: =10.7*12 -> 128.4
A26: Year this esimate comes from | B26: 2014 | C26: 2019 | E26: 2016 | F26: 2016
A27: Annual consumption per capita (PPP adjusted, year of data collection) | B27: =2536/B4 -> 603.80952 | C27: =C25*C22 -> 259.07405 | E27: =E25*E22 -> 358.75266 | F27: =2828/F4 -> 589.16667
A28: Years since data collection | B28: =2024-B26 -> 10 | C28: =2024-C26 -> 5 | E28: =2024-E26 -> 8 | F28: =2024-F26 -> 8
A29: Estimated annual consumption per capita (PPP adjusted, 2024) | B29: =B27*(1+B15)^B28 -> 736.04044 | C29: =C27*(1+C15)^C28 -> 272.28943 | E29: =E27*(1+E15)^E28 -> 420.33592 | F29: =F27*(1+F15)^F28 -> 690.30265
A31: Best guess
A32: Bottom quintile consumption estimates implied by government surveys | B32: =B21 -> 651.96604 | C32: =C21 -> 324.12749 | D32: =D21 -> 124.9393 | E32: =E21 -> 313.31847 | F32: =F21 -> 367.97252
A33: RCT estimates | B33: =B29 -> 736.04044 | C33: =C29 -> 272.28943 | D33: =D29 | E33: =E29 -> 420.33592 | F33: =F29 -> 690.30265
A34: Ad hoc adjustment to government consumption estimates | B34: 1 | C34: 1.45 | D34: 3.6 | E34: 1.7 | F34: 1.7
A35: Best-guess of consumption of GiveDirectly recipients | B35: =B32*B34 -> 651.96604 | C35: =C32*C34 -> 469.98486 | D35: =D32*D34 -> 449.78149 | E35: =E32*E34 -> 532.64139 | F35: =F32*F34 -> 625.55328
A37: Size of transfer
A38: Size of transfer (nominal USD) | B38: 1000 | C38: 1000 | D38: 1000 | E38: 1000 | F38: 1000
A39: Size of transfer (2017 PPP) | B39: =B22*B38 -> 2368.9924 | C39: =C22*C38 -> 2931.5863 | D39: =D22*D38 -> 2811.9848 | E39: =E22*E38 -> 2794.0238 | F39: =F22*F38 -> 2961.996 | G39: Intuition: $1k 'goes further' in different countries
A43: Compared to absolute poverty benchmarks
A44: Absolute poverty line (2017 prices) | B44: 2.15 | C44: 2.15 | D44: 2.15 | E44: 2.15 | F44: 2.15
A45: Estimated requirement to meet basic calorific needs (2017 prices) | B45: 0.83 | C45: 0.83 | D45: 0.83 | E45: 0.83 | F45: 0.83
B46: Kenya | C46: Malawi | D46: Mozambique | E46: Rwanda | F46: Uganda
A47: Implied consumption per day (current best guess) | B47: =B35/365 -> 1.7862083 | C47: =C35/365 -> 1.2876297 | D47: =D35/365 -> 1.2322781 | E47: =E35/365 -> 1.4592915 | F47: =F35/365 -> 1.7138446
...

Sheet Consumption
A1: What is this? This tab constructs an investment returns function given assumptions about amount invested and ROI
A3: Consumption returns assumptions | B3: Kenya | C3: Malawi | D3: Mozambique | E3: Rwanda | F3: Uganda
A4: Amount of transfer invested | B4: ='New CEA'!B15 -> 0.43 | C4: ='New CEA'!C15 -> 0.43 | D4: ='New CEA'!D15 -> 0.43 | E4: ='New CEA'!E15 -> 0.43 | F4: ='New CEA'!F15 -> 0.43
A5: Year 2 ROI | B5: 0.4 | C5: 0.4 | D5: 0.4 | E5: 0.4 | F5: 0.4
A6: Decay in consumption returns | B6: -0.2 | C6: =$B6 -> -0.2 | D6: =$B6 -> -0.2 | E6: =$B6 -> -0.2 | F6: =$B6 -> -0.2
A7: Counterfactual growth in recipient consumption | B7: =Baseline!B15 -> 0.02 | C7: =Baseline!C15 -> 0.01 | D7: =Baseline!D15 -> 0.01 | E7: =Baseline!E15 -> 0.02 | F7: =Baseline!F15 -> 0.02
A8: Moral weights
A9: Discount rate | B9: 0.04
A10: Value assigned to increasing ln(consumption) by one unit for one person for one year | B10: ='New CEA'!$B$20 -> 1.442695
A12: Kenya | B12: 2024 | C12: =B12+1 -> 2025 | D12: =C12+1 -> 2026 | E12: =D12+1 -> 2027 | F12: =E12+1 -> 2028 | G12: =F12+1 -> 2029 | H12: =G12+1 -> 2030 | I12: =H12+1 -> 2031 | J12: =I12+1 -> 2032 | K12: =J12+1 -> 2033
A13: Number of people reached | B13: ='New CEA'!B12 -> 4078.6127
A14: Transfer size per person | B14: ='New CEA'!B11 -> 487.89962
A15: Year 1 increase in consumption | B15: =B14*(1-B$4) -> 278.10278
A16: Amount invested/saved | B16: =B14-B15 -> 209.79684
A17: Baseline/counterfactual consumption | B17: ='New CEA'!$B$14 -> 651.96604 | C17: =B17*(1+$B$7) -> 665.00536 | D17: =C17*(1+$B$7) -> 678.30546 | E17: =D17*(1+$B$7) -> 691.87157 | F17: =E17*(1+$B$7) -> 705.709 | G17: =F17*(1+$B$7) -> 719.82318 | H17: =G17*(1+$B$7) -> 734.21965 | I17: =H17*(1+$B$7) -> 748.90404 | J17: =I17*(1+$B$7) -> 763.88212 | K17: =J17*(1+$B$7) -> 779.15976
A18: Counterfactual increase in consumption | B18: =B15 -> 278.10278 | C18: =B16*$B$5 -> 83.918735 | D18: =C18*(1+$B$6) -> 67.134988 | E18: =D18*(1+$B$6) -> 53.70799 | F18: =E18*(1+$B$6) -> 42.966392 | G18: =F18*(1+$B$6) -> 34.373114 | H18: =G18*(1+$B$6) -> 27.498491 | I18: =H18*(1+$B$6) -> 21.998793 | J18: =I18*(1+$B$6) -> 17.599034 | K18: =J18*(1+$B$6) -> 14.079227
A19: Increase in ln(consumption) | B19: =ln(B17+B18)-ln(B17) -> 0.35526612 | C19: =ln(C17+C18)-ln(C17) -> 0.11884254 | D19: =ln(D17+D18)-ln(D17) -> 0.094377531 | E19: =ln(E17+E18)-ln(E17) -> 0.074761503 | F19: =ln(F17+F18)-ln(F17) -> 0.05910253 | G19: =ln(G17+G18)-ln(G17) -> 0.046647072 | H19: =ln(H17+H18)-ln(H17) -> 0.036768359 | I19: =ln(I17+I18)-ln(I17) -> 0.02895148 | ... K19: =ln(K17+K18)-ln(K17) -> 0.017908439
A20: Discounted increase in ln(consumption) | B20: =B19/(1+$B$9)^(B$12-2024) -> 0.35526612 | C20: =C19/(1+$B$9)^(C$12-2024) -> 0.11427167 | D20: =D19/(1+$B$9)^(D$12-2024) -> 0.087257333 | E20: =E19/(1+$B$9)^(E$12-2024) -> 0.066462704 | F20: =F19/(1+$B$9)^(F$12-2024) -> 0.05052109 | G20: =G19/(1+$B$9)^(G$12-2024) -> 0.038340493 | H20: =H19/(1+$B$9)^(H$12-2024) -> 0.029058568 | I20: =I19/(1+$B$9)^(I$12-2024) -> 0.022000746 | ... K20: =K19/(1+$B$9)^(K$12-2024) -> 0.012582232
A21: Discounted units of value | B21: =B20*$B$10 -> 0.51254066 | C21: =C20*$B$10 -> 0.16485917 | D21: =D20*$B$10 -> 0.12588572 | E21: =E20*$B$10 -> 0.095885414 | F21: =F20*$B$10 -> 0.072886526 | G21: =G20*$B$10 -> 0.055313639 | H21: =H20*$B$10 -> 0.041922652 | I21: =I20*$B$10 -> 0.031740367 | ... K21: =K20*$B$10 -> 0.018152323
A22: Total units of value given people reached | B22: =B21*$B$13 -> 2090.4549 | C22: =C21*$B$13 -> 672.39671 | D22: =D21*$B$13 -> 513.4391 | E22: =E21*$B$13 -> 391.07947 | F22: =F21*$B$13 -> 297.27591 | G22: =G21*$B$13 -> 225.60291 | H22: =H21*$B$13 -> 170.98626 | I22: =I21*$B$13 -> 129.45666 | ... K22: =K21*$B$13 -> 74.036297
A23: Year 2-10 consumption gains (as % of year 1 consumption gains) | B23: =SUM(C22:K22)/B22 -> 1.2304527
A24: Relative consumption gains (%) | B24: =B18/B17 -> 0.42656023 | C24: =C18/C17 -> 0.12619257 | D24: =D18/D17 -> 0.098974565 | E24: =E18/E17 -> 0.07762711 | F24: =F18/F17 -> 0.060884007 | G24: =G18/G17 -> 0.047752163 | H24: =H18/H17 -> 0.037452677 | I24: =I18/I17 -> 0.029374648 | ... K24: =K18/K17 -> 0.018069757
A26: Malawi | B26: 2024 | C26: =B26+1 -> 2025 | D26: =C26+1 -> 2026 | E26: =D26+1 -> 2027 | F26: =E26+1 -> 2028 | G26: =F26+1 -> 2029 | H26: =G26+1 -> 2030 | I26: =H26+1 -> 2031 | J26: =I26+1 -> 2032 | K26: =J26+1 -> 2033
A27: Number of people reached | B27: ='New CEA'!C12 -> 3780
A28: Transfer size per person | B28: ='New CEA'!C11 -> 651.46361
A29: Year 1 increase in consumption | B29: =B28*(1-C$4) -> 371.33426
A30: Amount invested/saved | B30: =B28-B29 -> 280.12935
A31: Baseline/counterfactual consumption | B31: ='New CEA'!C14 -> 469.98486 | C31: =B31*(1+$C$7) -> 474.6847 | D31: =C31*(1+$B$7) -> 484.1784 | E31: =D31*(1+$B$7) -> 493.86197 | F31: =E31*(1+$B$7) -> 503.73921 | G31: =F31*(1+$B$7) -> 513.81399 | H31: =G31*(1+$B$7) -> 524.09027 | I31: =H31*(1+$B$7) -> 534.57207 | J31: =I31*(1+$B$7) -> 545.26352 | K31: =J31*(1+$B$7) -> 556.16879
A32: Counterfactual increase in consumption | B32: =B29 -> 371.33426 | C32: =B30*$C$5 -> 112.05174 | D32: =C32*(1+$C$6) -> 89.641393 | E32: =D32*(1+$C$6) -> 71.713114 | F32: =E32*(1+$C$6) -> 57.370491 | G32: =F32*(1+$C$6) -> 45.896393 | H32: =G32*(1+$C$6) -> 36.717115 | I32: =H32*(1+$C$6) -> 29.373692 | J32: =I32*(1+$C$6) -> 23.498953 | K32: =J32*(1+$C$6) -> 18.799163
A33: Increase in ln(consumption) | B33: =ln(B31+B32)-ln(B31) -> 0.58227056 | C33: =ln(C31+C32)-ln(C31) -> 0.21192493 | D33: =ln(D31+D32)-ln(D31) -> 0.16986196 | E33: =ln(E31+E32)-ln(E31) -> 0.135587 | F33: =ln(F31+F32)-ln(F31) -> 0.10785774 | G33: =ln(G31+G32)-ln(G31) -> 0.085558164 | H33: =ln(H31+H32)-ln(H31) -> 0.067713563 | I33: =ln(I31+I32)-ln(I31) -> 0.053491521 | ... K33: =ln(K31+K32)-ln(K31) -> 0.033242478
A34: Discounted increase in ln(consumption) | B34: =B33/(1+$B$9)^(B$12-2024) -> 0.58227056 | C34: =C33/(1+$B$9)^(C$12-2024) -> 0.20377397 | D34: =D33/(1+$B$9)^(D$12-2024) -> 0.15704693 | E34: =E33/(1+$B$9)^(E$12-2024) -> 0.12053635 | F34: =F33/(1+$B$9)^(F$12-2024) -> 0.092197248 | G34: =G33/(1+$B$9)^(G$12-2024) -> 0.070322575 | H34: =H33/(1+$B$9)^(H$12-2024) -> 0.053515013 | I34: =I33/(1+$B$9)^(I$12-2024) -> 0.04064916 | ... K34: =K33/(1+$B$9)^(K$12-2024) -> 0.023355724
A35: Discounted units of value | B35: =B34*$B$10 -> 0.84003885 | C35: =C34*$B$10 -> 0.2939837 | D35: =D34*$B$10 -> 0.22657083 | E35: =E34*$B$10 -> 0.17389719 | F35: =F34*$B$10 -> 0.13301251 | G35: =G34*$B$10 -> 0.10145403 | H35: =H34*$B$10 -> 0.077205843 | I35: =I34*$B$10 -> 0.058644342 | ... K35: =K34*$B$10 -> 0.033695187
A36: Total units of value given people reached | B36: =B35*$B$13 -> 3426.1931 | C36: =C35*$B$13 -> 1199.0457 | D36: =D35*$B$13 -> 924.09468 | E36: =E35*$B$13 -> 709.25929 | F36: =F35*$B$13 -> 542.50653 | G36: =G35*$B$13 -> 413.79169 | H36: =H35*$B$13 -> 314.89273 | I36: =I35*$B$13 -> 239.18756 | ... K36: =K35*$B$13 -> 137.42962
A37: Year 2-10 consumption gains (as % of year 1 consumption gains) | B37: =SUM(C36:K36)/B36 -> 1.3605831
A39: Mozambique | B39: 2024 | C39: =B39+1 -> 2025 | D39: =C39+1 -> 2026 | E39: =D39+1 -> 2027 | F39: =E39+1 -> 2028 | G39: =F39+1 -> 2029 | H39: =G39+1 -> 2030 | I39: =H39+1 -> 2031 | J39: =I39+1 -> 2032 | K39: =J39+1 -> 2033
A40: Number of people reached | B40: ='New CEA'!D12 -> 3300
A41: Transfer size per person | B41: ='New CEA'!D11 -> 639.08746
A42: Year 1 increase in consumption | B42: =B41*(1-D$4) -> 364.27985
A43: Amount invested/saved | B43: =B41-B42 -> 274.80761
A44: Baseline/counterfactual consumption | B44: ='New CEA'!D14 -> 449.78149 | C44: =B44*(1+$D$7) -> 454.2793 | D44: =C44*(1+$D$7) -> 458.8221 | E44: =D44*(1+$D$7) -> 463.41032 | F44: =E44*(1+$D$7) -> 468.04442 | G44: =F44*(1+$D$7) -> 472.72487 | H44: =G44*(1+$D$7) -> 477.45211 | I44: =H44*(1+$D$7) -> 482.22664 | J44: =I44*(1+$D$7) -> 487.0489 | K44: =J44*(1+$D$7) -> 491.91939
...

Sheet GE
A1: What is this? This tab applies adjustments to the headline economic multiplier estimate from Egger et al.
A2: Accounting adjustment | C2: Notes
A3: Total transfer amount per person (denominator) | B3: =Consumption!$B$14 -> 487.89962
A4: Transfer multiplier | B4: 2.5 | C4: Egger et al. multiplier
A5: Implied economic activity generated (numerator) | B5: =B3*B4 -> 1219.7491 | C5: Implied
A6: Recipient consumption/investment returns by year 2 | B6: =SUM(Consumption!$B$18:$C$18) -> 362.02152 | C6: Calculated elsewhere in the model
A7: Implied accounting adjustment | B7: =(B5-B6)/B5 -> 0.7032
A9: Sense-check: what is our implied multiplier?
B10: Kenya | C10: Malawi | D10: Mozambique | E10: Rwanda | F10: Uganda | G10: Notes:
A11: Total transfer amount per person (denominator) | B11: ='New CEA'!B11 -> 487.89962 | C11: ='New CEA'!C11 -> 651.46361 | D11: ='New CEA'!D11 -> 639.08746 | E11: ='New CEA'!E11 -> 714.75028 | F11: ='New CEA'!F11 -> 589.31378
A12: Recipient consumption/investment returns by year 2 | B12: =SUM(Consumption!$B$18:$C$18) -> 362.02152 | C12: =SUM(Consumption!$B$32:$C$32) -> 483.386 | D12: =SUM(Consumption!$B$45:$C$45) -> 474.2029 | E12: =SUM(Consumption!$B$58:$C$58) -> 530.34471 | F12: =SUM(Consumption!$B$71:$C$71) -> 437.27082 | G12: Implied by my consumption assumptions
A13: Non-recipient consumption benefits (as % of recipient consumption benefits) | B13: ='New CEA'!B36 -> 0.675072 | C13: ='New CEA'!C36 -> 0.590688 | D13: ='New CEA'!D36 -> 0.590688 | E13: ='New CEA'!E36 -> 0.63288 | F13: ='New CEA'!F36 -> 0.63288
A14: Distributional adjustment | B14: ='New CEA'!B35 -> 0.8 | C14: ='New CEA'!C35 -> 0.8 | D14: ='New CEA'!D35 -> 0.8 | E14: ='New CEA'!E35 -> 0.8 | F14: ='New CEA'!F35 -> 0.8
A15: Non-recipient consumption/investment returns by year 2 | B15: =(B12*B13)/B14 -> 305.48824 | C15: =(C12*C13)/C14 -> 356.91289 | D15: =(D12*D13)/D14 -> 350.13245 | E15: =(E12*E13)/E14 -> 419.5557 | F15: =(F12*F13)/F14 -> 345.92495
A16: Recipient + non-recipient consumption & investment returns by year 2 (numerator) | B16: =B15+B12 -> 667.50976 | C16: =C15+C12 -> 840.29889 | D16: =D15+D12 -> 824.33535 | E16: =E15+E12 -> 949.90041 | F16: =F15+F12 -> 783.19577
A17: Implied multiplier | B17: =B16/B11 -> 1.3681293 | C17: =C16/C11 -> 1.2898631 | D17: =D16/D11 -> 1.2898631 | E17: =E16/E11 -> 1.3289962 | F17: =F16/F11 -> 1.3289962
A20: Sense-check: what do our assumptions imply about how we expect the multiplier to grow across time?
A21: Kenya | B21: Year 2 | C21: Year 3 | D21: Year 4 | E21: Year 5 | F21: Year 6 | G21: Year 7 | H21: Year 8 | I21: Year 9 | J21: Year 10
A22: Cumulative consumption gains of recipients | B22: =SUM(Consumption!$B18:C18) -> 362.02152 | C22: =SUM(Consumption!$B18:D18) -> 429.15651 | D22: =SUM(Consumption!$B18:E18) -> 482.8645 | E22: =SUM(Consumption!$B18:F18) -> 525.83089 | F22: =SUM(Consumption!$B18:G18) -> 560.204 | G22: =SUM(Consumption!$B18:H18) -> 587.7025 | H22: =SUM(Consumption!$B18:I18) -> 609.70129 | I22: =SUM(Consumption!$B18:J18) -> 627.30032 | J22: =SUM(Consumption!$B18:K18) -> 641.37955
A23: % increase from previous year | C23: =(C22-B22)/B22 -> 0.18544474 | D23: =(D22-C22)/C22 -> 0.12514779 | E23: =(E22-D22)/D22 -> 0.088982297 | F23: =(F22-E22)/E22 -> 0.065369141 | G23: =(G22-F22)/F22 -> 0.049086566 | H23: =(H22-G22)/G22 -> 0.037431852 | I23: =(I22-H22)/H22 -> 0.028865011 | J23: =(J22-I22)/I22 -> 0.022444158
A24: What this implies about by expected multiplier growth | B24: =B17 -> 1.3681293 | C24: =B24*(1+C23) -> 1.6218417 | D24: =C24*(1+D23) -> 1.8248116 | E24: =D24*(1+E23) -> 1.9871875 | F24: =E24*(1+F23) -> 2.1170882 | G24: =F24*(1+G23) -> 2.2210088 | H24: =G24*(1+H23) -> 2.3041453 | I24: =H24*(1+I23) -> 2.3706545 | J24: =I24*(1+J23) -> 2.4238618

Sheet Spillover
A1: What is this? This tab tries to reconstruct the Egger et al. multiplier from the bottom-up, given population census estimates and treatment effects estimated on recipients and non-recipients (Table 1)
A2: Transfer amount | B2: BOTEC | D2: Notes | E2: Source
A3: Recipient households | B3: 10500 | E3: "We provided one-time cash transfers of about USD 1000 to over 10,500 poor households across 653 randomized villages in rural Kenya", Egger et al. (2022)
A4: Size of transfer (PPP) | B4: 1871 | E4: "These households received a series of three transfers totaling KES 87,000, or USD 1871 PPP (USD 1000 nominal)"
A5: Total amount transferred | B5: =B3*B4 -> 19645500 | D5: Denominator of the multiplier
A6: Consumption multiplier
A7: Recipients
A8: Average effect on annual consumption, recipients (PPP) | B8: 338 | E8: Table 1, column 2
A9: Median timing of follow-up (months) | B9: 19 | E9: "The 5th/95th percentiles of timing ranged from 12 to 27 months, and the median survey was conducted 19 months after the experimental start month"
A10: Timing of follow-up (years, rounded) | B10: 2
A11: Average increase in consumption, recipient households | B11: =B10*B8 -> 676 | E11: "The increase in GDP is fairly stable over time; in fact, we cannot reject that the expenditure response is constant across all quarters (p-value of 0.53)", Egger et al. (2022), page 29
A12: Total increase in consumption, recipients | B12: =B11*B3 -> 7098000 | D12: Note: doesn't include asset expenditure
A13: Non-recipients
A14: Number of households in sampling frame | B14: 65000 | E14: "Our household and enterprise censuses of the study area count 65,383 households and 12,095 non-farm enterprises"
A15: % of households defined as nearby non-recipients | B15: 0.67 | E15: "We find that nonrecipient households account for 82% of the household contribution to the expenditure multiplier and 85% of the contribution to the income multiplier, both of which are somewhat higher than their share in the local population of 67%"
A16: Implied number of non-recipient households that were nearby recipient households | B16: =B14*B15 -> 43550
A17: Implied number of households that i) didn't receive transfers; ii) weren't nearby those that did (i.e. 'pure' controls) | B17: =B14-B3-B16 -> 10950
A18: Average effect on annual consumption, non-recipients (PPP) | B18: 334 | E18: Table 1, column 3
A19: Average increase in consumption, non-recipient households | B19: =B18*B10 -> 668 | D19: Assume same 2 year follow-up
A20: Total increase in consumption, non-recipients | B20: =B19*B16 -> 29091400
A22: Total increase in consumption among recipients + nearby non-recipients | B22: =B20+B12 -> 36189400
A23: Implied consumption multiplier | B23: =B22/B5 -> 1.8421216 | D23: Consumption multiplier in Egger et al. = 2.0. Roughly checks out
A25: Transfer amount that still needs to be 'explained' | B25: =B5-B12 -> 12547500 | D25: Remainder of the cash transfer that isn't yet accounted for
A26: Total increase in economic activity if we include this as investment expenditure (metal roofs, farming equipment, radios etc.) | B26: =B25+B22 -> 48736900 | D26: Assume all the transfer which isn't consumed goes towards investment
A27: Implied total economic multiplier | B27: =B26/B5 -> 2.4808175 | D27: Checks out
A29: Sense checks
B31: Bottom-up model | C31: Egger et al.
A32: Consumption gains to recipients | B32: =B12/$B$26 -> 0.14563914 | C32: =0.8*0.18 -> 0.144 | E32: "We find that nonrecipient households account for 82% of the household contribution to the expenditure multiplier and 85% of the contribution to the income multiplier, both of which are somewhat higher than their share in the local population of 67%" See Table 5 - consumption contributes ~2.0 of the 2.5 multiplier, implying a ~80% contribution
A33: Asset/investment gains to recipients | B33: =B25/$B$26 -> 0.2574538 | C33: 0.2
A34: Consumption gains to non-recipients | B34: =B20/$B$26 -> 0.59690707 | C34: =0.8*0.82 -> 0.656 | E34: "We find that nonrecipient households account for 82% of the household contribution to the expenditure multiplier and 85% of the contribution to the income multiplier, both of which are somewhat higher than their share in the local population of 67%" See Table 5 - consumption contributes ~2.0 of the 2.5 multiplier, implying a ~80% contribution

Sheet Mortality
A1: Sense checks
A2: How does the Egger et al. estimate triangulate with x-country correlations between u5 mortality and baseline consumption?
C3: Source
A4: u5 mortality rate during the trial | B4: 0.057 | C4: Egger et al. (2024), Table 1
A5: Reduction due to GD progam | B5: 0.45 | C5: "Unconditional cash transfers (accounting for spillovers) lead to 48% fewer infant deaths before age one and 45% fewer child deaths before age five", Walker et al. (2025), page 1
A6: Implied u5 mortality rate during GD program | B6: =B4*(1-B5) -> 0.03135
A8: Household consumption in control group in Egger et al. (PPP) | B8: 2536 | C8: Egger et al. (2022), Table 1
A9: Size of transfer per household (PPP) | B9: 1871 | C9: "These households received a series of three transfers totaling KES 87,000, or USD 1871 PPP (USD 1000 nominal)", Egger et al. (2022), page 2
A10: Average household size | B10: =Baseline!B4 -> 4.2
A11: Size of transfer per member (PPP) | B11: =B9/B10 -> 445.47619
A12: Marginal propensity to consume | B12: 0.76 | C12: "These estimates are broadly in line with what a simple model would imply from households’ marginal propensity to consume local value added, which we estimate to be approximately 0.76 over the study period", page 4
A13: Timing of follow-up (years) | B13: 1.5 | C13: "The 5th/95th percentiles of timing ranged from 12 to 27 months, and the median survey was conducted 19 months after the experimental start month", Egger et al. (2022), page 7
A14: Consumption per capita (non-recipients) | B14: =B8/B10 -> 603.80952
A15: Consumption per capita (recipients) | B15: =B14+(B11*B12)/B13 -> 829.51746
B17: Year consumption estimate pertains to | C17: Annual consumption per capita (2017 PPP) | D17: under-5 mortality rate (%)
A18: Egger et al - control | B18: 2015-17 | C18: =B14 -> 603.80952 | D18: =B4 -> 0.057
A19: Egger et al - recipients | B19: 2015-17 | C19: =B15 -> 829.51746 | D19: =B6 -> 0.03135 | E19: =(D23-D19)/D23 -> 0.32217975
A20: Burundi | B20: {=ROUND(INDEX(WB!$I$70:$I$114,MATCH($A20,WB!$C$70:$C$524,0)),0)} -> 2020 | C20: {=INDEX(WB!$R$70:$R$114,MATCH($A20,WB!$C$70:$C$524,0))*365} -> 854.58326 | D20: {=INDEX(UNICEF!$H$12:$R$211,MATCH($A20,UNICEF!$B$12:$B$211,0),MATCH($B20,UNICEF!$H$11:$R$11,0))/1000} -> 0.0542285
A21: Democratic Republic of the Congo | B21: {=ROUND(INDEX(WB!$I$70:$I$114,MATCH($A21,WB!$C$70:$C$524,0)),0)} -> 2020 | C21: {=INDEX(WB!$R$70:$R$114,MATCH($A21,WB!$C$70:$C$524,0))*365} -> 637.92547 | D21: {=INDEX(UNICEF!$H$12:$R$211,MATCH($A21,UNICEF!$B$12:$B$211,0),MATCH($B21,UNICEF!$H$11:$R$11,0))/1000} -> 0.0808046
A22: Ethiopia | B22: {=ROUND(INDEX(WB!$I$70:$I$114,MATCH($A22,WB!$C$70:$C$524,0)),0)} -> 2016 | C22: {=INDEX(WB!$R$70:$R$114,MATCH($A22,WB!$C$70:$C$524,0))*365} -> 1364.7299 | D22: {=INDEX(UNICEF!$H$12:$R$211,MATCH($A22,UNICEF!$B$12:$B$211,0),MATCH($B22,UNICEF!$H$11:$R$11,0))/1000} -> 0.0598782
A23: Kenya | B23: {=ROUND(INDEX(WB!$I$70:$I$114,MATCH($A23,WB!$C$70:$C$524,0)),0)} -> 2016 | C23: {=INDEX(WB!$R$70:$R$114,MATCH($A23,WB!$C$70:$C$524,0))*365} -> 1549.8305 | D23: {=INDEX(UNICEF!$H$12:$R$211,MATCH($A23,UNICEF!$B$12:$B$211,0),MATCH($B23,UNICEF!$H$11:$R$11,0))/1000} -> 0.0462512
A24: Lesotho | B24: {=ROUND(INDEX(WB!$I$70:$I$114,MATCH($A24,WB!$C$70:$C$524,0)),0)} -> 2017 | C24: {=INDEX(WB!$R$70:$R$114,MATCH($A24,WB!$C$70:$C$524,0))*365} -> 1694.8399 | D24: {=INDEX(UNICEF!$H$12:$R$211,MATCH($A24,UNICEF!$B$12:$B$211,0),MATCH($B24,UNICEF!$H$11:$R$11,0))/1000} -> 0.075958
A25: Madagascar | B25: {=ROUND(INDEX(WB!$I$70:$I$114,MATCH($A25,WB!$C$70:$C$524,0)),0)} -> 2013 | C25: {=INDEX(WB!$R$70:$R$114,MATCH($A25,WB!$C$70:$C$524,0))*365} -> 580.59199 | D25: {=INDEX(UNICEF!$H$12:$R$211,MATCH($A25,UNICEF!$B$12:$B$211,0),MATCH($B25,UNICEF!$H$11:$R$11,0))/1000} -> 0.0668041
A26: Mozambique | B26: {=ROUND(INDEX(WB!$I$70:$I$114,MATCH($A26,WB!$C$70:$C$524,0)),0)} -> 2020 | C26: {=INDEX(WB!$R$70:$R$114,MATCH($A26,WB!$C$70:$C$524,0))*365} -> 765.08453 | D26: {=INDEX(UNICEF!$H$12:$R$211,MATCH($A26,UNICEF!$B$12:$B$211,0),MATCH($B26,UNICEF!$H$11:$R$11,0))/1000} -> 0.0701006
A27: Malawi | B27: {=ROUND(INDEX(WB!$I$70:$I$114,MATCH($A27,WB!$C$70:$C$524,0)),0)} -> 2019 | C27: {=INDEX(WB!$R$70:$R$114,MATCH($A27,WB!$C$70:$C$524,0))*365} -> 755.3175 | D27: {=INDEX(UNICEF!$H$12:$R$211,MATCH($A27,UNICEF!$B$12:$B$211,0),MATCH($B27,UNICEF!$H$11:$R$11,0))/1000} -> 0.0454005
A28: Rwanda | B28: {=ROUND(INDEX(WB!$I$70:$I$114,MATCH($A28,WB!$C$70:$C$524,0)),0)} -> 2017 | C28: {=INDEX(WB!$R$70:$R$114,MATCH($A28,WB!$C$70:$C$524,0))*365} -> 1126.6805 | D28: {=INDEX(UNICEF!$H$12:$R$211,MATCH($A28,UNICEF!$B$12:$B$211,0),MATCH($B28,UNICEF!$H$11:$R$11,0))/1000} -> 0.0447029
A29: Tanzania | B29: {=ROUND(INDEX(WB!$I$70:$I$114,MATCH($A29,WB!$C$70:$C$524,0)),0)} -> 2018 | C29: {=INDEX(WB!$R$70:$R$114,MATCH($A29,WB!$C$70:$C$524,0))*365} -> 1202.5838 | D29: {=INDEX(UNICEF!$H$12:$R$211,MATCH($A29,UNICEF!$B$12:$B$211,0),MATCH($B29,UNICEF!$H$11:$R$11,0))/1000} -> 0.0478895
A30: Uganda | B30: {=ROUND(INDEX(WB!$I$70:$I$114,MATCH($A30,WB!$C$70:$C$524,0)),0)} -> 2017 | C30: {=INDEX(WB!$R$70:$R$114,MATCH($A30,WB!$C$70:$C$524,0))*365} -> 1290.8714 | D30: {=INDEX(UNICEF!$H$12:$R$211,MATCH($A30,UNICEF!$B$12:$B$211,0),MATCH($B30,UNICEF!$H$11:$R$11,0))/1000} -> 0.0500448
A31: Zambia | B31: {=ROUND(INDEX(WB!$I$70:$I$114,MATCH($A31,WB!$C$70:$C$524,0)),0)} -> 2015 | C31: {=INDEX(WB!$R$70:$R$114,MATCH($A31,WB!$C$70:$C$524,0))*365} -> 1085.6618 | D31: {=INDEX(UNICEF!$H$12:$R$211,MATCH($A31,UNICEF!$B$12:$B$211,0),MATCH($B31,UNICEF!$H$11:$R$11,0))/1000} -> 0.0680389
A32: Zimbabwe | B32: {=ROUND(INDEX(WB!$I$70:$I$114,MATCH($A32,WB!$C$70:$C$524,0)),0)} -> 2017 | C32: {=INDEX(WB!$R$70:$R$114,MATCH($A32,WB!$C$70:$C$524,0))*365} -> 1609.3598 | D32: {=INDEX(UNICEF!$H$12:$R$211,MATCH($A32,UNICEF!$B$12:$B$211,0),MATCH($B32,UNICEF!$H$11:$R$11,0))/1000} -> 0.0557896

Sheet Development
A1: What is this? Sense check of how development effects might contribute to CE given different treatment effects
B2: Kenya | C2: Malawi | D2: Mozambique | E2: Rwanda | F2: Uganda | G2: Notes
A3: Size of transfer
A4: Arbitrary donation (nominal USD) | B4: ='New CEA'!$B$4 -> 1000000 | C4: ='New CEA'!$B$4 -> 1000000 | D4: ='New CEA'!$B$4 -> 1000000 | E4: ='New CEA'!$B$4 -> 1000000 | F4: ='New CEA'!$B$4 -> 1000000
A5: Number of households receiving transfer | B5: ='New CEA'!B$7 -> 971.09827 | C5: ='New CEA'!C$7 -> 840 | D5: ='New CEA'!D$7 -> 750 | E5: ='New CEA'!E$7 -> 772.72727 | F5: ='New CEA'!F$7 -> 743.4555
A6: Average household size | B6: ='New CEA'!B10 -> 4.2 | C6: ='New CEA'!C10 -> 4.5 | D6: ='New CEA'!D10 -> 4.4 | E6: ='New CEA'!E10 -> 4.3 | F6: ='New CEA'!F10 -> 4.8
A7: Number of people directly targeted | B7: =B6*B5 -> 4078.6127 | C7: =C6*C5 -> 3780 | D7: =D6*D5 -> 3300 | E7: =E6*E5 -> 3322.7273 | F7: =F6*F5 -> 3568.5864
A8: u15 share of people targeted | B8: =SUM(Equivalence!B20:B22)/Equivalence!B41 -> 0.37811439 | C8: =SUM(Equivalence!C20:C22)/Equivalence!C41 -> 0.42592677 | D8: =SUM(Equivalence!D20:D22)/Equivalence!D41 -> 0.43291063 | E8: =SUM(Equivalence!E20:E22)/Equivalence!E41 -> 0.38066471 | F8: =SUM(Equivalence!F20:F22)/Equivalence!F41 -> 0.44781392
A9: Number of u15 children targeted | B9: =B8*B7 -> 1542.1822 | C9: =C8*C7 -> 1610.0032 | D9: =D8*D7 -> 1428.6051 | E9: =E8*E7 -> 1264.845 | F9: =F8*F7 -> 1598.0627
A10: Baseline annual consumption per capita (PPP 2017) | B10: ='New CEA'!B14 -> 651.96604 | C10: ='New CEA'!C14 -> 469.98486 | D10: ='New CEA'!D14 -> 449.78149 | E10: ='New CEA'!E14 -> 532.64139 | F10: ='New CEA'!F14 -> 625.55328
A11: Effect of exposure to GD program in childhood on adult earnings | B11: 0.02 | C11: 0.02 | D11: 0.02 | E11: 0.02 | F11: 0.02
A12: Annual increase in ln consumption in adulthood | B12: =ln(B10*(1+B11))-ln(B10) -> 0.019802627 | C12: =ln(C10*(1+C11))-ln(C10) -> 0.019802627 | D12: =ln(D10*(1+D11))-ln(D10) -> 0.019802627 | E12: =ln(E10*(1+E11))-ln(E10) -> 0.019802627 | F12: =ln(F10*(1+F11))-ln(F10) -> 0.019802627
A13: Years until benefits start to materialize | B13: 10 | C13: 10 | D13: 10 | E13: 10 | F13: 10
A14: Discount rate | B14: 0.04 | C14: 0.04 | D14: 0.04 | E14: 0.04 | F14: 0.04
A15: Benefit on one year's income, discounted | B15: =B12/(1+B14)^B13 -> 0.013377945 | C15: =C12/(1+C14)^C13 -> 0.013377945 | D15: =D12/(1+D14)^D13 -> 0.013377945 | E15: =E12/(1+E14)^E13 -> 0.013377945 | F15: =F12/(1+F14)^F13 -> 0.013377945
A16: Years of working life | B16: 40 | C16: 40 | D16: 40 | E16: 40 | F16: 40
A17: Present value of increase in adult ln consumption | B17: =pv(B14,B16,-B15) -> 0.26478665 | C17: =pv(C14,C16,-C15) -> 0.26478665 | D17: =pv(D14,D16,-D15) -> 0.26478665 | E17: =pv(E14,E16,-E15) -> 0.26478665 | F17: =pv(F14,F16,-F15) -> 0.26478665
A18: Multiplier for resource sharing within household | B18: 2 | C18: 2 | D18: 2 | E18: 2 | F18: 2
A19: Value assigned to increasing ln(consumption) by one unit for one person for one year | B19: 1.44 | C19: 1.44 | D19: 1.44 | E19: 1.44 | F19: 1.44
A20: Units of value from development benefits | B20: =B17*B18*B19*B9 -> 1176.0458 | C20: =C17*C18*C19*C9 -> 1227.7652 | D20: =D17*D18*D19*D9 -> 1089.4336 | E20: =E17*E18*E19*E9 -> 964.55253 | F20: =F17*F18*F19*F9 -> 1218.6595
A21: Units of value per $ | B21: =B20/B4 -> 0.0011760458 | C21: =C20/C4 -> 0.0012277652 | D21: =D20/D4 -> 0.0010894336 | E21: =E20/E4 -> 0.00096455253 | F21: =F20/F4 -> 0.0012186595
A22: Cost-effectiveness (x cash) | B22: =B21/0.003355 -> 0.35053527 | C22: =C21/0.003355 -> 0.36595087 | D22: =D21/0.003355 -> 0.3247194 | E22: =E21/0.003355 -> 0.28749703 | F22: =F21/0.003355 -> 0.36323681

Sheet RFMF
B1: Kenya | C1: Malawi | D1: Mozambique | E1: Rwanda | F1: Uganda
A2: Population estimate (million) | B2: =Equivalence!B41/1000000 -> 54.027475 | C2: =Equivalence!C41/1000000 -> 20.405306 | D2: =Equivalence!D41/1000000 -> 33.897345 | E2: =Equivalence!E41/1000000 -> 14.094674 | F2: =Equivalence!F41/1000000 -> 47.249574
A3: Average household size | B3: =Baseline!B4 -> 4.2 | C3: =Baseline!C4 -> 4.5 | D3: =Baseline!D4 -> 4.4 | E3: =Baseline!E4 -> 4.3 | F3: =Baseline!F4 -> 4.8
A4: Estimated number of households (million) | B4: =B2/B3 -> 12.863685 | C4: =C2/C3 -> 4.5345124 | D4: =D2/D3 -> 7.703942 | E4: =E2/E3 -> 3.2778312 | F4: =F2/F3 -> 9.8436613
A5: Poverty headcount rate (%) | B5: {=INDEX(WB!$N$70:$N$114,MATCH(B$1,WB!$C$70:$C$114,0))} -> 0.293651 | C5: {=INDEX(WB!$N$70:$N$114,MATCH(C$1,WB!$C$70:$C$114,0))} -> 0.700606 | D5: {=INDEX(WB!$N$70:$N$114,MATCH(D$1,WB!$C$70:$C$114,0))} -> 0.745284 | E5: {=INDEX(WB!$N$70:$N$114,MATCH(E$1,WB!$C$70:$C$114,0))} -> 0.520054 | F5: {=INDEX(WB!$N$70:$N$114,MATCH(F$1,WB!$C$70:$C$114,0))} -> 0.428616
A6: Estimated number of households living in extreme poverty (million) | B6: =B4*B5 -> 3.7774338 | C6: =C4*C5 -> 3.1769066 | D6: =D4*D5 -> 5.7416247 | E6: =E4*E5 -> 1.7046492 | F6: =F4*F5 -> 4.2191507
A7: Number of households that have received large one-off GD transfers | B7: =Country!B28 -> 122997 | C7: =Country!C28 -> 78579 | D7: =Country!D28 -> 5485 | E7: =Country!E28 -> 120393 | F7: =Country!F28 -> 78929
A8: Number of households that have received other types of GD transfers | B8: =406932-B7 -> 283935 | C8: =186900-C7 -> 108321 | E8: =221157-E7 -> 100764 | F8: =120520-F7 -> 41591
A9: Max % of households in extreme poverty that could have received a lump-sum GD transfer | B9: =B7/(B6*1000000) -> 0.032560994 | C9: =C7/(C6*1000000) -> 0.024734438 | D9: =D7/(D6*1000000) -> 0.00095530451 | E9: =E7/(E6*1000000) -> 0.070626261 | F9: =F7/(F6*1000000) -> 0.018707319
A10: Max % of households in extreme poverty that could have received any GD transfer | B10: =(B7+B8)/(B6*1000000) -> 0.1077271 | C10: =(C7+C8)/(C6*1000000) -> 0.058830813 | E10: =(E7+E8)/(E6*1000000) -> 0.12973754 | F10: =(F7+F8)/(F6*1000000) -> 0.028564991
A11: % of households in extreme poverty that have not received transfers | B11: =1-B9 -> 0.96743901 | C11: =1-C9 -> 0.97526556 | E11: =1-E9 -> 0.92937374 | F11: =1-F9 -> 0.98129268

Sheet Uncertainty
A1: Uncertainty
A2: Inputs | B2: Inputs for Monte Carlo simulations of our GiveDirectly model
A3: Sims | B3: Simulations of our GiveDirectly CEA based on the inputs in the previous tab

Sheet Inputs
A1: What is this? This tab specifies inputs for Monte Carlo simulations of our GiveDirectly model
B2: Distribution | C2: p5 | D2: p25 | E2: Kenya | F2: p75 | G2: p95
A3: Program reach
A4: Arbitrary donation (nominal USD) | E4: {=INDEX('New CEA'!$B4:$F4,MATCH($E$2,'New CEA'!B$2:F$2,0))} -> 1000000
A5: Transfers as a percentage of total cost | D5: =$E5-($E5*$H5) -> 0.7896 | E5: {=INDEX('New CEA'!$B6:$F6,MATCH($E$2,'New CEA'!B$2:F$2,0))} -> 0.84 | F5: =$E5+($E5*$H5) -> 0.8904 | H5: 0.06
A6: Total size of transfer per household (nominal USD) | E6: {=INDEX('New CEA'!$B5:$F5,MATCH($E$2,'New CEA'!B$2:F$2,0))} -> 865
A7: Number of households receiving transfer | E7: =(E4*E5)/E6 -> 971.09827
A8: Average household size | E8: {=INDEX('New CEA'!$B10:$F10,MATCH($E$2,'New CEA'!B$2:F$2,0))} -> 4.2
A9: Number of people reached | E9: =E8*E7 -> 4078.6127
A10: Consumption gains to recipients
A11: Baseline annual consumption per capita (PPP 2017) | B11: Uniform | D11: =$E11-($E11*$H11) -> 554.17113 | E11: {=INDEX('New CEA'!$B14:$F14,MATCH($E$2,'New CEA'!B$2:F$2,0))} -> 651.96604 | F11: =$E11+($E11*$H11) -> 749.76094 | H11: 0.15
A12: PPP adjustment (2017) | E12: {=INDEX('New CEA'!$B8:$F8,MATCH($E$2,'New CEA'!B$2:F$2,0))} -> 2.3689924
A13: Total size of transfer per household (PPP 2017) | E13: =E12*E6 -> 2049.1784
A14: Size of transfer per person (PPP 2017) | E14: =E13/E8 -> 487.89962
A15: Percentage of transfers invested | E15: {=INDEX('New CEA'!$B15:$F15,MATCH($E$2,'New CEA'!B$2:F$2,0))} -> 0.43
A16: Percentage of transfers consumed in year 1 | E16: =1-E15 -> 0.57
A17: Implied increase in consumption per person in year 1 | E17: =E16*E14 -> 278.10278
A18: Percentage increase in consumption over baseline | D18: =$E18-($E18*$H18) -> 0.3625762 | E18: =((E17+E11)/E11)-1 -> 0.42656023 | F18: =$E18+($E18*$H18) -> 0.49054427 | H18: 0.15
A19: Immediate increase in ln(consumption) per person | E19: =ln(1+E18)-ln(1) -> 0.35526612
A20: Value assigned to increasing ln(consumption) by one unit for one person for one year | B20: Uniform | D20: =$E20-($E20*$H20) -> 1.0820213 | E20: {=INDEX('New CEA'!$B20:$F20,MATCH($E$2,'New CEA'!B$2:F$2,0))} -> 1.442695 | F20: =$E20+($E20*$H20) -> 1.8033688 | H20: 0.25
A21: Units of value from year 1 consumption gains per person | E21: =E19*E20 -> 0.51254066
A22: Units of value from year 1 consumption gains given program reach | E22: =E21*E9 -> 2090.4549
A23: Value of year 2-10 consumption returns as % of year 1 consumption returns | B23: Uniform | D23: =$E23-($E23*$H23) -> 0.73827165 | E23: {=INDEX('New CEA'!$B23:$F23,MATCH($E$2,'New CEA'!B$2:F$2,0))} -> 1.2304527 | F23: =$E23+($E23*$H23) -> 1.7226338 | H23: 0.4
A24: Units of value from year 1-10 consumption gains | E24: =E22+(E22*E23) -> 4662.6608
A25: Distributional adjustment (accounting for consumption gains accruing to richer recipients) | E25: {=INDEX('New CEA'!$B25:$F25,MATCH($E$2,'New CEA'!B$2:F$2,0))} -> 0.9
A26: Units of value from year 1-10 consumption gains post adjustments | D26: =PERCENTILE(Sims!$G26:$SL26,0.25) -> 2839.1911 | E26: =E24*E25 -> 4196.3947 | F26: =PERCENTILE(Sims!$G26:$SL26,0.75) -> 5238.554
A27: Units of value from recipient consumption gains per $ donated | E27: =E26/E4 -> 0.0041963947
A28: Previous GiveDirectly cost-effectiveness estimate (units of value per $) | E28: {=INDEX('New CEA'!$B28:$F28,MATCH($E$2,'New CEA'!B$2:F$2,0))} -> 0.003355
A29: Initial CE from recipient consumption gains (x previous benchmark) | D29: =PERCENTILE(Sims!$G$29:$SL$29,0.25) -> 0.84625666 | E29: =E27/E28 -> 1.2507883 | F29: =PERCENTILE(Sims!$G$29:$SL$29,0.75) -> 1.561417
A30: Spillovers to non-recipients/general equilibrium effects
A31: Egger et al. economic multiplier | E31: {=INDEX('New CEA'!$B31:$F31,MATCH($E$2,'New CEA'!B$2:F$2,0))} -> 2.5
A32: Double-counting adjustment (stripping out recipient consumption gains) | E32: {=INDEX('New CEA'!$B32:$F32,MATCH($E$2,'New CEA'!B$2:F$2,0))} -> 0.7032
A33: IV adjustment (regressing Egger et al. towards prior) | B33: Uniform | D33: =$E33-($E33*$H33) -> 0.27 | E33: {=INDEX('New CEA'!$B33:$F33,MATCH($E$2,'New CEA'!B$2:F$2,0))} -> 0.6 | F33: =$E33+($E33*$H33) -> 0.93 | H33: 0.55
A34: EV adjustment (generalizing the multiplier to current program conditions) | B34: Uniform | D34: =$E34-($E34*$H34) -> 0.32 | E34: {=INDEX('New CEA'!$B34:$F34,MATCH($E$2,'New CEA'!B$2:F$2,0))} -> 0.8 | F34: =$E34+($E34*$H34) -> 1.28 | H34: 0.6
A35: Distributional adjustment (accounting for consumption spillovers accruing to richer non-recipients) | B35: Uniform | D35: =$E35-($E35*$H35) -> 0.6 | E35: {=INDEX('New CEA'!$B35:$F35,MATCH($E$2,'New CEA'!B$2:F$2,0))} -> 0.8 | F35: =$E35+($E35*$H35) -> 1 | H35: 0.25
A36: Spillover/general equilibrium benefits (as % of recipient consumption benefits), post adjustments | E36: =E31*E35*E32*E33*E34 -> 0.675072
A37: Units of value from non-recipient spillovers | D37: =PERCENTILE(Sims!$G37:$SL37,0.25) -> 384.87509 | E37: =E26*E36 -> 2832.8686 | F37: =PERCENTILE(Sims!$G37:$SL37,0.75) -> 4152.021
A38: Units of value from consumption gains and non-recipient spillovers | E38: =E26+E37 -> 7029.2633
A39: Initial CE from consumption gains and spillovers (x previous benchmark) | E39: =(E38/E4)/E28 -> 2.0951604
A40: Mortality benefits
...

Sheet Sims
A1: What is this? This tab runs simulations of our GiveDirectly CEA based on the inputs in the previous tab | C1: Avg check | D1: p25 check | E1: p75 check
B2: =Inputs!E2 -> Kenya
A3: Program reach | F3: Sims >> | G3: 1 | H3: =G3+1 -> 2 | I3: =H3+1 -> 3 | J3: =I3+1 -> 4 | K3: =J3+1 -> 5 | L3: =K3+1 -> 6 | M3: =L3+1 -> 7 | N3: =M3+1 -> 8 | O3: =N3+1 -> 9 | ... SL3: =SK3+1 -> 500
A4: Arbitrary donation (nominal USD) | B4: =Inputs!E4 -> 1000000 | G4: =$B4 -> 1000000 | H4: =$B4 -> 1000000 | I4: =$B4 -> 1000000 | J4: =$B4 -> 1000000 | K4: =$B4 -> 1000000 | L4: =$B4 -> 1000000 | M4: =$B4 -> 1000000 | N4: =$B4 -> 1000000 | ... SL4: =$B4 -> 1000000
A5: Transfers as a percentage of total cost | B5: =Inputs!E5 -> 0.84 | C5: =AVERAGE(G5:SL5) -> 0.8355826 | D5: =PERCENTILE($G5:$SL5,0.25) -> 0.779675 | E5: =PERCENTILE($G5:$SL5,0.75) -> 0.889475 | G5: =RANDBETWEEN((Inputs!$E5-(Inputs!$E5-Inputs!$D5)*2)*10000,(Inputs!$E5+(Inputs!$F5-Inputs!$E5)*2)*10000)/10000 -> 0.8734 | H5: =RANDBETWEEN((Inputs!$E5-(Inputs!$E5-Inputs!$D5)*2)*10000,(Inputs!$E5+(Inputs!$F5-Inputs!$E5)*2)*10000)/10000 -> 0.9314 | I5: =RANDBETWEEN((Inputs!$E5-(Inputs!$E5-Inputs!$D5)*2)*10000,(Inputs!$E5+(Inputs!$F5-Inputs!$E5)*2)*10000)/10000 -> 0.857 | J5: =RANDBETWEEN((Inputs!$E5-(Inputs!$E5-Inputs!$D5)*2)*10000,(Inputs!$E5+(Inputs!$F5-Inputs!$E5)*2)*10000)/10000 -> 0.7686 | K5: =RANDBETWEEN((Inputs!$E5-(Inputs!$E5-Inputs!$D5)*2)*10000,(Inputs!$E5+(Inputs!$F5-Inputs!$E5)*2)*10000)/10000 -> 0.7801 | L5: =RANDBETWEEN((Inputs!$E5-(Inputs!$E5-Inputs!$D5)*2)*10000,(Inputs!$E5+(Inputs!$F5-Inputs!$E5)*2)*10000)/10000 -> 0.7534 | M5: =RANDBETWEEN((Inputs!$E5-(Inputs!$E5-Inputs!$D5)*2)*10000,(Inputs!$E5+(Inputs!$F5-Inputs!$E5)*2)*10000)/10000 -> 0.835 | N5: =RANDBETWEEN((Inputs!$E5-(Inputs!$E5-Inputs!$D5)*2)*10000,(Inputs!$E5+(Inputs!$F5-Inputs!$E5)*2)*10000)/10000 -> 0.9179 | ... SL5: =RANDBETWEEN((Inputs!$E5-(Inputs!$E5-Inputs!$D5)*2)*10000,(Inputs!$E5+(Inputs!$F5-Inputs!$E5)*2)*10000)/10000 -> 0.8834
A6: Total size of transfer per household (nominal USD) | B6: =Inputs!E6 -> 865 | G6: =$B6 -> 865 | H6: =$B6 -> 865 | I6: =$B6 -> 865 | J6: =$B6 -> 865 | K6: =$B6 -> 865 | L6: =$B6 -> 865 | M6: =$B6 -> 865 | N6: =$B6 -> 865 | ... SL6: =$B6 -> 865
A7: Number of households receiving transfer | B7: =(B4*B5)/B6 -> 971.09827 | G7: =(G4*G5)/G6 -> 1009.711 | H7: =(H4*H5)/H6 -> 1076.763 | I7: =(I4*I5)/I6 -> 990.75145 | J7: =(J4*J5)/J6 -> 888.55491 | K7: =(K4*K5)/K6 -> 901.84971 | L7: =(L4*L5)/L6 -> 870.98266 | M7: =(M4*M5)/M6 -> 965.31792 | N7: =(N4*N5)/N6 -> 1061.1561 | ... SL7: =(SL4*SL5)/SL6 -> 1021.2717
A8: Average household size | B8: =Inputs!E8 -> 4.2 | G8: =$B8 -> 4.2 | H8: =$B8 -> 4.2 | I8: =$B8 -> 4.2 | J8: =$B8 -> 4.2 | K8: =$B8 -> 4.2 | L8: =$B8 -> 4.2 | M8: =$B8 -> 4.2 | N8: =$B8 -> 4.2 | ... SL8: =$B8 -> 4.2
A9: Number of people reached | B9: =B8*B7 -> 4078.6127 | G9: =G8*G7 -> 4240.7861 | H9: =H8*H7 -> 4522.4046 | I9: =I8*I7 -> 4161.1561 | J9: =J8*J7 -> 3731.9306 | K9: =K8*K7 -> 3787.7688 | L9: =L8*L7 -> 3658.1272 | M9: =M8*M7 -> 4054.3353 | N9: =N8*N7 -> 4456.8555 | ... SL9: =SL8*SL7 -> 4289.341
A10: Consumption gains to recipients
A11: Baseline annual consumption per capita (PPP 2017) | B11: {=INDEX('New CEA'!$B14:$F14,MATCH($B$2,'New CEA'!B$2:F$2,0))} -> 651.96604 | C11: =AVERAGE(G11:SL11) -> 653.73655 | D11: =PERCENTILE($G11:$SL11,0.25) -> 554.05618 | E11: =PERCENTILE($G11:$SL11,0.75) -> 750.06737 | G11: =RANDBETWEEN((Inputs!$E11-(Inputs!$E11-Inputs!$D11)*2)*10000,(Inputs!$E11+(Inputs!$F11-Inputs!$E11)*2)*10000)/10000 -> 817.9051 | H11: =RANDBETWEEN((Inputs!$E11-(Inputs!$E11-Inputs!$D11)*2)*10000,(Inputs!$E11+(Inputs!$F11-Inputs!$E11)*2)*10000)/10000 -> 793.049 | I11: =RANDBETWEEN((Inputs!$E11-(Inputs!$E11-Inputs!$D11)*2)*10000,(Inputs!$E11+(Inputs!$F11-Inputs!$E11)*2)*10000)/10000 -> 697.8467 | J11: =RANDBETWEEN((Inputs!$E11-(Inputs!$E11-Inputs!$D11)*2)*10000,(Inputs!$E11+(Inputs!$F11-Inputs!$E11)*2)*10000)/10000 -> 488.0784 | K11: =RANDBETWEEN((Inputs!$E11-(Inputs!$E11-Inputs!$D11)*2)*10000,(Inputs!$E11+(Inputs!$F11-Inputs!$E11)*2)*10000)/10000 -> 819.7316 | L11: =RANDBETWEEN((Inputs!$E11-(Inputs!$E11-Inputs!$D11)*2)*10000,(Inputs!$E11+(Inputs!$F11-Inputs!$E11)*2)*10000)/10000 -> 609.1298 | M11: =RANDBETWEEN((Inputs!$E11-(Inputs!$E11-Inputs!$D11)*2)*10000,(Inputs!$E11+(Inputs!$F11-Inputs!$E11)*2)*10000)/10000 -> 484.7656 | N11: =RANDBETWEEN((Inputs!$E11-(Inputs!$E11-Inputs!$D11)*2)*10000,(Inputs!$E11+(Inputs!$F11-Inputs!$E11)*2)*10000)/10000 -> 604.9603 | ... SL11: =RANDBETWEEN((Inputs!$E11-(Inputs!$E11-Inputs!$D11)*2)*10000,(Inputs!$E11+(Inputs!$F11-Inputs!$E11)*2)*10000)/10000 -> 720.3762
A12: PPP adjustment (2017) | B12: {=INDEX('New CEA'!$B8:$F8,MATCH($B$2,'New CEA'!B$2:F$2,0))} -> 2.3689924 | G12: =$B12 -> 2.3689924 | H12: =$B12 -> 2.3689924 | I12: =$B12 -> 2.3689924 | J12: =$B12 -> 2.3689924 | K12: =$B12 -> 2.3689924 | L12: =$B12 -> 2.3689924 | M12: =$B12 -> 2.3689924 | N12: =$B12 -> 2.3689924 | ... SL12: =$B12 -> 2.3689924
A13: Total size of transfer per household (PPP 2017) | B13: =B12*B6 -> 2049.1784 | G13: =G12*G6 -> 2049.1784 | H13: =H12*H6 -> 2049.1784 | I13: =I12*I6 -> 2049.1784 | J13: =J12*J6 -> 2049.1784 | K13: =K12*K6 -> 2049.1784 | L13: =L12*L6 -> 2049.1784 | M13: =M12*M6 -> 2049.1784 | N13: =N12*N6 -> 2049.1784 | ... SL13: =SL12*SL6 -> 2049.1784
A14: Size of transfer per person (PPP 2017) | B14: =B13/B8 -> 487.89962 | G14: =G13/G8 -> 487.89962 | H14: =H13/H8 -> 487.89962 | I14: =I13/I8 -> 487.89962 | J14: =J13/J8 -> 487.89962 | K14: =K13/K8 -> 487.89962 | L14: =L13/L8 -> 487.89962 | M14: =M13/M8 -> 487.89962 | N14: =N13/N8 -> 487.89962 | ... SL14: =SL13/SL8 -> 487.89962
A15: Percentage of transfers invested | B15: {=INDEX('New CEA'!$B15:$F15,MATCH($B$2,'New CEA'!B$2:F$2,0))} -> 0.43 | G15: =$B15 -> 0.43 | H15: =$B15 -> 0.43 | I15: =$B15 -> 0.43 | J15: =$B15 -> 0.43 | K15: =$B15 -> 0.43 | L15: =$B15 -> 0.43 | M15: =$B15 -> 0.43 | N15: =$B15 -> 0.43 | ... SL15: =$B15 -> 0.43
A16: Percentage of transfers consumed in year 1 | B16: =1-B15 -> 0.57 | G16: =1-G15 -> 0.57 | H16: =1-H15 -> 0.57 | I16: =1-I15 -> 0.57 | J16: =1-J15 -> 0.57 | K16: =1-K15 -> 0.57 | L16: =1-L15 -> 0.57 | M16: =1-M15 -> 0.57 | N16: =1-N15 -> 0.57 | ... SL16: =1-SL15 -> 0.57
A17: Implied increase in consumption per person in year 1 | B17: =B16*B14 -> 278.10278 | G17: =G16*G14 -> 278.10278 | H17: =H16*H14 -> 278.10278 | I17: =I16*I14 -> 278.10278 | J17: =J16*J14 -> 278.10278 | K17: =K16*K14 -> 278.10278 | L17: =L16*L14 -> 278.10278 | M17: =M16*M14 -> 278.10278 | N17: =N16*N14 -> 278.10278 | ... SL17: =SL16*SL14 -> 278.10278
A18: Percentage increase in consumption over baseline | B18: =((B17+B11)/B11)-1 -> 0.42656023 | G18: =((G17+G11)/G11)-1 -> 0.3400184 | H18: =((H17+H11)/H11)-1 -> 0.35067541 | I18: =((I17+I11)/I11)-1 -> 0.39851558 | J18: =((J17+J11)/J11)-1 -> 0.56979121 | K18: =((K17+K11)/K11)-1 -> 0.33926078 | L18: =((L17+L11)/L11)-1 -> 0.45655751 | M18: =((M17+M11)/M11)-1 -> 0.57368506 | N18: =((N17+N11)/N11)-1 -> 0.45970419 | ... SL18: =((SL17+SL11)/SL11)-1 -> 0.38605216
A19: Immediate increase in ln(consumption) per person | B19: =ln(1+B18)-ln(1) -> 0.35526612 | G19: =ln(1+G18)-ln(1) -> 0.29268335 | H19: =ln(1+H18)-ln(1) -> 0.30060477 | I19: =ln(1+I18)-ln(1) -> 0.33541138 | J19: =ln(1+J18)-ln(1) -> 0.45094263 | K19: =ln(1+K18)-ln(1) -> 0.29211781 | L19: =ln(1+L18)-ln(1) -> 0.37607578 | M19: =ln(1+M18)-ln(1) -> 0.45342004 | N19: =ln(1+N18)-ln(1) -> 0.37823381 | ... SL19: =ln(1+SL18)-ln(1) -> 0.32645953
