Workbook

Sheet Key
A1: Guide to interpreting this cost-effectiveness analysis
A2: Sheet descriptions
E4: Main CEA | F4: This sheet contains the primary calculations that result in final cost-effectiveness estimates. This sheet draws on inputs from the "Inputs" sheet and inputs calculated in the other supplemental sheets listed below.
E5: Counterfactual malaria | F5: This sheet contains our calculations of how high malaria mortality and prevalence rates would be in the absence of SMC campaigns.
E6: Leverage/Funging | F6: This sheet contains our calculations of the impact that crowding in and crowding out funding by other contributors has on the benefits of the program.
E7: Inputs | F7: This sheet contains all of the manually entered input values informing the CEA, along with the sources and reasoning supporting them. This sheet also contains inputs sourced from the "GBD estimates" sheet.
E8: GBD estimates | F8: This sheet contains disease burden and population datasets downloaded from the Institute of Health Metrics (IHME)'s Global Burden of Disease (GBD) project.
E9: Simple CEA | F9: This sheet contains a simplified version of the CEA that is designed to be comparable to our CEAs of other programs.
E10: Confidence intervals | F10: This sheet contains our best guesses of the 25th and 75th percentile values for each of the parameters of our simple CEA.
E11: Sensitivity analysis | F11: This sheet contains the outputs of our sensitivity analysis that tests the cost-effectiveness ranges that would result from updating certain inputs to their 25th or 75th percentile values.
A13: Terminology key
C15: Terms specific to this CEA
E16: SMC season | F16: The part of the year when SMC is delivered because malaria transmission is highest. In locations where GiveWell currently supports SMC, this is either four or five months each year.
E17: SMC cycle | F17: Refers to a monthly SMC treatment cycle, which consists of a three-day treatment regimen of SMC medication that provides protection from malaria for one month.
E18: SMC round | F18: Refers to a year's worth of SMC cycles, which are typically delievered over a period of four to five consecutive months during the rainy season.
E19: Sahel | F19: A subregion of Africa where malaria transmission tends to be highly seasonal. Historically, SMC was only delivered at large scale within the Sahel. Since 2020-21, SMC is now being piloted in locations outside the Sahel.
E20: Malaria-attributable mortality | F20: Deaths that could be averted by SMC, either directly (because they are malaria deaths) or indirectly (because malaria indirectly increases the risk of death from other causes).
E21: Indirect malaria deaths | F21: Deaths in which malaria plays a causal role, but are attributed to another cause. For example, malaria may increase the likelihood of death from malnutrition or other infectious diseases. Malaria control interventions often have a larger effect on all-cause mortality than would be expected exclusively from declines in malaria-specific mortality, which we interpret as evidence that averting malaria may also avert deaths attributed to other causes.
C23: Terms used across GiveWell's CEAs
E24: Internal validity | F24: Describes an adjustment we make to the treatment effect of an intervention to account for the possibility that the treatment effects found in studies may not represent the true effect the intervention had on the populations studied.
E25: External validity | F25: Describes an adjustment we make to the treatment effect of an intervention to account for differences in the program implementation or populations treated in studies from the program implementation or populations treated by grantee programs.
E26: Leverage | F26: Describes a situation where a grantee's spending on a program causes other organizations or governments to contribute more to the program than they otherwise would have. In most cases, accounting for leverage increases cost-effectiveness
E27: Funging | F27: Describes a situation where a grantee's spending on a program causes other organizations or governments to contribute less to the program than they otherwise would have. In most cases, accounting for funging decreases cost-effectiveness.
E28: Counterfactual | F28: In most cases, describes the state of the world that would exist if we did not provide funding to a grantee for a program. When discussing the "counterfactual value of other actors' spending," we are referring to how much benefit another organization's or government's spending would generate if it were spent on something other than the grantee program.
E29: Moral weights | F29: To compare cost-effectiveness across different programs, we use ‘moral weights’ to quantify the benefits of different program impacts (e.g. increased income vs reduced deaths). We benchmark the value of each benefit to a value of 1, which we define as the value of doubling someone’s consumption for one year.
E30: Philanthropic actors | F30: Non-governmental organizations (NGOs) providing funding to philanthropic programs.
A32: Unit and source key
C34: Unit labels used in the CEA
E35: # | F35: Number
E36: per 1k | F36: Rate per 1,000
E37: per 100k | F37: Rate per 100,000
E38: $ | F38: U.S. dollars
E39: ln($) | F39: The natural logarithm of a monetary value
E40: % | F40: Percentage
E41: ppt | F41: Percentage points
E42: UoV | F42: Units of value: an arbitrary unit GiveWell uses to compare the moral value of different types of outcomes, such as saving lives or increasing income
E43: xcash | F43: Cost-effectiveness in terms of multiples of GiveDirectly's unconditional cash transfer program
C45: Source labels used in the CEA
E47: input | F47: A value pulled from the "Inputs" sheet
E48: calc | F48: A value calculated using other values in the same sheet
...

Sheet Main CEA
I1: Malaria Consortium | S1: Malaria Consortium
I2: Burkina Faso | J2: Chad | K2: Côte d'Ivoire | L2: DRC | M2: DRC | N2: DRC | O2: DRC | P2: Mozambique | Q2: Nigeria | R2: Nigeria | S2: Nigeria | T2: Nigeria | U2: Nigeria | V2: Nigeria | W2: Nigeria | X2: Nigeria | Y2: Nigeria | Z2: South Sudan | AA2: Togo | AB2: Uganda
A3: Main calculations | F3: unit | G3: type | H3: Overall | L3: Haut-Katanga | M3: Haut-Lomami | N3: Lualaba | O3: Tanganyika | P3: Nampula | Q3: Bauchi | R3: Borno | S3: FCT (Abuja) | T3: Kebbi | U3: Kogi | V3: Nasarawa | W3: Oyo | X3: Plateau | Y3: Sokoto | Z3: Northern Bahr El Ghazal | AB3: Karamoja
E4: Final cost-effectiveness estimate (pulled from below for visibility) | F4: =F193 -> xcash | G4: feed | H4: =H193 -> - | I4: =I193 -> 13.310868 | J4: =J193 -> 14.65303 | K4: =K193 -> 8.5184856 | L4: =L193 -> 10.227025 | M4: =M193 -> 11.22453 | N4: =N193 -> 12.200271 | O4: =O193 -> 12.821222 | ... AB4: =AB193 -> 6.7780673
A5: Costs
C7: GiveWell costs
E8: =HYPERLINK(buildUrl(CELL("address", Inputs!E8)), Inputs!E8) -> Grant size | F8: =Inputs!F8 -> $ | G8: =Inputs!G8 -> input | H8: =Inputs!H8 -> - | I8: =Inputs!I8 -> 0.01 | J8: =Inputs!J8 -> 0.01 | K8: =Inputs!K8 -> 0.01 | L8: =Inputs!L8 -> 0.01 | M8: =Inputs!M8 -> 0.01 | ... AB8: =Inputs!AB8 -> 0.01
C10: Cost breakdown
E11: =HYPERLINK(buildUrl(CELL("address", Inputs!E11)), Inputs!E11) -> Percentage of total costs covered by the grantee | F11: =Inputs!F11 -> % | G11: =Inputs!G11 -> input | H11: =Inputs!H11 -> - | I11: =Inputs!I11 -> 0.8944838 | J11: =Inputs!J11 -> 0.90224903 | K11: =Inputs!K11 -> 0.906659 | L11: =Inputs!L11 -> 0.50149962 | M11: =Inputs!M11 -> 0.50149962 | ... AB11: =Inputs!AB11 -> 0.89331272
E12: =HYPERLINK(buildUrl(CELL("address", Inputs!E12)), Inputs!E12) -> Percentage of total costs covered by other philanthropic actors | F12: =Inputs!F12 -> % | G12: =Inputs!G12 -> input | H12: =Inputs!H12 -> - | I12: =Inputs!I12 -> 0 | J12: =Inputs!J12 -> 0 | K12: =Inputs!K12 -> 0 | L12: =Inputs!L12 -> 0.43937414 | M12: =Inputs!M12 -> 0.43937414 | ... AB12: =Inputs!AB12 -> 0
E13: =HYPERLINK(buildUrl(CELL("address", Inputs!E13)), Inputs!E13) -> Percentage of total costs covered by domestic governments | F13: =Inputs!F13 -> % | G13: =Inputs!G13 -> input | H13: =Inputs!H13 -> - | I13: =Inputs!I13 -> 0.1055162 | J13: =Inputs!J13 -> 0.09775097 | K13: =Inputs!K13 -> 0.093341 | L13: =Inputs!L13 -> 0.05912624 | M13: =Inputs!M13 -> 0.05912624 | ... AB13: =Inputs!AB13 -> 0.10668728
C15: Total costs
E16: Total spending by all contributors | F16: $ | G16: calc | H16: - | I16: =IF(I8="-",$H8/I11,I8/I11) -> 0.011179632 | J16: =IF(J8="-",$H8/J11,J8/J11) -> 0.011083415 | K16: =IF(K8="-",$H8/K11,K8/K11) -> 0.011029505 | L16: =IF(L8="-",$H8/L11,L8/L11) -> 0.019940195 | M16: =IF(M8="-",$H8/M11,M8/M11) -> 0.019940195 | N16: =IF(N8="-",$H8/N11,N8/N11) -> 0.019940195 | O16: =IF(O8="-",$H8/O11,O8/O11) -> 0.019940195 | P16: =IF(P8="-",$H8/P11,P8/P11) -> 19516180 | ... AB16: =IF(AB8="-",$H8/AB11,AB8/AB11) -> 0.011194288
C18: Total spending attributable to different actors
E19: Total spending contributed by grantee | F19: $ | G19: calc | H19: - | I19: =I$16*I11 -> 0.01 | J19: =J$16*J11 -> 0.01 | K19: =K$16*K11 -> 0.01 | L19: =L$16*L11 -> 0.01 | M19: =M$16*M11 -> 0.01 | N19: =N$16*N11 -> 0.01 | O19: =O$16*O11 -> 0.01 | P19: =P$16*P11 -> 17456907 | ... AB19: =AB$16*AB11 -> 0.01
E20: Total spending contributed by other philanthropic actors | F20: $ | G20: calc | H20: - | I20: =I$16*I12 -> 0 | J20: =J$16*J12 -> 0 | K20: =K$16*K12 -> 0 | L20: =L$16*L12 -> 0.0087612059 | M20: =M$16*M12 -> 0.0087612059 | N20: =N$16*N12 -> 0.0087612059 | O20: =O$16*O12 -> 0.0087612059 | P20: =P$16*P12 -> 0 | ... AB20: =AB$16*AB12 -> 0
E21: Total spending contributed by domestic governments | F21: $ | G21: calc | H21: - | I21: =I$16*I13 -> 0.0011796323 | J21: =J$16*J13 -> 0.0010834145 | K21: =K$16*K13 -> 0.001029505 | L21: =L$16*L13 -> 0.0011789887 | M21: =M$16*M13 -> 0.0011789887 | N21: =N$16*N13 -> 0.0011789887 | O21: =O$16*O13 -> 0.0011789887 | P21: =P$16*P13 -> 2059273.2 | ... AB21: =AB$16*AB13 -> 0.0011942882
C23: Upstream / downstream spending
E24: Total spending causally upstream of donations to grantee | F24: $ | G24: calc | H24: - | I24: =SUM(I19:I20) -> 0.01 | J24: =SUM(J19:J20) -> 0.01 | K24: =SUM(K19:K20) -> 0.01 | L24: =SUM(L19:L20) -> 0.018761206 | M24: =SUM(M19:M20) -> 0.018761206 | N24: =SUM(N19:N20) -> 0.018761206 | O24: =SUM(O19:O20) -> 0.018761206 | P24: =SUM(P19:P20) -> 17456907 | ... AB24: =SUM(AB19:AB20) -> 0.01
E25: Total spending causally downstream of donations to grantee | F25: $ | G25: calc | H25: - | I25: =I21 -> 0.0011796323 | J25: =J21 -> 0.0010834145 | K25: =K21 -> 0.001029505 | L25: =L21 -> 0.0011789887 | M25: =M21 -> 0.0011789887 | N25: =N21 -> 0.0011789887 | O25: =O21 -> 0.0011789887 | P25: =P21 -> 2059273.2 | ... AB25: =AB21 -> 0.0011942882
C27: Cost per child covered
E28: =HYPERLINK(buildUrl(CELL("address", Inputs!E16)), Inputs!E16) -> Cost per seasonal malaria chemoprevention (SMC) cycle administered | F28: =Inputs!F16 -> $ | G28: =Inputs!G16 -> input | H28: =Inputs!H16 -> - | I28: =Inputs!I16 -> 1.641799 | J28: =Inputs!J16 -> 1.943721 | K28: =Inputs!K16 -> 2.525697 | L28: =Inputs!L16 -> 1.943721 | M28: =Inputs!M16 -> 1.943721 | ... AB28: =Inputs!AB16 -> 1.9852456
E29: =HYPERLINK(buildUrl(CELL("address", Inputs!E17)), Inputs!E17) -> Number of SMC cycles per year | F29: =Inputs!F17 -> # | G29: =Inputs!G17 -> input | H29: =Inputs!H17 -> - | I29: =Inputs!I17 -> 4.312275 | J29: =Inputs!J17 -> 4 | K29: =Inputs!K17 -> 5 | L29: =Inputs!L17 -> 4 | M29: =Inputs!M17 -> 4 | ... AB29: =Inputs!AB17 -> 5
E30: Total cost per child treated with all cycles of SMC in a year | F30: $ | G30: calc | H30: - | I30: =I28*I29 -> 7.0798888 | J30: =J28*J29 -> 7.774884 | K30: =K28*K29 -> 12.628485 | L30: =L28*L29 -> 7.774884 | M30: =M28*M29 -> 7.774884 | N30: =N28*N29 -> 7.774884 | O30: =O28*O29 -> 7.774884 | P30: =P28*P29 -> 8.2932718 | ... AB30: =AB28*AB29 -> 9.9262278
E31: Upstream costs per child treated with all cycles of SMC in a year | F31: $ | G31: calc | H31: - | I31: =(I24/I16)*I30 -> 6.3328458 | J31: =(J24/J16)*J30 -> 7.0148815 | K31: =(K24/K16)*K30 -> 11.44973 | L31: =(L24/L16)*L30 -> 7.3151843 | M31: =(M24/M16)*M30 -> 7.3151843 | N31: =(N24/N16)*N30 -> 7.3151843 | O31: =(O24/O16)*O30 -> 7.3151843 | P31: =(P24/P16)*P30 -> 7.4181972 | ... AB31: =(AB24/AB16)*AB30 -> 8.8672256
A33: Outputs
C35: Total children covered
E36: Total people under age 5 receiving a year of SMC | F36: # | G36: calc | H36: - | I36: =I19/I31 -> 0.0015790689 | J36: =J19/J31 -> 0.0014255408 | K36: =K19/K31 -> 0.00087338307 | L36: =L19/L31 -> 0.0013670195 | M36: =M19/M31 -> 0.0013670195 | N36: =N19/N31 -> 0.0013670195 | O36: =O19/O31 -> 0.0013670195 | P36: =P19/P31 -> 2353254.6 | ... AB36: =AB19/AB31 -> 0.0011277485
A38: Outcomes
C40: Mortality reduction among people under age 5 (treated population)
E41: =HYPERLINK(buildUrl(CELL("address", Inputs!E45)), Inputs!E45) -> Reduction in malaria incidence for children under age 5 targeted for SMC found in GiveWell's adjusted version of the Meremikwu et al. 2012 meta-analysis | F41: =Inputs!F45 -> % | G41: =Inputs!G45 -> input | H41: =Inputs!H45 -> 0.75 | I41: =Inputs!I45 -> - | J41: =Inputs!J45 -> - | K41: =Inputs!K45 -> - | L41: =Inputs!L45 -> - | M41: =Inputs!M45 -> - | ... AB41: =Inputs!AB45 -> -
E42: =HYPERLINK(buildUrl(CELL("address", Inputs!E46)), Inputs!E46) -> Estimated proportion of children targeted for SMC in trials that received SMC | F42: =Inputs!F46 -> % | G42: =Inputs!G46 -> input | H42: =Inputs!H46 -> 0.8977 | I42: - | J42: - | K42: - | L42: - | M42: - | N42: - | O42: - | P42: - | Q42: - | R42: - | S42: - | T42: - | U42: - | V42: - | W42: - | X42: - | Y42: - | Z42: - | AA42: - | AB42: -
E43: Implied reduction in malaria incidence among children under age 5 receiving SMC | F43: % | G43: calc | H43: =H41/H42 -> 0.83546842 | I43: - | J43: - | K43: - | L43: - | M43: - | N43: - | O43: - | P43: - | Q43: - | R43: - | S43: - | T43: - | U43: - | V43: - | W43: - | X43: - | Y43: - | Z43: - | AA43: - | AB43: -
E44: =HYPERLINK(buildUrl(CELL("address", Inputs!E47)), Inputs!E47) -> Internal validity adjustment | F44: =Inputs!F47 -> % | G44: =Inputs!G47 -> input | H44: =Inputs!H47 -> -0.05 | I44: =Inputs!I47 -> - | J44: =Inputs!J47 -> - | K44: =Inputs!K47 -> - | L44: =Inputs!L47 -> - | M44: =Inputs!M47 -> - | ... AB44: =Inputs!AB47 -> -
E45: =HYPERLINK(buildUrl(CELL("address", Inputs!E48)), Inputs!E48) -> External validity adjustment | F45: =Inputs!F48 -> % | G45: =Inputs!G48 -> input | H45: =Inputs!H48 -> 0 | I45: =Inputs!I48 -> - | J45: =Inputs!J48 -> - | K45: =Inputs!K48 -> - | L45: =Inputs!L48 -> - | M45: =Inputs!M48 -> - | ... AB45: =Inputs!AB48 -> -
E46: =HYPERLINK(buildUrl(CELL("address", Inputs!E49)), Inputs!E49) -> Adjustment for lower effectiveness outside the Sahel region of Africa | F46: =Inputs!F49 -> % | G46: =Inputs!G49 -> input | H46: =Inputs!H49 -> - | I46: =Inputs!I49 -> 0 | J46: =Inputs!J49 -> 0 | K46: =Inputs!K49 -> 0 | L46: =Inputs!L49 -> -0.25 | M46: =Inputs!M49 -> -0.25 | ... AB46: =Inputs!AB49 -> -0.25
E47: Expected reduction in malaria incidence among children under age 5 receiving SMC | F47: % | G47: calc | H47: - | I47: =$H43*(1+$H44)*(1+$H45)*(1+I46) -> 0.793695 | J47: =$H43*(1+$H44)*(1+$H45)*(1+J46) -> 0.793695 | K47: =$H43*(1+$H44)*(1+$H45)*(1+K46) -> 0.793695 | L47: =$H43*(1+$H44)*(1+$H45)*(1+L46) -> 0.59527125 | M47: =$H43*(1+$H44)*(1+$H45)*(1+M46) -> 0.59527125 | N47: =$H43*(1+$H44)*(1+$H45)*(1+N46) -> 0.59527125 | O47: =$H43*(1+$H44)*(1+$H45)*(1+O46) -> 0.59527125 | P47: =$H43*(1+$H44)*(1+$H45)*(1+P46) -> 0.59527125 | ... AB47: =$H43*(1+$H44)*(1+$H45)*(1+AB46) -> 0.59527125
E48: =HYPERLINK(buildUrl(CELL("address", Inputs!E50)), Inputs!E50) -> Ratio of the reduction in malaria mortality to the reduction in malaria incidence | F48: =Inputs!F50 -> % | G48: =Inputs!G50 -> input | H48: =Inputs!H50 -> 1 | I48: =Inputs!I50 -> - | J48: =Inputs!J50 -> - | K48: =Inputs!K50 -> - | L48: =Inputs!L50 -> - | M48: =Inputs!M50 -> - | ... AB48: =Inputs!AB50 -> -
E49: Expected reduction in malaria mortality among children under age 5 receiving SMC | F49: % | G49: calc | H49: - | I49: =I47*$H48 -> 0.793695 | J49: =J47*$H48 -> 0.793695 | K49: =K47*$H48 -> 0.793695 | L49: =L47*$H48 -> 0.59527125 | M49: =M47*$H48 -> 0.59527125 | N49: =N47*$H48 -> 0.59527125 | O49: =O47*$H48 -> 0.59527125 | P49: =P47*$H48 -> 0.59527125 | ... AB49: =AB47*$H48 -> 0.59527125
E50: =HYPERLINK(buildUrl(CELL("address", 'Counterfactual malaria'!E30)), 'Counterfactual malaria'!E30) -> Annual malaria mortality rate among 3-59-month-olds | F50: ='Counterfactual malaria'!F30 -> % | G50: supp | H50: ='Counterfactual malaria'!H30 -> - | I50: ='Counterfactual malaria'!I30 -> 0.0031550343 | J50: ='Counterfactual malaria'!J30 -> 0.0027922656 | K50: ='Counterfactual malaria'!K30 -> 0.0027416285 | L50: ='Counterfactual malaria'!L30 -> 0.0034548952 | M50: ='Counterfactual malaria'!M30 -> 0.0037111602 | N50: ='Counterfactual malaria'!N30 -> 0.004094441 | O50: ='Counterfactual malaria'!O30 -> 0.0044204672 | ... AB50: ='Counterfactual malaria'!AB30 -> 0.0022459667
...

Sheet Counterfactual malaria
I1: Malaria Consortium | S1: Malaria Consortium
I2: Burkina Faso | J2: Chad | K2: Côte d'Ivoire | L2: DRC | M2: DRC | N2: DRC | O2: DRC | P2: Mozambique | Q2: Nigeria | R2: Nigeria | S2: Nigeria | T2: Nigeria | U2: Nigeria | V2: Nigeria | W2: Nigeria | X2: Nigeria | Y2: Nigeria | Z2: South Sudan | AA2: Togo | AB2: Uganda
A3: Supplemental calculations for counterfactual malaria mortality and incidence rates | H3: Overall | L3: Haut-Katanga | M3: Haut-Lomami | N3: Lualaba | O3: Tanganyika | P3: Nampula | Q3: Bauchi | R3: Borno | S3: FCT (Abuja) | T3: Kebbi | U3: Kogi | V3: Nasarawa | W3: Oyo | X3: Plateau | Y3: Sokoto | Z3: Northern Bahr El Ghazal | AB3: Karamoja
E4: Final cost-effectiveness estimate (pulled from "Main calcs" sheet for visibility) | F4: ='Main CEA'!F193 -> xcash | G4: main | H4: ='Main CEA'!H193 -> - | I4: ='Main CEA'!I193 -> 13.310868 | J4: ='Main CEA'!J193 -> 14.65303 | K4: ='Main CEA'!K193 -> 8.5184856 | L4: ='Main CEA'!L193 -> 10.227025 | M4: ='Main CEA'!M193 -> 11.22453 | N4: ='Main CEA'!N193 -> 12.200271 | O4: ='Main CEA'!O193 -> 12.821222 | ... AB4: ='Main CEA'!AB193 -> 6.7780673
A5: Malaria mortality among the SMC-eligible population
C7: Malaria mortalities per year among people under age 5
E8: =HYPERLINK(buildUrl(CELL("address", Inputs!E22)), Inputs!E22) -> Malaria mortalities per year among people under age 5 | F8: =Inputs!F22 -> # | G8: =Inputs!G22 -> input | H8: =Inputs!H22 -> - | I8: =Inputs!I22 -> 6910 | J8: =Inputs!J22 -> 582 | K8: =Inputs!K22 -> 2780 | L8: =Inputs!L22 -> 2766 | M8: =Inputs!M22 -> 2408 | ... AB8: =Inputs!AB22 -> 4689
E9: =HYPERLINK(buildUrl(CELL("address", Inputs!E23)), Inputs!E23) -> Early neonatal malaria mortalities per year (babies under 7 days old) | F9: =Inputs!F23 -> # | G9: =Inputs!G23 -> input | H9: =Inputs!H23 -> - | I9: =Inputs!I23 -> 0 | J9: =Inputs!J23 -> 0 | K9: =Inputs!K23 -> 0 | L9: =Inputs!L23 -> 0 | M9: =Inputs!M23 -> 0 | ... AB9: =Inputs!AB23 -> 0
E10: =HYPERLINK(buildUrl(CELL("address", Inputs!E24)), Inputs!E24) -> Late neonatal malaria mortalities per year (babies between 7 and 27 days old) | F10: =Inputs!F24 -> # | G10: =Inputs!G24 -> input | H10: =Inputs!H24 -> - | I10: =Inputs!I24 -> 315 | J10: =Inputs!J24 -> 24 | K10: =Inputs!K24 -> 135 | L10: =Inputs!L24 -> 165 | M10: =Inputs!M24 -> 143 | ... AB10: =Inputs!AB24 -> 281
E11: =HYPERLINK(buildUrl(CELL("address", Inputs!E25)), Inputs!E25) -> Post-neonatal malaria mortalities per year (babies between 28 and 364 days old) | F11: =Inputs!F25 -> # | G11: =Inputs!G25 -> input | H11: =Inputs!H25 -> - | I11: =Inputs!I25 -> 2269 | J11: =Inputs!J25 -> 171 | K11: =Inputs!K25 -> 1048 | L11: =Inputs!L25 -> 1131 | M11: =Inputs!M25 -> 985 | ... AB11: =Inputs!AB25 -> 2056
C13: Estimated malaria mortalities per year among the SMC-eligible population
E14: =HYPERLINK(buildUrl(CELL("address", Inputs!E26)), Inputs!E26) -> Number of post-neonatal months of life in which children are under 1 year old | F14: =Inputs!F26 -> # | G14: =Inputs!G26 -> input | H14: =Inputs!H26 -> 11 | I14: =Inputs!I26 -> - | J14: =Inputs!J26 -> - | K14: =Inputs!K26 -> - | L14: =Inputs!L26 -> - | M14: =Inputs!M26 -> - | ... AB14: =Inputs!AB26 -> -
E15: =HYPERLINK(buildUrl(CELL("address", Inputs!E27)), Inputs!E27) -> Number of post-neonatal months of life in which children are under 3 months old | F15: =Inputs!F27 -> # | G15: =Inputs!G27 -> input | H15: =Inputs!H27 -> 2 | I15: =Inputs!I27 -> - | J15: =Inputs!J27 -> - | K15: =Inputs!K27 -> - | L15: =Inputs!L27 -> - | M15: =Inputs!M27 -> - | ... AB15: =Inputs!AB27 -> -
E16: Proportion of post-neonatal malaria mortalities that are among 1-2-month-olds | F16: % | G16: calc | H16: =H15/H14 -> 0.18181818 | I16: - | J16: - | K16: - | L16: - | M16: - | N16: - | O16: - | P16: - | Q16: - | R16: - | S16: - | T16: - | U16: - | V16: - | W16: - | X16: - | Y16: - | Z16: - | AA16: - | AB16: -
E17: Estimated malaria mortalities per year among 1-2-month-olds | F17: # | G17: calc | H17: - | I17: =I11*$H16 -> 412.54545 | J17: =J11*$H16 -> 31.090909 | K17: =K11*$H16 -> 190.54545 | L17: =L11*$H16 -> 205.63636 | M17: =M11*$H16 -> 179.09091 | N17: =N11*$H16 -> 130.36364 | O17: =O11*$H16 -> 186.54545 | P17: =P11*$H16 -> 316.54545 | ... AB17: =AB11*$H16 -> 373.81818
E18: Total malaria mortalities per year among 3-59-month-olds | F18: # | G18: calc | H18: - | I18: =I8-SUM(I9:I10,I17) -> 6182.4545 | J18: =J8-SUM(J9:J10,J17) -> 526.90909 | K18: =K8-SUM(K9:K10,K17) -> 2454.4545 | L18: =L8-SUM(L9:L10,L17) -> 2395.3636 | M18: =M8-SUM(M9:M10,M17) -> 2085.9091 | N18: =N8-SUM(N9:N10,N17) -> 1518.6364 | O18: =O8-SUM(O9:O10,O17) -> 2172.4545 | P18: =P8-SUM(P9:P10,P17) -> 3245.4545 | ... AB18: =AB8-SUM(AB9:AB10,AB17) -> 4034.1818
E19: Proportion of malaria mortalities among people under age 5 that occur among 3-59-month-olds | F19: % | G19: calc | H19: - | I19: =I18/I8 -> 0.89471122 | J19: =J18/J8 -> 0.90534208 | K19: =K18/K8 -> 0.88289732 | L19: =L18/L8 -> 0.86600276 | M19: =M18/M8 -> 0.86624132 | N19: =N18/N8 -> 0.86630711 | O19: =O18/O8 -> 0.86586471 | P19: =P18/P8 -> 0.87102913 | ... AB19: =AB18/AB8 -> 0.86035014
C21: Annual malaria mortality rate among the SMC-eligible population
E22: =HYPERLINK(buildUrl(CELL("address", Inputs!E30)), Inputs!E30) -> Annual malaria mortality rate among people under age 5 | F22: =Inputs!F30 -> per 100k | G22: =Inputs!G30 -> input | H22: =Inputs!H30 -> - | I22: =Inputs!I30 -> 335 | J22: =Inputs!J30 -> 293 | K22: =Inputs!K30 -> 295 | L22: =Inputs!L30 -> 379 | M22: =Inputs!M30 -> 407 | ... AB22: =Inputs!AB30 -> 248
E23: Implied population of people under age 5 | F23: # | G23: calc | H23: - | I23: =I8/I22*100000 -> 2062686.6 | J23: =J8/J22*100000 -> 198634.81 | K23: =K8/K22*100000 -> 942372.88 | L23: =L8/L22*100000 -> 729815.3 | M23: =M8/M22*100000 -> 591646.19 | N23: =N8/N22*100000 -> 390423.16 | O23: =O8/O22*100000 -> 517319.59 | P23: =P8/P22*100000 -> 1061538.5 | ... AB23: =AB8/AB22*100000 -> 1890725.8
E24: =HYPERLINK(buildUrl(CELL("address", Inputs!E31)), Inputs!E31) -> Total number of months of life in which children are under 5 years old | F24: =Inputs!F31 -> # | G24: =Inputs!G31 -> input | H24: =Inputs!H31 -> 60 | I24: =Inputs!I31 -> - | J24: =Inputs!J31 -> - | K24: =Inputs!K31 -> - | L24: =Inputs!L31 -> - | M24: =Inputs!M31 -> - | ... AB24: =Inputs!AB31 -> -
E25: =HYPERLINK(buildUrl(CELL("address", Inputs!E32)), Inputs!E32) -> Number of months of life in which children are under 3 months old | F25: =Inputs!F32 -> # | G25: =Inputs!G32 -> input | H25: =Inputs!H32 -> 3 | I25: =Inputs!I32 -> - | J25: =Inputs!J32 -> - | K25: =Inputs!K32 -> - | L25: =Inputs!L32 -> - | M25: =Inputs!M32 -> - | ... AB25: =Inputs!AB32 -> -
E26: Proportion of people under age 5 who are 3-59-month-olds | F26: % | G26: calc | H26: =(H24-H25)/H24 -> 0.95 | I26: - | J26: - | K26: - | L26: - | M26: - | N26: - | O26: - | P26: - | Q26: - | R26: - | S26: - | T26: - | U26: - | V26: - | W26: - | X26: - | Y26: - | Z26: - | AA26: - | AB26: -
E27: Estimated population of 3-59-month olds | F27: # | G27: calc | H27: - | I27: =I23*$H26 -> 1959552.2 | J27: =J23*$H26 -> 188703.07 | K27: =K23*$H26 -> 895254.24 | L27: =L23*$H26 -> 693324.54 | M27: =M23*$H26 -> 562063.88 | N27: =N23*$H26 -> 370902 | O27: =O23*$H26 -> 491453.61 | P27: =P23*$H26 -> 1008461.5 | ... AB27: =AB23*$H26 -> 1796189.5
E28: Unadjusted annual malaria mortality rate among 3-59-month-olds | F28: % | G28: calc | H28: - | I28: =I18/I27 -> 0.0031550343 | J28: =J18/J27 -> 0.0027922656 | K28: =K18/K27 -> 0.0027416285 | L28: =L18/L27 -> 0.0034548952 | M28: =M18/M27 -> 0.0037111602 | N28: =N18/N27 -> 0.004094441 | O28: =O18/O27 -> 0.0044204672 | P28: =P18/P27 -> 0.0032182234 | ... AB28: =AB18/AB27 -> 0.0022459667
E29: =HYPERLINK(buildUrl(CELL("address", Inputs!E33)), Inputs!E33) -> Adjustment for malaria averted by ITN distributions not accounted for in GBD 2019 | F29: =Inputs!F33 -> % | G29: =Inputs!G33 -> input | H29: =Inputs!H33 -> - | I29: =Inputs!I33 -> 0 | J29: =Inputs!J33 -> 0 | K29: =Inputs!K33 -> 0 | L29: =Inputs!L33 -> 0 | M29: =Inputs!M33 -> 0 | ... AB29: =Inputs!AB33 -> 0
E30: Annual malaria mortality rate among 3-59-month-olds | F30: % | G30: calc | H30: - | I30: =I28*(1+I29) -> 0.0031550343 | J30: =J28*(1+J29) -> 0.0027922656 | K30: =K28*(1+K29) -> 0.0027416285 | L30: =L28*(1+L29) -> 0.0034548952 | M30: =M28*(1+M29) -> 0.0037111602 | N30: =N28*(1+N29) -> 0.004094441 | O30: =O28*(1+O29) -> 0.0044204672 | P30: =P28*(1+P29) -> 0.0032182234 | ... AB30: =AB28*(1+AB29) -> 0.0022459667
C32: Proportion of malaria mortalities that are among the SMC-eligible population
E33: =HYPERLINK(buildUrl(CELL("address", Inputs!E36)), Inputs!E36) -> Total malaria mortalities per year | F33: =Inputs!F36 -> # | G33: =Inputs!G36 -> input | H33: =Inputs!H36 -> - | I33: =Inputs!I36 -> 11943 | J33: =Inputs!J36 -> 926 | K33: =Inputs!K36 -> 5829 | L33: =Inputs!L36 -> 3607 | M33: =Inputs!M36 -> 3140 | ... AB33: =Inputs!AB36 -> 6280
E34: Malaria mortalities per year among people age 5 and older | F34: # | G34: calc | H34: - | I34: =I33-I8 -> 5033 | J34: =J33-J8 -> 344 | K34: =K33-K8 -> 3049 | L34: =L33-L8 -> 841 | M34: =M33-M8 -> 732 | N34: =N33-N8 -> 533 | O34: =O33-O8 -> 763 | P34: =P33-P8 -> 5718 | ... AB34: =AB33-AB8 -> 1591
E35: Malaria mortalities among people age 5 and older per malaria mortality among 3-59-month-olds | F35: # | G35: calc | H35: - | I35: =I34/I18 -> 0.81407796 | J35: =J34/J18 -> 0.65286404 | K35: =K34/K18 -> 1.2422312 | L35: =L34/L18 -> 0.35109492 | M35: =M34/M18 -> 0.35092613 | N35: =N34/N18 -> 0.35097276 | O35: =O34/O18 -> 0.35121563 | P35: =P34/P18 -> 1.7618487 | ... AB35: =AB34/AB18 -> 0.39437985
A37: Malaria incidence among the SMC-eligible population
C39: Malaria incidence among people under age 15
E40: =HYPERLINK(buildUrl(CELL("address", Inputs!E39)), Inputs!E39) -> Malaria incidence among people under 5 | F40: =Inputs!F39 -> per 100k | G40: =Inputs!G39 -> input | H40: =Inputs!H39 -> - | I40: =Inputs!I39 -> 72800 | J40: =Inputs!J39 -> 47873 | K40: =Inputs!K39 -> 78599 | L40: =Inputs!L39 -> 76062 | M40: =Inputs!M39 -> 91107 | ... AB40: =Inputs!AB39 -> 90318
E41: =HYPERLINK(buildUrl(CELL("address", Inputs!E40)), Inputs!E40) -> Malaria incidence among people age 5 to 14 | F41: =Inputs!F40 -> per 100k | G41: =Inputs!G40 -> input | H41: =Inputs!H40 -> - | I41: =Inputs!I40 -> 30179 | J41: =Inputs!J40 -> 21805 | K41: =Inputs!K40 -> 32926 | L41: =Inputs!L40 -> 31197 | M41: =Inputs!M40 -> 37367 | ... AB41: =Inputs!AB40 -> 38439
E42: =HYPERLINK(buildUrl(CELL("address", Inputs!E33)), Inputs!E33) -> Adjustment for malaria averted by ITN distributions not accounted for in GBD 2019 | F42: =Inputs!F33 -> % | G42: =Inputs!G33 -> input | H42: =Inputs!H33 -> - | I42: =Inputs!I33 -> 0 | J42: =Inputs!J33 -> 0 | K42: =Inputs!K33 -> 0 | L42: =Inputs!L33 -> 0 | M42: =Inputs!M33 -> 0 | ... AB42: =Inputs!AB33 -> 0
E43: Adjusted malaria incidence among people under 5 | F43: % | G43: calc | H43: - | I43: =(I40/100000)*(1+I42) -> 0.728 | J43: =(J40/100000)*(1+J42) -> 0.47873 | K43: =(K40/100000)*(1+K42) -> 0.78599 | L43: =(L40/100000)*(1+L42) -> 0.76062 | M43: =(M40/100000)*(1+M42) -> 0.91107 | N43: =(N40/100000)*(1+N42) -> 0.96207 | O43: =(O40/100000)*(1+O42) -> 0.93495 | P43: =(P40/100000)*(1+P42) -> 0.8227 | ... AB43: =(AB40/100000)*(1+AB42) -> 0.90318
E44: Adjusted malaria incidence among people age 5 to 14 | F44: % | G44: calc | H44: - | I44: =(I41/100000)*(1+I42) -> 0.30179 | J44: =(J41/100000)*(1+J42) -> 0.21805 | K44: =(K41/100000)*(1+K42) -> 0.32926 | L44: =(L41/100000)*(1+L42) -> 0.31197 | M44: =(M41/100000)*(1+M42) -> 0.37367 | N44: =(N41/100000)*(1+N42) -> 0.39459 | O44: =(O41/100000)*(1+O42) -> 0.38347 | P44: =(P41/100000)*(1+P42) -> 0.3458 | ... AB44: =(AB41/100000)*(1+AB42) -> 0.38439

Sheet LeverageFunging
I1: Malaria Consortium | S1: Malaria Consortium
I2: Burkina Faso | J2: Chad | K2: Côte d'Ivoire | L2: DRC | M2: DRC | N2: DRC | O2: DRC | P2: Mozambique | Q2: Nigeria | R2: Nigeria | S2: Nigeria | T2: Nigeria | U2: Nigeria | V2: Nigeria | W2: Nigeria | X2: Nigeria | Y2: Nigeria | Z2: South Sudan | AA2: Togo | AB2: Uganda
A3: Supplemental calculations for the leverage/funging adjustment | F3: unit | G3: type | H3: Overall | L3: Haut-Katanga | M3: Haut-Lomami | N3: Lualaba | O3: Tanganyika | P3: Nampula | Q3: Bauchi | R3: Borno | S3: FCT (Abuja) | T3: Kebbi | U3: Kogi | V3: Nasarawa | W3: Oyo | X3: Plateau | Y3: Sokoto | Z3: Northern Bahr El Ghazal | AB3: Karamoja
E4: Final cost-effectiveness estimate (pulled from "Main calcs" sheet for visibility) | F4: ='Main CEA'!F193 -> xcash | G4: main | H4: ='Main CEA'!H193 -> - | I4: ='Main CEA'!I193 -> 13.310868 | J4: ='Main CEA'!J193 -> 14.65303 | K4: ='Main CEA'!K193 -> 8.5184856 | L4: ='Main CEA'!L193 -> 10.227025 | M4: ='Main CEA'!M193 -> 11.22453 | N4: ='Main CEA'!N193 -> 12.200271 | O4: ='Main CEA'!O193 -> 12.821222 | ... AB4: ='Main CEA'!AB193 -> 6.7780673
A5: Costs
C7: GiveWell costs
E8: =HYPERLINK(buildUrl(CELL("address", Inputs!E8)), Inputs!E8) -> Grant size | F8: =Inputs!F8 -> $ | G8: =Inputs!G8 -> input | H8: =Inputs!H8 -> - | I8: =Inputs!I8 -> 0.01 | J8: =Inputs!J8 -> 0.01 | K8: =Inputs!K8 -> 0.01 | L8: =Inputs!L8 -> 0.01 | M8: =Inputs!M8 -> 0.01 | ... AB8: =Inputs!AB8 -> 0.01
C10: Cost breakdown
E11: =HYPERLINK(buildUrl(CELL("address", Inputs!E11)), Inputs!E11) -> Percentage of total costs covered by the grantee | F11: =Inputs!F11 -> % | G11: =Inputs!G11 -> input | H11: =Inputs!H11 -> - | I11: =Inputs!I11 -> 0.8944838 | J11: =Inputs!J11 -> 0.90224903 | K11: =Inputs!K11 -> 0.906659 | L11: =Inputs!L11 -> 0.50149962 | M11: =Inputs!M11 -> 0.50149962 | ... AB11: =Inputs!AB11 -> 0.89331272
E12: =HYPERLINK(buildUrl(CELL("address", Inputs!E12)), Inputs!E12) -> Percentage of total costs covered by other philanthropic actors | F12: =Inputs!F12 -> % | G12: =Inputs!G12 -> input | H12: =Inputs!H12 -> - | I12: =Inputs!I12 -> 0 | J12: =Inputs!J12 -> 0 | K12: =Inputs!K12 -> 0 | L12: =Inputs!L12 -> 0.43937414 | M12: =Inputs!M12 -> 0.43937414 | ... AB12: =Inputs!AB12 -> 0
E13: =HYPERLINK(buildUrl(CELL("address", Inputs!E13)), Inputs!E13) -> Percentage of total costs covered by domestic governments | F13: =Inputs!F13 -> % | G13: =Inputs!G13 -> input | H13: =Inputs!H13 -> - | I13: =Inputs!I13 -> 0.1055162 | J13: =Inputs!J13 -> 0.09775097 | K13: =Inputs!K13 -> 0.093341 | L13: =Inputs!L13 -> 0.05912624 | M13: =Inputs!M13 -> 0.05912624 | ... AB13: =Inputs!AB13 -> 0.10668728
C15: Total costs
E16: =HYPERLINK(buildUrl(CELL("address", 'Main CEA'!E16)), 'Main CEA'!E16) -> Total spending by all contributors | F16: ='Main CEA'!F16 -> $ | G16: main | H16: ='Main CEA'!H16 -> - | I16: ='Main CEA'!I16 -> 0.011179632 | J16: ='Main CEA'!J16 -> 0.011083415 | K16: ='Main CEA'!K16 -> 0.011029505 | L16: ='Main CEA'!L16 -> 0.019940195 | M16: ='Main CEA'!M16 -> 0.019940195 | N16: ='Main CEA'!N16 -> 0.019940195 | O16: ='Main CEA'!O16 -> 0.019940195 | ... AB16: ='Main CEA'!AB16 -> 0.011194288
C18: Total spending attributable to different actors
E19: =HYPERLINK(buildUrl(CELL("address", 'Main CEA'!E19)), 'Main CEA'!E19) -> Total spending contributed by grantee | F19: ='Main CEA'!F19 -> $ | G19: main | H19: ='Main CEA'!H19 -> - | I19: ='Main CEA'!I19 -> 0.01 | J19: ='Main CEA'!J19 -> 0.01 | K19: ='Main CEA'!K19 -> 0.01 | L19: ='Main CEA'!L19 -> 0.01 | M19: ='Main CEA'!M19 -> 0.01 | N19: ='Main CEA'!N19 -> 0.01 | O19: ='Main CEA'!O19 -> 0.01 | ... AB19: ='Main CEA'!AB19 -> 0.01
E20: =HYPERLINK(buildUrl(CELL("address", 'Main CEA'!E20)), 'Main CEA'!E20) -> Total spending contributed by other philanthropic actors | F20: ='Main CEA'!F20 -> $ | G20: main | H20: ='Main CEA'!H20 -> - | I20: ='Main CEA'!I20 -> 0 | J20: ='Main CEA'!J20 -> 0 | K20: ='Main CEA'!K20 -> 0 | L20: ='Main CEA'!L20 -> 0.0087612059 | M20: ='Main CEA'!M20 -> 0.0087612059 | N20: ='Main CEA'!N20 -> 0.0087612059 | O20: ='Main CEA'!O20 -> 0.0087612059 | ... AB20: ='Main CEA'!AB20 -> 0
E21: =HYPERLINK(buildUrl(CELL("address", 'Main CEA'!E21)), 'Main CEA'!E21) -> Total spending contributed by domestic governments | F21: ='Main CEA'!F21 -> $ | G21: main | H21: ='Main CEA'!H21 -> - | I21: ='Main CEA'!I21 -> 0.0011796323 | J21: ='Main CEA'!J21 -> 0.0010834145 | K21: ='Main CEA'!K21 -> 0.001029505 | L21: ='Main CEA'!L21 -> 0.0011789887 | M21: ='Main CEA'!M21 -> 0.0011789887 | N21: ='Main CEA'!N21 -> 0.0011789887 | O21: ='Main CEA'!O21 -> 0.0011789887 | ... AB21: ='Main CEA'!AB21 -> 0.0011942882
C23: Upstream / downstream spending
E24: =HYPERLINK(buildUrl(CELL("address", 'Main CEA'!E24)), 'Main CEA'!E24) -> Total spending causally upstream of donations to grantee | F24: ='Main CEA'!F24 -> $ | G24: main | H24: ='Main CEA'!H24 -> - | I24: ='Main CEA'!I24 -> 0.01 | J24: ='Main CEA'!J24 -> 0.01 | K24: ='Main CEA'!K24 -> 0.01 | L24: ='Main CEA'!L24 -> 0.018761206 | M24: ='Main CEA'!M24 -> 0.018761206 | N24: ='Main CEA'!N24 -> 0.018761206 | O24: ='Main CEA'!O24 -> 0.018761206 | ... AB24: ='Main CEA'!AB24 -> 0.01
E25: =HYPERLINK(buildUrl(CELL("address", 'Main CEA'!E25)), 'Main CEA'!E25) -> Total spending causally downstream of donations to grantee | F25: ='Main CEA'!F25 -> $ | G25: main | H25: ='Main CEA'!H25 -> - | I25: ='Main CEA'!I25 -> 0.0011796323 | J25: ='Main CEA'!J25 -> 0.0010834145 | K25: ='Main CEA'!K25 -> 0.001029505 | L25: ='Main CEA'!L25 -> 0.0011789887 | M25: ='Main CEA'!M25 -> 0.0011789887 | N25: ='Main CEA'!N25 -> 0.0011789887 | O25: ='Main CEA'!O25 -> 0.0011789887 | ... AB25: ='Main CEA'!AB25 -> 0.0011942882
A27: Counterfactual funding scenarios
C29: Probability of scenarios in the absence of philanthropic funding
E30: =HYPERLINK(buildUrl(CELL("address", Inputs!E114)), Inputs!E114) -> Scenario 1: Domestic governments would replace the grantee's costs | F30: =Inputs!F114 -> % | G30: =Inputs!G114 -> input | H30: =Inputs!H114 -> - | I30: =Inputs!I114 -> 0 | J30: =Inputs!J114 -> 0 | K30: =Inputs!K114 -> 0 | L30: =Inputs!L114 -> 0 | M30: =Inputs!M114 -> 0 | ... AB30: =Inputs!AB114 -> 0
E31: =HYPERLINK(buildUrl(CELL("address", Inputs!E115)), Inputs!E115) -> Scenario 2: Global Fund and/or PMI would replace the grantee's costs | F31: =Inputs!F115 -> % | G31: =Inputs!G115 -> input | H31: =Inputs!H115 -> - | I31: =Inputs!I115 -> 0.5 | J31: =Inputs!J115 -> 0.3 | K31: =Inputs!K115 -> 0.4 | L31: =Inputs!L115 -> 0.15 | M31: =Inputs!M115 -> 0.15 | ... AB31: =Inputs!AB115 -> 0.4
E32: =HYPERLINK(buildUrl(CELL("address", Inputs!E116)), Inputs!E116) -> Scenario 3: Other actors' upstream costs would stay the same (downstream costs would shrink in proportion to the total size of the program) | F32: =Inputs!F116 -> % | G32: =Inputs!G116 -> input | H32: =Inputs!H116 -> - | I32: =Inputs!I116 -> 0 | J32: =Inputs!J116 -> 0 | K32: =Inputs!K116 -> 0 | L32: =Inputs!L116 -> 0 | M32: =Inputs!M116 -> 0 | ... AB32: =Inputs!AB116 -> 0
E33: Scenario 4: Distributions would go unfunded | F33: % | G33: calc | H33: - | I33: =1-SUM(I30:I32) -> 0.5 | J33: =1-SUM(J30:J32) -> 0.7 | K33: =1-SUM(K30:K32) -> 0.6 | L33: =1-SUM(L30:L32) -> 0.85 | M33: =1-SUM(M30:M32) -> 0.85 | N33: =1-SUM(N30:N32) -> 0.85 | O33: =1-SUM(O30:O32) -> 0.85 | P33: =1-SUM(P30:P32) -> 0.65 | ... AB33: =1-SUM(AB30:AB32) -> 0.6
C35: Proportion of the program that would still occur in each scenario
E36: =HYPERLINK(buildUrl(CELL("address", Inputs!E119)), Inputs!E119) -> Scenario 1: Domestic governments would replace the grantee's costs | F36: =Inputs!F119 -> % | G36: =Inputs!G119 -> input | H36: =Inputs!H119 -> 1 | I36: =Inputs!I119 -> - | J36: =Inputs!J119 -> - | K36: =Inputs!K119 -> - | L36: =Inputs!L119 -> - | M36: =Inputs!M119 -> - | ... AB36: =Inputs!AB119 -> -
E37: =HYPERLINK(buildUrl(CELL("address", Inputs!E120)), Inputs!E120) -> Scenario 2: Global Fund and/or PMI would replace the grantee's costs | F37: =Inputs!F120 -> % | G37: =Inputs!G120 -> input | H37: =Inputs!H120 -> 1 | I37: =Inputs!I120 -> - | J37: =Inputs!J120 -> - | K37: =Inputs!K120 -> - | L37: =Inputs!L120 -> - | M37: =Inputs!M120 -> - | ... AB37: =Inputs!AB120 -> -
E38: Scenario 3: Other actors' upstream costs would stay the same (downstream costs would shrink in proportion to the total size of the program) | F38: % | G38: calc | H38: - | I38: =I20/I24 -> 0 | J38: =J20/J24 -> 0 | K38: =K20/K24 -> 0 | L38: =L20/L24 -> 0.46698522 | M38: =M20/M24 -> 0.46698522 | N38: =N20/N24 -> 0.46698522 | O38: =O20/O24 -> 0.46698522 | P38: =P20/P24 -> 0 | ... AB38: =AB20/AB24 -> 0
E39: =HYPERLINK(buildUrl(CELL("address", Inputs!E121)), Inputs!E121) -> Scenario 4: Distributions would go unfunded | F39: =Inputs!F121 -> % | G39: =Inputs!G121 -> input | H39: =Inputs!H121 -> 0 | I39: =Inputs!I121 -> - | J39: =Inputs!J121 -> - | K39: =Inputs!K121 -> - | L39: =Inputs!L121 -> - | M39: =Inputs!M121 -> - | ... AB39: =Inputs!AB121 -> -
A41: Value of spending
C43: Cost-effectiveness of the program (before leverage and funging)
E44: =HYPERLINK(buildUrl(CELL("address", 'Main CEA'!E134)), 'Main CEA'!E134) -> Units of value generated per dollar (before final adjustments) | F44: ='Main CEA'!F134 -> UoV | G44: main | H44: ='Main CEA'!H134 -> - | I44: ='Main CEA'!I134 -> 0.067960931 | J44: ='Main CEA'!J134 -> 0.056189917 | K44: ='Main CEA'!K134 -> 0.036064272 | L44: ='Main CEA'!L134 -> 0.035188858 | M44: ='Main CEA'!M134 -> 0.038812006 | N44: ='Main CEA'!N134 -> 0.042356106 | O44: ='Main CEA'!O134 -> 0.044611531 | ... AB44: ='Main CEA'!AB134 -> 0.02596393
E45: =HYPERLINK(buildUrl(CELL("address", 'Main CEA'!D163)), 'Main CEA'!D163) -> Total supplemental grantee-level adjustment | F45: ='Main CEA'!F163 -> % | G45: main | H45: ='Main CEA'!H163 -> -0.08 | I45: ='Main CEA'!I163 -> - | J45: ='Main CEA'!J163 -> - | K45: ='Main CEA'!K163 | L45: ='Main CEA'!L163 -> - | M45: ='Main CEA'!M163 -> - | N45: ='Main CEA'!N163 -> - | O45: ='Main CEA'!O163 -> - | ... AB45: ='Main CEA'!AB163 -> -
E46: =HYPERLINK(buildUrl(CELL("address", 'Main CEA'!D179)), 'Main CEA'!D179) -> Total supplemental intervention-level adjustment | F46: ='Main CEA'!F179 -> % | G46: main | H46: ='Main CEA'!H179 -> - | I46: ='Main CEA'!I179 -> 0.191 | J46: ='Main CEA'!J179 -> 0.241 | K46: ='Main CEA'!K179 -> 0.141 | L46: ='Main CEA'!L179 -> 0.181 | M46: ='Main CEA'!M179 -> 0.181 | N46: ='Main CEA'!N179 -> 0.181 | O46: ='Main CEA'!O179 -> 0.181 | ... AB46: ='Main CEA'!AB179 -> 0.181
E47: Units of value generated per dollar donated to grantee (after supplemental adjustments) | F47: UoV | G47: calc | H47: - | I47: =I44*(1+$H45)*(1+I46) -> 0.074466151 | J47: =J44*(1+$H45)*(1+J46) -> 0.064153152 | K47: =K44*(1+$H45)*(1+K46) -> 0.037857387 | L47: =L44*(1+$H45)*(1+L46) -> 0.038233399 | M47: =M44*(1+$H45)*(1+M46) -> 0.042170021 | N47: =N44*(1+$H45)*(1+N46) -> 0.046020756 | O47: =O44*(1+$H45)*(1+O46) -> 0.04847132 | P47: =P44*(1+$H45)*(1+P46) -> 0.037519782 | ... AB47: =AB44*(1+$H45)*(1+AB46) -> 0.028210329
C49: Lives saved by the program (before leverage and funging)
E50: =HYPERLINK(buildUrl(CELL("address", 'Main CEA'!E145)), 'Main CEA'!E145) -> Total lives saved (before final adjustments) | F50: ='Main CEA'!F145 -> # | G50: main | H50: ='Main CEA'!H145 -> - | I50: ='Main CEA'!I145 -> 4.6194604e-06 | J50: ='Main CEA'!J145 -> 4.1240105e-06 | K50: ='Main CEA'!K145 -> 2.3892264e-06 | L50: ='Main CEA'!L145 -> 2.3609947e-06 | M50: ='Main CEA'!M145 -> 2.5360655e-06 | N50: ='Main CEA'!N145 -> 2.7980017e-06 | O50: ='Main CEA'!O145 -> 3.0208907e-06 | ... AB50: ='Main CEA'!AB145 -> 1.4294503e-06
E51: =HYPERLINK(buildUrl(CELL("address", 'Main CEA'!D163)), 'Main CEA'!D163) -> Total supplemental grantee-level adjustment | F51: ='Main CEA'!F163 -> % | G51: main | H51: ='Main CEA'!H163 -> -0.08 | I51: ='Main CEA'!I163 -> - | J51: ='Main CEA'!J163 -> - | K51: ='Main CEA'!K163 | L51: ='Main CEA'!L163 -> - | M51: ='Main CEA'!M163 -> - | N51: ='Main CEA'!N163 -> - | O51: ='Main CEA'!O163 -> - | ... AB51: ='Main CEA'!AB163 -> -
...

Sheet Inputs
I1: Malaria Consortium | S1: Malaria Consortium
I2: Burkina Faso | J2: Chad | K2: Côte d'Ivoire | L2: DRC | M2: DRC | N2: DRC | O2: DRC | P2: Mozambique | Q2: Nigeria | R2: Nigeria | S2: Nigeria | T2: Nigeria | U2: Nigeria | V2: Nigeria | W2: Nigeria | X2: Nigeria | Y2: Nigeria | Z2: South Sudan | AA2: Togo | AB2: Uganda
A3: Inputs | F3: unit | G3: type | H3: Overall | L3: Haut-Katanga | M3: Haut-Lomami | N3: Lualaba | O3: Tanganyika | P3: Nampula | Q3: Bauchi | R3: Borno | S3: FCT (Abuja) | T3: Kebbi | U3: Kogi | V3: Nasarawa | W3: Oyo | X3: Plateau | Y3: Sokoto | Z3: Northern Bahr El Ghazal | AB3: Karamoja | AD3: Source | AE3: GW analysis and discussion
E4: Final cost-effectiveness estimate (pulled from "Main calcs" sheet for visibility) | F4: ='Main CEA'!F193 -> xcash | G4: main | H4: ='Main CEA'!H193 -> - | I4: ='Main CEA'!I193 -> 13.310868 | J4: ='Main CEA'!J193 -> 14.65303 | K4: ='Main CEA'!K193 -> 8.5184856 | L4: ='Main CEA'!L193 -> 10.227025 | M4: ='Main CEA'!M193 -> 11.22453 | N4: ='Main CEA'!N193 -> 12.200271 | O4: ='Main CEA'!O193 -> 12.821222 | ... AB4: ='Main CEA'!AB193 -> 6.7780673
A5: Costs
C7: GiveWell costs
E8: Grant size | F8: $ | G8: input | H8: - | I8: 0.01 | J8: 0.01 | K8: 0.01 | L8: 0.01 | M8: 0.01 | N8: 0.01 | O8: 0.01 | P8: 17456907 | Q8: 0.01 | R8: 0.01 | S8: 0.01 | T8: 0.01 | U8: 0.01 | V8: 0.01 | W8: 0.01 | X8: 0.01 | Y8: 0.01 | Z8: 0.01 | AA8: 0.01 | AB8: 0.01 | AD8: Arbitrary value
C10: Cost breakdown
E11: Percentage of total costs covered by the grantee | F11: % | G11: input | H11: - | I11: 0.8944838 | J11: 0.90224903 | K11: 0.906659 | L11: =$AA11 -> 0.50149962 | M11: =$AA11 -> 0.50149962 | N11: =$AA11 -> 0.50149962 | O11: =$AA11 -> 0.50149962 | P11: 0.8944838 | Q11: 0.81586554 | R11: 0.8944838 | S11: 0.8944838 | T11: 0.8944838 | U11: 0.8944838 | V11: 0.8944838 | W11: 0.8944838 | X11: 0.8944838 | Y11: 0.8944838 | Z11: 0.91399685 | AA11: 0.50149962 | AB11: 0.89331272 | AD11: GW analysis | AE11: GW's analysis of Malaria Consortium's cost per SMC cycle administration
E12: Percentage of total costs covered by other philanthropic actors | F12: % | G12: input | H12: - | I12: 0 | J12: 0 | K12: 0 | L12: =$AA12 -> 0.43937414 | M12: =$AA12 -> 0.43937414 | N12: =$AA12 -> 0.43937414 | O12: =$AA12 -> 0.43937414 | P12: 0 | Q12: 0.08789232 | R12: 0 | S12: 0 | T12: 0 | U12: 0 | V12: 0 | W12: 0 | X12: 0 | Y12: 0 | Z12: 0 | AA12: 0.43937414 | AB12: 0 | AD12: GW analysis | AE12: GW's analysis of Malaria Consortium's cost per SMC cycle administration
E13: Percentage of total costs covered by domestic governments | F13: % | G13: input | H13: - | I13: 0.1055162 | J13: 0.09775097 | K13: 0.093341 | L13: =$AA13 -> 0.05912624 | M13: =$AA13 -> 0.05912624 | N13: =$AA13 -> 0.05912624 | O13: =$AA13 -> 0.05912624 | P13: 0.1055162 | Q13: 0.09624214 | R13: 0.1055162 | S13: 0.1055162 | T13: 0.1055162 | U13: 0.1055162 | V13: 0.1055162 | W13: 0.1055162 | X13: 0.1055162 | Y13: 0.1055162 | Z13: 0.08600315 | AA13: 0.05912624 | AB13: 0.10668728 | AD13: GW analysis | AE13: GW's analysis of Malaria Consortium's cost per SMC cycle administration
C15: Cost per child covered
E16: Cost per seasonal malaria chemoprevention (SMC) cycle administered | F16: $ | G16: input | H16: - | I16: 1.641799 | J16: =2.15969*0.9 -> 1.943721 | K16: =2.80633*0.9 -> 2.525697 | L16: =max($I$16:$J$16,$Q$16:$Y$16,$AA$16) -> 1.943721 | M16: =max($I$16:$J$16,$Q$16:$Y$16,$AA$16) -> 1.943721 | N16: =max($I$16:$J$16,$Q$16:$Y$16,$AA$16) -> 1.943721 | O16: =max($I$16:$J$16,$Q$16:$Y$16,$AA$16) -> 1.943721 | P16: =2.3036866*0.9 -> 2.0733179 | Q16: 0.884114 | R16: 0.738607 | S16: 1.517807 | T16: 1.128167 | U16: 1.361817 | V16: 1.151538 | W16: 1.808616 | X16: 1.246252 | Y16: 0.991878 | Z16: =5.155467*0.9 -> 4.6399203 | AA16: 1.9326022 | AB16: =2.2058284*0.9 -> 1.9852456 | AD16: GW analysis | AE16: GW's analysis of Malaria Consortium's cost per SMC cycle administration
E17: Number of SMC cycles per year | F17: # | G17: input | H17: - | I17: 4.312275 | J17: 4 | K17: 5 | L17: 4 | M17: 4 | N17: 4 | O17: 4 | P17: 4 | Q17: 5 | R17: 4 | S17: 5 | T17: 4 | U17: 5 | V17: 5 | W17: 5 | X17: 5 | Y17: 4 | Z17: 5 | AA17: 4 | AB17: 5 | AD17: GW analysis | AE17: GW's analysis of Malaria Consortium's cost per SMC cycle administration
A19: Counterfactual malaria
C21: Malaria mortalities among the SMC-eligible population
E22: Malaria mortalities per year among people under age 5 | F22: # | G22: input | H22: - | I22: 6910 | J22: 582 | K22: 2780 | L22: 2766 | M22: 2408 | N22: 1753 | O22: 2509 | P22: 3726 | Q22: =IFERROR(__xludf.DUMMYFUNCTION("FILTER('GBD estimates'!$BA$4:$BA$258,'GBD estimates'!$AV$4:$AV$258=Q$3,'GBD estimates'!$AU$4:$AU$258=""Under 5"")"),6310.369098) -> 6310.3691 | R22: =IFERROR(__xludf.DUMMYFUNCTION("FILTER('GBD estimates'!$BA$4:$BA$258,'GBD estimates'!$AV$4:$AV$258=R$3,'GBD estimates'!$AU$4:$AU$258=""Under 5"")"),1946.768516) -> 1946.7685 | S22: =IFERROR(__xludf.DUMMYFUNCTION("FILTER('GBD estimates'!$BA$4:$BA$258,'GBD estimates'!$AV$4:$AV$258=S$3,'GBD estimates'!$AU$4:$AU$258=""Under 5"")"),2525.95462) -> 2525.9546 | T22: =IFERROR(__xludf.DUMMYFUNCTION("FILTER('GBD estimates'!$BA$4:$BA$258,'GBD estimates'!$AV$4:$AV$258=T$3,'GBD estimates'!$AU$4:$AU$258=""Under 5"")"),3863.160124) -> 3863.1601 | U22: =IFERROR(__xludf.DUMMYFUNCTION("FILTER('GBD estimates'!$BA$4:$BA$258,'GBD estimates'!$AV$4:$AV$258=U$3,'GBD estimates'!$AU$4:$AU$258=""Under 5"")"),1159.106488) -> 1159.1065 | V22: =IFERROR(__xludf.DUMMYFUNCTION("FILTER('GBD estimates'!$BA$4:$BA$258,'GBD estimates'!$AV$4:$AV$258=V$3,'GBD estimates'!$AU$4:$AU$258=""Under 5"")"),2235.297195) -> 2235.2972 | W22: =IFERROR(__xludf.DUMMYFUNCTION("FILTER('GBD estimates'!$BA$4:$BA$258,'GBD estimates'!$AV$4:$AV$258=W$3,'GBD estimates'!$AU$4:$AU$258=""Under 5"")"),2153.286251) -> 2153.2863 | X22: =IFERROR(__xludf.DUMMYFUNCTION("FILTER('GBD estimates'!$BA$4:$BA$258,'GBD estimates'!$AV$4:$AV$258=X$3,'GBD estimates'!$AU$4:$AU$258=""Under 5"")"),4770.056621) -> 4770.0566 | Y22: =IFERROR(__xludf.DUMMYFUNCTION("FILTER('GBD estimates'!$BA$4:$BA$258,'GBD estimates'!$AV$4:$AV$258=Y$3,'GBD estimates'!$AU$4:$AU$258=""Under 5"")"),5952.332882) -> 5952.3329 | Z22: 99 | AA22: =IFERROR(__xludf.DUMMYFUNCTION("FILTER('GBD estimates'!$S$4:$S$309,'GBD estimates'!$M$4:$M$309=AA$2,'GBD estimates'!$O$4:$O$309=""<5 years"")"),2278.182123) -> 2278.1821 | AB22: 4689 | AD22: GW analysis | AE22: GW's analysis of malaria burden in SMC-eligible countries
E23: Early neonatal malaria mortalities per year (babies under 7 days old) | F23: # | G23: input | H23: - | I23: 0 | J23: 0 | K23: 0 | L23: 0 | M23: 0 | N23: 0 | O23: 0 | P23: 0 | Q23: 0 | R23: 0 | S23: 0 | T23: 0 | U23: 0 | V23: 0 | W23: 0 | X23: 0 | Y23: 0 | Z23: 0 | AA23: =IFERROR(__xludf.DUMMYFUNCTION("FILTER('GBD estimates'!$S$4:$S$309,'GBD estimates'!$M$4:$M$309=AA$2,'GBD estimates'!$O$4:$O$309=""0-6 days"")"),0.0) -> 0 | AB23: 0 | AD23: GW analysis | AE23: GW's analysis of malaria burden in SMC-eligible countries
E24: Late neonatal malaria mortalities per year (babies between 7 and 27 days old) | F24: # | G24: input | H24: - | I24: 315 | J24: 24 | K24: 135 | L24: 165 | M24: 143 | N24: 104 | O24: 150 | P24: 164 | Q24: =IFERROR(__xludf.DUMMYFUNCTION("FILTER('GBD estimates'!$BA$4:$BA$258,'GBD estimates'!$AV$4:$AV$258=Q$3,'GBD estimates'!$AU$4:$AU$258=""7 to 27 days (late neonatal)"")"),159.3470041) -> 159.347 | R24: =IFERROR(__xludf.DUMMYFUNCTION("FILTER('GBD estimates'!$BA$4:$BA$258,'GBD estimates'!$AV$4:$AV$258=R$3,'GBD estimates'!$AU$4:$AU$258=""7 to 27 days (late neonatal)"")"),95.61855998) -> 95.61856 | S24: =IFERROR(__xludf.DUMMYFUNCTION("FILTER('GBD estimates'!$BA$4:$BA$258,'GBD estimates'!$AV$4:$AV$258=S$3,'GBD estimates'!$AU$4:$AU$258=""7 to 27 days (late neonatal)"")"),143.5773073) -> 143.57731 | T24: =IFERROR(__xludf.DUMMYFUNCTION("FILTER('GBD estimates'!$BA$4:$BA$258,'GBD estimates'!$AV$4:$AV$258=T$3,'GBD estimates'!$AU$4:$AU$258=""7 to 27 days (late neonatal)"")"),129.0610436) -> 129.06104 | U24: =IFERROR(__xludf.DUMMYFUNCTION("FILTER('GBD estimates'!$BA$4:$BA$258,'GBD estimates'!$AV$4:$AV$258=U$3,'GBD estimates'!$AU$4:$AU$258=""7 to 27 days (late neonatal)"")"),69.97392707) -> 69.973927 | V24: =IFERROR(__xludf.DUMMYFUNCTION("FILTER('GBD estimates'!$BA$4:$BA$258,'GBD estimates'!$AV$4:$AV$258=V$3,'GBD estimates'!$AU$4:$AU$258=""7 to 27 days (late neonatal)"")"),102.3979599) -> 102.39796 | W24: =IFERROR(__xludf.DUMMYFUNCTION("FILTER('GBD estimates'!$BA$4:$BA$258,'GBD estimates'!$AV$4:$AV$258=W$3,'GBD estimates'!$AU$4:$AU$258=""7 to 27 days (late neonatal)"")"),117.5898727) -> 117.58987 | X24: =IFERROR(__xludf.DUMMYFUNCTION("FILTER('GBD estimates'!$BA$4:$BA$258,'GBD estimates'!$AV$4:$AV$258=X$3,'GBD estimates'!$AU$4:$AU$258=""7 to 27 days (late neonatal)"")"),256.0142374) -> 256.01424 | Y24: =IFERROR(__xludf.DUMMYFUNCTION("FILTER('GBD estimates'!$BA$4:$BA$258,'GBD estimates'!$AV$4:$AV$258=Y$3,'GBD estimates'!$AU$4:$AU$258=""7 to 27 days (late neonatal)"")"),152.644696) -> 152.6447 | Z24: 7 | AA24: =IFERROR(__xludf.DUMMYFUNCTION("FILTER('GBD estimates'!$S$4:$S$309,'GBD estimates'!$M$4:$M$309=AA$2,'GBD estimates'!$O$4:$O$309=""7-27 days"")"),96.25746212) -> 96.257462 | AB24: 281 | AD24: GW analysis | AE24: GW's analysis of malaria burden in SMC-eligible countries
E25: Post-neonatal malaria mortalities per year (babies between 28 and 364 days old) | F25: # | G25: input | H25: - | I25: 2269 | J25: 171 | K25: 1048 | L25: 1131 | M25: 985 | N25: 717 | O25: 1026 | P25: 1741 | Q25: =IFERROR(__xludf.DUMMYFUNCTION("FILTER('GBD estimates'!$BA$4:$BA$258,'GBD estimates'!$AV$4:$AV$258=Q$3,'GBD estimates'!$AU$4:$AU$258=""28 to 364 days (post neonatal)"")"),1316.323721) -> 1316.3237 | R25: =IFERROR(__xludf.DUMMYFUNCTION("FILTER('GBD estimates'!$BA$4:$BA$258,'GBD estimates'!$AV$4:$AV$258=R$3,'GBD estimates'!$AU$4:$AU$258=""28 to 364 days (post neonatal)"")"),579.8918146) -> 579.89181 | S25: =IFERROR(__xludf.DUMMYFUNCTION("FILTER('GBD estimates'!$BA$4:$BA$258,'GBD estimates'!$AV$4:$AV$258=S$3,'GBD estimates'!$AU$4:$AU$258=""28 to 364 days (post neonatal)"")"),967.3492147) -> 967.34921 | T25: =IFERROR(__xludf.DUMMYFUNCTION("FILTER('GBD estimates'!$BA$4:$BA$258,'GBD estimates'!$AV$4:$AV$258=T$3,'GBD estimates'!$AU$4:$AU$258=""28 to 364 days (post neonatal)"")"),912.8296952) -> 912.8297 | U25: =IFERROR(__xludf.DUMMYFUNCTION("FILTER('GBD estimates'!$BA$4:$BA$258,'GBD estimates'!$AV$4:$AV$258=U$3,'GBD estimates'!$AU$4:$AU$258=""28 to 364 days (post neonatal)"")"),391.0566835) -> 391.05668 | V25: =IFERROR(__xludf.DUMMYFUNCTION("FILTER('GBD estimates'!$BA$4:$BA$258,'GBD estimates'!$AV$4:$AV$258=V$3,'GBD estimates'!$AU$4:$AU$258=""28 to 364 days (post neonatal)"")"),739.9298848) -> 739.92988 | W25: =IFERROR(__xludf.DUMMYFUNCTION("FILTER('GBD estimates'!$BA$4:$BA$258,'GBD estimates'!$AV$4:$AV$258=W$3,'GBD estimates'!$AU$4:$AU$258=""28 to 364 days (post neonatal)"")"),751.4804856) -> 751.48049 | X25: =IFERROR(__xludf.DUMMYFUNCTION("FILTER('GBD estimates'!$BA$4:$BA$258,'GBD estimates'!$AV$4:$AV$258=X$3,'GBD estimates'!$AU$4:$AU$258=""28 to 364 days (post neonatal)"")"),1789.39109) -> 1789.3911 | Y25: =IFERROR(__xludf.DUMMYFUNCTION("FILTER('GBD estimates'!$BA$4:$BA$258,'GBD estimates'!$AV$4:$AV$258=Y$3,'GBD estimates'!$AU$4:$AU$258=""28 to 364 days (post neonatal)"")"),1280.356355) -> 1280.3564 | Z25: 48 | AA25: =IFERROR(__xludf.DUMMYFUNCTION("FILTER('GBD estimates'!$S$4:$S$309,'GBD estimates'!$M$4:$M$309=AA$2,'GBD estimates'!$O$4:$O$309=""<1 year"")-FILTER('GBD estimates'!$S$4:$S$309,'GBD estimates'!$M$4:$M$309=AA$2,'GBD estimates'!$O$4:$O$309=""<28 days"")"),691.27791708) -> 691.27792 | AB25: 2056 | AD25: GW analysis | AE25: GW's analysis of malaria burden in SMC-eligible countries
E26: Number of post-neonatal months of life in which children are under 1 year old | F26: # | G26: input | H26: 11 | I26: - | J26: - | K26: - | L26: - | M26: - | N26: - | O26: - | P26: - | Q26: - | R26: - | S26: - | T26: - | U26: - | V26: - | W26: - | X26: - | Y26: - | Z26: - | AA26: - | AB26: -
E27: Number of post-neonatal months of life in which children are under 3 months old | F27: # | G27: input | H27: 2 | I27: - | J27: - | K27: - | L27: - | M27: - | N27: - | O27: - | P27: - | Q27: - | R27: - | S27: - | T27: - | U27: - | V27: - | W27: - | X27: - | Y27: - | Z27: - | AA27: - | AB27: -
C29: Malaria mortality rate among the SMC-eligible population
E30: Annual malaria mortality rate among people under age 5 | F30: per 100k | G30: input | H30: - | I30: 335 | J30: 293 | K30: 295 | L30: 379 | M30: 407 | N30: 449 | O30: 485 | P30: 351 | Q30: 554 | R30: 357 | S30: 333 | T30: 716 | U30: 373 | V30: 361 | W30: 289 | X30: 366 | Y30: 588 | Z30: 280 | AA30: =IFERROR(__xludf.DUMMYFUNCTION("FILTER('GBD estimates'!$AD$4:$AD$54,'GBD estimates'!$X$4:$X$54=AA$2)"),194.2996635) -> 194.29966 | AB30: 248 | AD30: GW analysis | AE30: GW's analysis of malaria burden in SMC-eligible countries
E31: Total number of months of life in which children are under 5 years old | F31: # | G31: input | H31: 60 | I31: - | J31: - | K31: - | L31: - | M31: - | N31: - | O31: - | P31: - | Q31: - | R31: - | S31: - | T31: - | U31: - | V31: - | W31: - | X31: - | Y31: - | Z31: - | AA31: - | AB31: -
E32: Number of months of life in which children are under 3 months old | F32: # | G32: input | H32: 3 | I32: - | J32: - | K32: - | L32: - | M32: - | N32: - | O32: - | P32: - | Q32: - | R32: - | S32: - | T32: - | U32: - | V32: - | W32: - | X32: - | Y32: - | Z32: - | AA32: - | AB32: -
E33: Adjustment for malaria averted by ITN distributions not accounted for in GBD 2019 | F33: % | G33: input | H33: - | I33: 0 | J33: 0 | K33: 0 | L33: 0 | M33: 0 | N33: 0 | O33: 0 | P33: 0 | Q33: -0.05 | R33: -0.05 | S33: -0.3512063 | T33: -0.05 | U33: -0.05 | V33: -0.05 | W33: -0.05 | X33: -0.05 | Y33: -0.05 | Z33: 0 | AA33: 0 | AB33: 0 | AD33: GW guesstimate
C35: Proportion of malaria mortalities that are among the SMC-eligible population
E36: Total malaria mortalities per year | F36: # | G36: input | H36: - | I36: 11943 | J36: 926 | K36: 5829 | L36: 3607 | M36: 3140 | N36: 2286 | O36: 3272 | P36: 9444 | Q36: =IFERROR(__xludf.DUMMYFUNCTION("FILTER('GBD estimates'!$BA$4:$BA$258,'GBD estimates'!$AV$4:$AV$258=Q$3,'GBD estimates'!$AU$4:$AU$258=""All ages"")"),8241.349008) -> 8241.349 | R36: =IFERROR(__xludf.DUMMYFUNCTION("FILTER('GBD estimates'!$BA$4:$BA$258,'GBD estimates'!$AV$4:$AV$258=R$3,'GBD estimates'!$AU$4:$AU$258=""All ages"")"),3790.634534) -> 3790.6345 | S36: =IFERROR(__xludf.DUMMYFUNCTION("FILTER('GBD estimates'!$BA$4:$BA$258,'GBD estimates'!$AV$4:$AV$258=S$3,'GBD estimates'!$AU$4:$AU$258=""All ages"")"),5429.375255) -> 5429.3753 | T36: =IFERROR(__xludf.DUMMYFUNCTION("FILTER('GBD estimates'!$BA$4:$BA$258,'GBD estimates'!$AV$4:$AV$258=T$3,'GBD estimates'!$AU$4:$AU$258=""All ages"")"),6060.643259) -> 6060.6433 | U36: =IFERROR(__xludf.DUMMYFUNCTION("FILTER('GBD estimates'!$BA$4:$BA$258,'GBD estimates'!$AV$4:$AV$258=U$3,'GBD estimates'!$AU$4:$AU$258=""All ages"")"),3106.693896) -> 3106.6939 | V36: =IFERROR(__xludf.DUMMYFUNCTION("FILTER('GBD estimates'!$BA$4:$BA$258,'GBD estimates'!$AV$4:$AV$258=V$3,'GBD estimates'!$AU$4:$AU$258=""All ages"")"),4403.622657) -> 4403.6227 | W36: =IFERROR(__xludf.DUMMYFUNCTION("FILTER('GBD estimates'!$BA$4:$BA$258,'GBD estimates'!$AV$4:$AV$258=W$3,'GBD estimates'!$AU$4:$AU$258=""All ages"")"),6495.373611) -> 6495.3736 | X36: =IFERROR(__xludf.DUMMYFUNCTION("FILTER('GBD estimates'!$BA$4:$BA$258,'GBD estimates'!$AV$4:$AV$258=X$3,'GBD estimates'!$AU$4:$AU$258=""All ages"")"),9889.762202) -> 9889.7622 | Y36: =IFERROR(__xludf.DUMMYFUNCTION("FILTER('GBD estimates'!$BA$4:$BA$258,'GBD estimates'!$AV$4:$AV$258=Y$3,'GBD estimates'!$AU$4:$AU$258=""All ages"")"),8078.866903) -> 8078.8669 | Z36: 135 | AA36: =IFERROR(__xludf.DUMMYFUNCTION("FILTER('GBD estimates'!$S$4:$S$309,'GBD estimates'!$M$4:$M$309=AA$2,'GBD estimates'!$O$4:$O$309=""All ages"")"),5776.359003) -> 5776.359 | AB36: 6280 | AD36: GW analysis | AE36: GW's analysis of malaria burden in SMC-eligible countries
C38: Malaria incidence among people under age 15
E39: Malaria incidence among people under 5 | F39: per 100k | G39: input | H39: - | I39: 72800 | J39: 47873 | K39: 78599 | L39: 76062 | M39: 91107 | N39: 96207 | O39: 93495 | P39: 82270 | Q39: =IFERROR(__xludf.DUMMYFUNCTION("FILTER('GBD estimates'!$CA$4:$CA$105,'GBD estimates'!$BV$4:$BV$105=Q$3,'GBD estimates'!$BU$4:$BU$105=""Under 5"")"),92549.9) -> 92549.9 | R39: =IFERROR(__xludf.DUMMYFUNCTION("FILTER('GBD estimates'!$CA$4:$CA$105,'GBD estimates'!$BV$4:$BV$105=R$3,'GBD estimates'!$BU$4:$BU$105=""Under 5"")"),66346.67) -> 66346.67 | S39: =IFERROR(__xludf.DUMMYFUNCTION("FILTER('GBD estimates'!$CA$4:$CA$105,'GBD estimates'!$BV$4:$BV$105=S$3,'GBD estimates'!$BU$4:$BU$105=""Under 5"")"),77203.83) -> 77203.83 | T39: =IFERROR(__xludf.DUMMYFUNCTION("FILTER('GBD estimates'!$CA$4:$CA$105,'GBD estimates'!$BV$4:$BV$105=T$3,'GBD estimates'!$BU$4:$BU$105=""Under 5"")"),98746.64) -> 98746.64 | U39: =IFERROR(__xludf.DUMMYFUNCTION("FILTER('GBD estimates'!$CA$4:$CA$105,'GBD estimates'!$BV$4:$BV$105=U$3,'GBD estimates'!$BU$4:$BU$105=""Under 5"")"),90253.5) -> 90253.5 | V39: =IFERROR(__xludf.DUMMYFUNCTION("FILTER('GBD estimates'!$CA$4:$CA$105,'GBD estimates'!$BV$4:$BV$105=V$3,'GBD estimates'!$BU$4:$BU$105=""Under 5"")"),72018.194) -> 72018.194 | W39: =IFERROR(__xludf.DUMMYFUNCTION("FILTER('GBD estimates'!$CA$4:$CA$105,'GBD estimates'!$BV$4:$BV$105=W$3,'GBD estimates'!$BU$4:$BU$105=""Under 5"")"),93840.62) -> 93840.62 | X39: =IFERROR(__xludf.DUMMYFUNCTION("FILTER('GBD estimates'!$CA$4:$CA$105,'GBD estimates'!$BV$4:$BV$105=X$3,'GBD estimates'!$BU$4:$BU$105=""Under 5"")"),77809.67) -> 77809.67 | Y39: =IFERROR(__xludf.DUMMYFUNCTION("FILTER('GBD estimates'!$CA$4:$CA$105,'GBD estimates'!$BV$4:$BV$105=Y$3,'GBD estimates'!$BU$4:$BU$105=""Under 5"")"),69826.126) -> 69826.126 | Z39: 46489 | AA39: =IFERROR(__xludf.DUMMYFUNCTION("FILTER('GBD estimates'!$AO$4:$AO$156,'GBD estimates'!$AI$4:$AI$156=AA$2,'GBD estimates'!$AK$4:$AK$156=""<5 years"")"),63337.56905) -> 63337.569 | AB39: 90318 | AD39: GW analysis | AE39: GW's analysis of malaria burden in SMC-eligible countries
