Workbook

Sheet Key
A1: Guide to interpreting this cost-effectiveness analysis
A2: Sheet descriptions
E4: Main CEA | F4: This sheet contains the primary calculations that result in final cost-effectiveness estimates. This sheet draws on inputs from the "Inputs" sheet and inputs calculated in the other supplemental sheets listed below.
E5: Aggregation across vaccines | F5: This sheet contains our calculations for pulling CEA parameters from other supplementary sheets and aggregating them across vaccines before entering them in the "Main CEA" sheet.
E6: Treatment effect | F6: This sheet contains our calculations of the effect of New Incentives' program on vaccine uptake.
E7: Disease burden | F7: This sheet contains our calculations of vaccine-preventable disease burden among New Incentives' target population.
E8: Vaccine coverage | F8: This sheet contains our calculations of baseline vaccination coverage among New Incentives' target population, as well as vaccination coverage among populations represented by GBD disease burden estimates.
E9: Vaccine efficacy | F9: This sheet contains our calculations of the effect of vaccination on disease incidence for each vaccine incentivized by New Incentives' program.
E10: Leverage/Funging | F10: This sheet contains our calculations of the impact that crowding in and crowding out funding by other contributors has on the benefits of the program.
E11: Inputs | F11: This sheet contains all of the manually entered input values informing the CEA, along with the sources and reasoning supporting them. This sheet also contains inputs sourced from the "GBD estimates" sheet.
E12: GBD estimates | F12: This sheet contains disease burden and population datasets downloaded from the Institute of Health Metrics (IHME)'s Global Burden of Disease (GBD) project.
E13: Simple CEA | F13: This sheet contains a simplified version of the CEA that is designed to be comparable to our CEAs of other programs.
E14: Confidence intervals | F14: This sheet contains our best guesses of the 25th and 75th percentile values for each of the parameters of our simple CEA.
E15: Sensitivity analysis | F15: This sheet contains the outputs of our sensitivity analysis that tests the cost-effectiveness ranges that would result from updating certain inputs to their 25th or 75th percentile values.
A17: Terminology key
C19: Terms specific to this CEA
E20: BCG vaccine | F20: The Bacillus Calmette-Guerin (BCG) vaccine is designed to prevent tuberculosis and other mycobacterial infections. BCG is one of the vaccines directly incentivized by New Incentives' program.
E21: Penta vaccine | F21: The pentavalent vaccine (referred to as Penta in this CEA) is a 5-in-1 vaccine that is designed to prevent diphtheria, pertussis, tetanus, hepatitis B, and H. influenza type B infections. Penta is one of the vaccines directly incentivized by New Incentives' program.
E22: DTP vaccine | F22: The DTP vaccine is designed to prevent diphtheria, pertussis, and tetanus. In Nigeria, the DTP vaccine is typically delivered as part of the Penta vaccine, which is one of the vaccines directly incentivized by New Incentives' program.
E23: Hib vaccine | F23: The HiB vaccine is designed to prevent H. influenzae type B (Hib) infections. In Nigeria, the Hib vaccine is typically delivered as part of the Penta vaccine, which is one of the vaccines directly incentivized by New Incentives' program.
E24: PCV vaccine | F24: The pneumococcal conjugate vaccine (PCV) is designed to prevent pneumococcal infections. PCV is one of the vaccines directly incentivized by New Incentives' program.
E25: Vaccine efficacy | F25: The efficacy rate of a vaccine refers to the reduction in vaccine-targeted disease incidence among people who receive the vaccine compared to those who do not receive the vaccine.
E26: Vaccine-preventable causes | F26: In this CEA, we use "vaccine-preventable causes" to refer to causes of disease incidence and mortality that are addressable by the specific set of vaccines directly incentivized by New Incentives' program.
E27: Vaccine-preventable mortalities | F27: In this CEA, we use "vaccine-preventable mortalities" to refer to mortalities that we expect would be averted if all children were fully vaccinated with the set of vaccines directly incentivized by New Incentives' program. Because vaccines are not 100% effective, the number of "vaccine-preventable mortalities" will always represent a subset of "mortalities from vaccine-preventable causes."
E28: MICS survey | F28: Multiple Indicator Cluster Surveys (MICS) are standardized household surveys implemented in many countries to collect data on a variety of indicators, including child vaccination rates.
C30: Terms used across GiveWell's CEAs
E31: Internal validity | F31: Describes an adjustment we make to the treatment effect of an intervention to account for the possibility that the treatment effects found in studies may not represent the true effect the intervention had on the populations studied.
E32: External validity | F32: Describes an adjustment we make to the treatment effect of an intervention to account for differences in the program implementation or populations treated in studies from the program implementation or populations treated by grantee programs.
E33: Leverage | F33: Describes a situation where a grantee's spending on a program causes other organizations or governments to contribute more to the program than they otherwise would have. In most cases, accounting for leverage increases cost-effectiveness
E34: Funging | F34: Describes a situation where a grantee's spending on a program causes other organizations or governments to contribute less to the program than they otherwise would have. In most cases, accounting for funging decreases cost-effectiveness.
E35: Counterfactual | F35: In most cases, describes the state of the world that would exist if we did not provide funding to a grantee for a program. When discussing the "counterfactual value of other actors' spending," we are referring to how much benefit another organization's or government's spending would generate if it were spent on something other than the grantee program.
E36: Moral weights | F36: To compare cost-effectiveness across different programs, we use ‘moral weights’ to quantify the benefits of different program impacts (e.g. increased income vs reduced deaths). We benchmark the value of each benefit to a value of 1, which we define as the value of doubling someone’s consumption for one year.
E37: Philanthropic actors | F37: Non-governmental organizations (NGOs) providing funding to philanthropic programs.
A39: Unit and source key
C41: Unit labels used in the CEA
E42: # | F42: Number
E43: per 1k | F43: Rate per 1,000
E44: per 100k | F44: Rate per 100,000
E45: $ | F45: U.S. dollars
E46: ln($) | F46: The natural logarithm of a monetary value
...

Sheet Main CEA
I1: New Incentives – current states of operation | R1: New Incentives – prospective states | AF1: New Incentives – prospective states
I2: Nigeria | J2: Nigeria | K2: Nigeria | L2: Nigeria | M2: Nigeria | N2: Nigeria | O2: Nigeria | P2: Nigeria | Q2: Nigeria | R2: Nigeria | S2: Nigeria | T2: Nigeria | U2: Nigeria | V2: Nigeria | W2: Nigeria | X2: Nigeria | Y2: Nigeria | Z2: Nigeria | AA2: Nigeria | AB2: Nigeria | AC2: Nigeria | AD2: Nigeria | AE2: Nigeria | AF2: Nigeria | AG2: Nigeria | AH2: Nigeria | AI2: Nigeria | AJ2: Nigeria | AK2: Nigeria | AL2: Nigeria | AM2: Nigeria | AN2: Nigeria | AO2: Nigeria | AP2: Nigeria | AQ2: Nigeria | AR2: Nigeria | AS2: Nigeria | AT2: Nigeria | AU2: Nigeria | AV2: Nigeria
A3: Main calculations | F3: unit | G3: type | H3: Overall | I3: Bauchi | J3: Gombe | K3: Jigawa | L3: Kaduna - cohort 17 | M3: Kano | N3: Katsina | O3: Kebbi | P3: Sokoto | Q3: Zamfara | R3: Abia | S3: Adamawa | T3: Akwa Ibom | U3: Anambra | V3: Bayelsa | W3: Benue | X3: Borno | Y3: Cross River | Z3: Delta | AA3: Ebonyi | AB3: Edo | AC3: Ekiti | AD3: Enugu | AE3: FCT | AF3: Imo | AG3: Kaduna | AH3: Kogi | AI3: Kwara | AJ3: Lagos | AK3: Nasarawa | AL3: Niger | AM3: Niger - cohorts 32 & 36 | AN3: Niger - cohort 34 | AO3: Ogun | AP3: Ondo | AQ3: Osun | AR3: Oyo | AS3: Plateau | AT3: Rivers | AU3: Taraba | AV3: Yobe
E4: Final cost-effectiveness estimate (pulled from below for visibility) | F4: =F242 -> xbenchmark | G4: feed | H4: =H242 -> - | I4: =I242 -> 20.039606 | J4: =J242 -> 10.020838 | K4: =K242 -> 18.177505 | L4: =L242 -> 9.0027672 | M4: =M242 -> 12.612827 | N4: =N242 -> 16.809734 | O4: =O242 -> 29.037013 | ... AV4: =AV242 -> 11.471963
A5: Grantee costs
C7: GiveWell costs
E8: Grant size | F8: =Inputs!F8 -> $ | G8: =Inputs!G8 -> input | H8: =Inputs!H8 -> 1000000 | I8: =Inputs!I8 -> - | J8: =Inputs!J8 -> - | K8: =Inputs!K8 -> - | L8: =Inputs!L8 -> - | M8: =Inputs!M8 -> - | ... AV8: =Inputs!AV8 -> -
C10: Spending attributable to grantee
E11: Total spending contributed by grantee | F11: $ | G11: calc | H11: - | I11: =IF(I8="-",$H8,I8) -> 1000000 | J11: =IF(J8="-",$H8,J8) -> 1000000 | K11: =IF(K8="-",$H8,K8) -> 1000000 | L11: =IF(L8="-",$H8,L8) -> 1000000 | M11: =IF(M8="-",$H8,M8) -> 1000000 | N11: =IF(N8="-",$H8,N8) -> 1000000 | O11: =IF(O8="-",$H8,O8) -> 1000000 | P11: =IF(P8="-",$H8,P8) -> 1000000 | ... AV11: =IF(AV8="-",$H8,AV8) -> 1000000
C13: Cost per child enrolled
E14: Cost per infant enrolled in the program | F14: $ | G14: input | H14: =Inputs!H11 -> 16.26
E15: Adjustment for repeat enrollments | F15: % | G15: input | H15: =Inputs!H12 -> 0.107211
E16: Adjusted cost per infant enrolled in the program | F16: $ | G16: calc | H16: =H14/(1-H15) -> 18.21259 | I16: =Inputs!I11 -> - | J16: =Inputs!J11 -> - | K16: =Inputs!K11 -> - | L16: =Inputs!L11 -> - | M16: =Inputs!M11 -> - | N16: =Inputs!N11 -> - | O16: =Inputs!O11 -> - | P16: =Inputs!P11 -> - | ... AV16: =Inputs!AV11 -> -
A18: Outputs
C20: Total children enrolled
E21: Total children enrolled in the program | F21: # | G21: calc | H21: - | I21: =I11/$H16 -> 54907.073 | J21: =J11/$H16 -> 54907.073 | K21: =K11/$H16 -> 54907.073 | L21: =L11/$H16 -> 54907.073 | M21: =M11/$H16 -> 54907.073 | N21: =N11/$H16 -> 54907.073 | O21: =O11/$H16 -> 54907.073 | P21: =P11/$H16 -> 54907.073 | ... AV21: =AV11/$H16 -> 54907.073
C23: Counterfactual vaccination coverage
E24: Proportion of children in the target population who would be vaccinated in the absence of the program, aggregated across vaccines | F24: ='Aggregation across vaccines'!F36 -> % | G24: supp | H24: ='Aggregation across vaccines'!H36 -> - | I24: ='Aggregation across vaccines'!I42 -> 0.56315632 | J24: ='Aggregation across vaccines'!J42 -> 0.68255102 | K24: ='Aggregation across vaccines'!K42 -> 0.63869041 | L24: ='Aggregation across vaccines'!L42 -> 0.61022684 | M24: ='Aggregation across vaccines'!M42 -> 0.5925868 | N24: ='Aggregation across vaccines'!N42 -> 0.55620425 | O24: ='Aggregation across vaccines'!O42 -> 0.42892733 | P24: ='Aggregation across vaccines'!P42 -> 0.38889499 | ... AV24: ='Aggregation across vaccines'!AV42 -> 0.62035872
E25: Corresponding proportion of children who would not be vaccinated in the absence of the program, aggregated across incentivized vaccines | F25: % | G25: calc | H25: - | I25: =1-I24 -> 0.43684368 | J25: =1-J24 -> 0.31744898 | K25: =1-K24 -> 0.36130959 | L25: =1-L24 -> 0.38977316 | M25: =1-M24 -> 0.4074132 | N25: =1-N24 -> 0.44379575 | O25: =1-O24 -> 0.57107267 | P25: =1-P24 -> 0.61110501 | ... AV25: =1-AV24 -> 0.37964128
C27: Effect of the program on vaccination coverage
E28: Reduction in the proportion of children who are unvaccinated as a result of New Incentives' program, based on GW's analysis of the New Incentives RCT, aggregated across vaccines | F28: ='Treatment effect'!F71 -> % | G28: supp | H28: ='Treatment effect'!H84 -> 0.33303026 | I28: ='Treatment effect'!I71 -> - | J28: ='Treatment effect'!J71 -> - | K28: ='Treatment effect'!K71 -> - | L28: ='Treatment effect'!L71 -> - | M28: ='Treatment effect'!M71 -> - | N28: ='Treatment effect'!N71 -> - | O28: ='Treatment effect'!O71 -> - | P28: ='Treatment effect'!P71 -> - | ... AV28: ='Treatment effect'!AV71 -> -
E29: Internal validity adjustment | F29: =Inputs!F236 -> % | G29: =Inputs!G236 -> input | H29: =Inputs!H236 -> -0.12 | I29: =Inputs!I236 -> - | J29: =Inputs!J236 -> - | K29: =Inputs!K236 -> - | L29: =Inputs!L236 -> - | M29: =Inputs!M236 -> - | ... AV29: =Inputs!AV236 -> -
E30: Reduction in the proportion of children who are unvaccinated as a result of New Incentives' program | F30: % | G30: calc | H30: =H28*(1+H29) -> 0.29306663 | I30: - | J30: - | K30: - | L30: - | M30: - | N30: - | O30: - | P30: - | R30: - | S30: - | T30: - | U30: - | V30: - | W30: - | X30: - | Y30: - | Z30: - | AA30: - | AB30: - | AC30: - | AD30: - | AE30: - | AF30: - | AG30: - | AH30: - | AI30: - | AJ30: - | AK30: - | AL30: - | AM30: - | AN30: - | AO30: - | AP30: - | AQ30: - | AR30: - | AS30: - | AT30: - | AU30: - | AV30: -
E31: Corresponding increase in the proportion of children who are vaccinated as a result of New Incentives' program | F31: ppt | G31: calc | H31: - | I31: =I25*$H30 -> 0.12802431 | J31: =J25*$H30 -> 0.093033702 | K31: =K25*$H30 -> 0.10588779 | L31: =L25*$H30 -> 0.11422951 | M31: =M25*$H30 -> 0.11939921 | N31: =N25*$H30 -> 0.13006173 | O31: =O25*$H30 -> 0.16736235 | P31: =P25*$H30 -> 0.17909449 | ... AV31: =AV25*$H30 -> 0.11126019
E32: Total proportion of children in the target population who are vaccinated | F32: % | G32: calc | H32: - | I32: =I24+I31 -> 0.69118063 | J32: =J24+J31 -> 0.77558473 | K32: =K24+K31 -> 0.74457819 | L32: =L24+L31 -> 0.72445635 | M32: =M24+M31 -> 0.71198602 | N32: =N24+N31 -> 0.68626598 | O32: =O24+O31 -> 0.59628967 | P32: =P24+P31 -> 0.56798948 | ... AV32: =AV24+AV31 -> 0.73161891
C34: Number of children vaccinated as a result of New Incentives' program
E35: Children in the target population | F35: # | G35: calc | H35: - | I35: =I21/I32 -> 79439.542 | J35: =J21/J32 -> 70794.422 | K35: =K21/K32 -> 73742.52 | L35: =L21/L32 -> 75790.726 | M35: =M21/M32 -> 77118.189 | N35: =N21/N32 -> 80008.444 | O35: =O21/O32 -> 92081.207 | P35: =P21/P32 -> 96669.172 | ... AV35: =AV21/AV32 -> 75048.733
E36: Children counterfactually vaccinated | F36: # | G36: calc | H36: - | I36: =I35*I31 -> 10170.192 | J36: =J35*J31 -> 6586.2672 | K36: =K35*K31 -> 7808.4321 | L36: =L35*L31 -> 8657.5374 | M36: =M35*M31 -> 9207.8511 | N36: =N35*N31 -> 10406.036 | O36: =O35*O31 -> 15410.927 | P36: =P35*P31 -> 17312.916 | ... AV36: =AV35*AV31 -> 8349.9364
A38: Outcomes
C40: Mortality reduction among people under age 5
E41: Probability that a person will die of a vaccine-preventable cause before reaching age 5, adjusted for deaths occurring before the age of vaccination | F41: ='Disease burden'!F184 -> % | G41: supp | H41: ='Disease burden'!H184 -> - | I41: ='Disease burden'!I184 -> 0.027625565 | J41: ='Disease burden'!J184 -> 0.01953192 | K41: ='Disease burden'!K184 -> 0.027236652 | L41: ='Disease burden'!L184 -> 0.011660475 | M41: ='Disease burden'!M184 -> 0.018680701 | N41: ='Disease burden'!N184 -> 0.020226729 | O41: ='Disease burden'!O184 -> 0.021982759 | ... AV41: ='Disease burden'!AV184 -> 0.014629881
E42: Proportion of people under age 5 represented in GBD 2021 disease burden estimates who were vaccinated, aggregated across vaccines | F42: ='Aggregation across vaccines'!F74 -> % | G42: supp | H42: ='Aggregation across vaccines'!H74 -> - | I42: ='Aggregation across vaccines'!I74 -> 0.27723536 | J42: ='Aggregation across vaccines'!J74 -> 0.35272184 | K42: ='Aggregation across vaccines'!K74 -> 0.44729281 | L42: ='Aggregation across vaccines'!L74 -> 0.51957609 | M42: ='Aggregation across vaccines'!M74 -> 0.35511405 | N42: ='Aggregation across vaccines'!N74 -> 0.35528503 | O42: ='Aggregation across vaccines'!O74 -> 0.44566539 | ... AV42: ='Aggregation across vaccines'!AV74 -> 0.55188809
E43: Proportion of vaccine-preventable disease incidence averted by full vaccination among people under age 5, aggregated across vaccines | F43: ='Aggregation across vaccines'!F63 -> % | G43: supp | H43: ='Aggregation across vaccines'!H63 -> - | I43: ='Aggregation across vaccines'!I63 -> 0.52255605 | J43: ='Aggregation across vaccines'!J63 -> 0.52738394 | K43: ='Aggregation across vaccines'!K63 -> 0.5508425 | L43: ='Aggregation across vaccines'!L63 -> 0.54371205 | M43: ='Aggregation across vaccines'!M63 -> 0.51595309 | N43: ='Aggregation across vaccines'!N63 -> 0.54582208 | O43: ='Aggregation across vaccines'!O63 -> 0.55824395 | ... AV43: ='Aggregation across vaccines'!AV63 -> 0.57218524
E44: Probability that an unvaccinated person will die of a vaccine-preventable cause before reaching age 5, adjusted for deaths occurring before the age of vaccination | F44: ='Disease burden'!F209 -> % | G44: calc | H44: ='Disease burden'!H209 -> - | I44: =I41/((1-I42)+(I42*(1-I43))) -> 0.032305729 | J44: =J41/((1-J42)+(J42*(1-J43))) -> 0.023995572 | K44: =K41/((1-K42)+(K42*(1-K43))) -> 0.036141473 | L44: =L41/((1-L42)+(L42*(1-L43))) -> 0.016251528 | M44: =M41/((1-M42)+(M42*(1-M43))) -> 0.022871215 | N44: =N41/((1-N42)+(N42*(1-N43))) -> 0.025092782 | O44: =O41/((1-O42)+(O42*(1-O43))) -> 0.029263135 | P44: =P41/((1-P42)+(P42*(1-P43))) -> 0.036347232 | ... AV44: =AV41/((1-AV42)+(AV42*(1-AV43))) -> 0.021381907
E45: Mortalities indirectly attributable to vaccine-preventable disease per mortality directly caused by vaccine-preventable disease | F45: =Inputs!F241 -> % | G45: =Inputs!G241 -> input | H45: =Inputs!H241 -> 0.75 | I45: =Inputs!I241 -> - | J45: =Inputs!J241 -> - | K45: =Inputs!K241 -> - | L45: =Inputs!L241 -> - | M45: =Inputs!M241 -> - | ... AV45: =Inputs!AV241 -> -
E46: Probability that an unvaccinated person will die of a vaccine-preventable cause before reaching age 5, including mortalities indirectly attributable to vaccine-preventable disease | F46: % | G46: calc | H46: - | I46: =I44*(1+$H45) -> 0.056535025 | J46: =J44*(1+$H45) -> 0.041992252 | K46: =K44*(1+$H45) -> 0.063247578 | L46: =L44*(1+$H45) -> 0.028440174 | M46: =M44*(1+$H45) -> 0.040024626 | N46: =N44*(1+$H45) -> 0.043912369 | O46: =O44*(1+$H45) -> 0.051210486 | P46: =P44*(1+$H45) -> 0.063607657 | ... AV46: =AV44*(1+$H45) -> 0.037418337
E47: Ratio of the reduction in vaccine-preventable disease mortality to the reduction in vaccine-preventable disease incidence | F47: =Inputs!F242 -> % | G47: =Inputs!G242 -> input | H47: =Inputs!H242 -> 1 | I47: =Inputs!I242 -> - | J47: =Inputs!J242 -> - | K47: =Inputs!K242 -> - | L47: =Inputs!L242 -> - | M47: =Inputs!M242 -> - | ... AV47: =Inputs!AV242 -> -
E48: Total deaths averted among people under age 5 | F48: # | G48: calc | H48: - | I48: =I36*I43*I46*$H47 -> 300.45514 | J48: =J36*J43*J46*$H47 -> 145.85973 | K48: =K36*K43*K46*$H47 -> 272.04151 | L48: =L36*L43*L46*$H47 -> 133.8738 | M48: =M36*M43*M46*$H47 -> 190.14977 | N48: =N36*N43*N46*$H47 -> 249.41542 | O48: =O36*O43*O46*$H47 -> 440.56671 | P48: =P36*P43*P46*$H47 -> 583.66726 | ... AV48: =AV36*AV43*AV46*$H47 -> 178.77398
C50: Mortality reduction among people age 5 through age 14
E51: Probability that a 5-year-old will die of a vaccine-preventable cause before reaching age 15 | F51: ='Disease burden'!F229 -> % | G51: supp | H51: ='Disease burden'!H229 -> - | I51: ='Disease burden'!I229 -> 0.0022627988 | J51: ='Disease burden'!J229 -> 0.0015769754 | K51: ='Disease burden'!K229 -> 0.0022646562 | L51: ='Disease burden'!L229 -> 0.0010096079 | M51: ='Disease burden'!M229 -> 0.0015299464 | N51: ='Disease burden'!N229 -> 0.0018337091 | O51: ='Disease burden'!O229 -> 0.0020464817 | ... AV51: ='Disease burden'!AV229 -> 0.0016231791
...

Sheet Aggregation across vaccines
I1: New Incentives – current states of operation | R1: New Incentives – prospective states | AF1: New Incentives – prospective states
I2: Nigeria | J2: Nigeria | K2: Nigeria | L2: Nigeria | M2: Nigeria | N2: Nigeria | O2: Nigeria | P2: Nigeria | Q2: Nigeria | R2: Nigeria | S2: Nigeria | T2: Nigeria | U2: Nigeria | V2: Nigeria | W2: Nigeria | X2: Nigeria | Y2: Nigeria | Z2: Nigeria | AA2: Nigeria | AB2: Nigeria | AC2: Nigeria | AD2: Nigeria | AE2: Nigeria | AF2: Nigeria | AG2: Nigeria | AH2: Nigeria | AI2: Nigeria | AJ2: Nigeria | AK2: Nigeria | AL2: Nigeria | AM2: Nigeria | AN2: Nigeria | AO2: Nigeria | AP2: Nigeria | AQ2: Nigeria | AR2: Nigeria | AS2: Nigeria | AT2: Nigeria | AU2: Nigeria | AV2: Nigeria
A3: Main calculations | F3: unit | G3: type | H3: Overall | I3: Bauchi | J3: Gombe | K3: Jigawa | L3: Kaduna - cohort 17 | M3: Kano | N3: Katsina | O3: Kebbi | P3: Sokoto | Q3: Zamfara | R3: Abia | S3: Adamawa | T3: Akwa Ibom | U3: Anambra | V3: Bayelsa | W3: Benue | X3: Borno | Y3: Cross River | Z3: Delta | AA3: Ebonyi | AB3: Edo | AC3: Ekiti | AD3: Enugu | AE3: FCT | AF3: Imo | AG3: Kaduna | AH3: Kogi | AI3: Kwara | AJ3: Lagos | AK3: Nasarawa | AL3: Niger | AM3: Niger - cohorts 32 & 36 | AN3: Niger - cohort 34 | AO3: Ogun | AP3: Ondo | AQ3: Osun | AR3: Oyo | AS3: Plateau | AT3: Rivers | AU3: Taraba | AV3: Yobe
E4: Final cost-effectiveness estimate (pulled from "Main calcs" sheet for visibility) | F4: ='Main CEA'!F242 -> xbenchmark | G4: ='Main CEA'!G242 -> calc | H4: ='Main CEA'!H242 -> - | I4: ='Main CEA'!I242 -> 20.039606 | J4: ='Main CEA'!J242 -> 10.020838 | K4: ='Main CEA'!K242 -> 18.177505 | L4: ='Main CEA'!L242 -> 9.0027672 | M4: ='Main CEA'!M242 -> 12.612827 | ... AV4: ='Main CEA'!AV242 -> 11.471963
A5: Baseline coverage for the target population
C7: Baseline vaccination coverage for the target population
E8: Baseline proportion of children in the target population who receive the BCG vaccine | F8: ='Vaccine coverage'!F96 -> % | G8: supp | H8: ='Vaccine coverage'!H96 -> - | I8: ='Vaccine coverage'!I96 -> 0.55242574 | J8: ='Vaccine coverage'!J96 -> 0.72882976 | K8: ='Vaccine coverage'!K96 -> 0.60775837 | L8: ='Vaccine coverage'!L96 -> 0.63807624 | M8: ='Vaccine coverage'!M96 -> 0.61526279 | N8: ='Vaccine coverage'!N96 -> 0.49219015 | O8: ='Vaccine coverage'!O96 -> 0.40063624 | ... AV8: ='Vaccine coverage'!AV96 -> 0.64274993
E9: Baseline proportion of children in the target population who receive the 1st dose of the Penta vaccine | F9: ='Vaccine coverage'!F97 -> % | G9: supp | H9: ='Vaccine coverage'!H97 -> - | I9: ='Vaccine coverage'!I97 -> 0.49339093 | J9: ='Vaccine coverage'!J97 -> 0.67679908 | K9: ='Vaccine coverage'!K97 -> 0.57233748 | L9: ='Vaccine coverage'!L97 -> 0.59765241 | M9: ='Vaccine coverage'!M97 -> 0.56243164 | N9: ='Vaccine coverage'!N97 -> 0.45688369 | O9: ='Vaccine coverage'!O97 -> 0.33809936 | ... AV9: ='Vaccine coverage'!AV97 -> 0.60764175
E10: Baseline proportion of children in the target population who receive the 2nd dose of the Penta vaccine | F10: ='Vaccine coverage'!F98 -> % | G10: supp | H10: ='Vaccine coverage'!H98 -> - | I10: ='Vaccine coverage'!I98 -> 0.44736379 | J10: ='Vaccine coverage'!J98 -> 0.63357359 | K10: ='Vaccine coverage'!K98 -> 0.51570409 | L10: ='Vaccine coverage'!L98 -> 0.50729913 | M10: ='Vaccine coverage'!M98 -> 0.48268462 | N10: ='Vaccine coverage'!N98 -> 0.41743904 | O10: ='Vaccine coverage'!O98 -> 0.24294325 | ... AV10: ='Vaccine coverage'!AV98 -> 0.50552412
E11: Baseline proportion of children in the target population who receive the 3rd dose of the Penta vaccine | F11: ='Vaccine coverage'!F99 -> % | G11: supp | H11: ='Vaccine coverage'!H99 -> - | I11: ='Vaccine coverage'!I99 -> 0.35420886 | J11: ='Vaccine coverage'!J99 -> 0.50179589 | K11: ='Vaccine coverage'!K99 -> 0.39683399 | L11: ='Vaccine coverage'!L99 -> 0.40964155 | M11: ='Vaccine coverage'!M99 -> 0.36891753 | N11: ='Vaccine coverage'!N99 -> 0.35086445 | O11: ='Vaccine coverage'!O99 -> 0.15439104 | ... AV11: ='Vaccine coverage'!AV99 -> 0.41023644
E12: Baseline proportion of children in the target population who receive the 1st dose of the PCV vaccine | F12: ='Vaccine coverage'!F108 -> % | G12: supp | H12: ='Vaccine coverage'!H108 -> - | I12: ='Vaccine coverage'!I108 -> 0.49161614 | J12: ='Vaccine coverage'!J108 -> 0.64092967 | K12: ='Vaccine coverage'!K108 -> 0.5647796 | L12: ='Vaccine coverage'!L108 -> 0.58656257 | M12: ='Vaccine coverage'!M108 -> 0.54917961 | N12: ='Vaccine coverage'!N108 -> 0.44239613 | O12: ='Vaccine coverage'!O108 -> 0.3330181 | ... AV12: ='Vaccine coverage'!AV108 -> 0.59058673
E13: Baseline proportion of children in the target population who receive the 2nd dose of the PCV vaccine | F13: ='Vaccine coverage'!F109 -> % | G13: supp | H13: ='Vaccine coverage'!H109 -> - | I13: ='Vaccine coverage'!I109 -> 0.44575457 | J13: ='Vaccine coverage'!J109 -> 0.59999507 | K13: ='Vaccine coverage'!K109 -> 0.50889407 | L13: ='Vaccine coverage'!L109 -> 0.49788586 | M13: ='Vaccine coverage'!M109 -> 0.47131159 | N13: ='Vaccine coverage'!N109 -> 0.39628905 | O13: ='Vaccine coverage'!O109 -> 0.23929208 | ... AV13: ='Vaccine coverage'!AV109 -> 0.48978056
E14: Baseline proportion of children in the target population who receive the 3rd dose of the PCV vaccine | F14: ='Vaccine coverage'!F110 -> % | G14: supp | H14: ='Vaccine coverage'!H110 -> - | I14: ='Vaccine coverage'!I110 -> 0.35293473 | J14: ='Vaccine coverage'!J110 -> 0.4752014 | K14: ='Vaccine coverage'!K110 -> 0.39159369 | L14: ='Vaccine coverage'!L110 -> 0.40204037 | M14: ='Vaccine coverage'!M110 -> 0.36022509 | N14: ='Vaccine coverage'!N110 -> 0.33429231 | O14: ='Vaccine coverage'!O110 -> 0.15207071 | ... AV14: ='Vaccine coverage'!AV110 -> 0.39934281
E15: Baseline proportion of children in the target population who receive the 1st dose of the rotavirus vaccine | F15: ='Vaccine coverage'!F115 -> % | G15: supp | H15: ='Vaccine coverage'!H115 -> - | I15: ='Vaccine coverage'!I115 -> 0.49250354 | J15: ='Vaccine coverage'!J115 -> 0.65886437 | K15: ='Vaccine coverage'!K115 -> 0.56855854 | L15: ='Vaccine coverage'!L115 -> 0.59210749 | M15: ='Vaccine coverage'!M115 -> 0.55580563 | N15: ='Vaccine coverage'!N115 -> 0.44963991 | O15: ='Vaccine coverage'!O115 -> 0.33555873 | ... AV15: ='Vaccine coverage'!AV115 -> 0.59911424
E16: Baseline proportion of children in the target population who receive the 2nd dose of the rotavirus vaccine | F16: ='Vaccine coverage'!F116 -> % | G16: supp | H16: ='Vaccine coverage'!H116 -> - | I16: ='Vaccine coverage'!I116 -> 0.44655918 | J16: ='Vaccine coverage'!J116 -> 0.61678433 | K16: ='Vaccine coverage'!K116 -> 0.51229908 | L16: ='Vaccine coverage'!L116 -> 0.50259249 | M16: ='Vaccine coverage'!M116 -> 0.4769981 | N16: ='Vaccine coverage'!N116 -> 0.40686404 | O16: ='Vaccine coverage'!O116 -> 0.24111767 | ... AV16: ='Vaccine coverage'!AV116 -> 0.49765234
E17: Baseline proportion of children in the target population who receive the 3rd dose of the rotavirus vaccine | F17: ='Vaccine coverage'!F117 -> % | G17: supp | H17: ='Vaccine coverage'!H117 -> - | I17: ='Vaccine coverage'!I117 -> 0.35357179 | J17: ='Vaccine coverage'!J117 -> 0.48849864 | K17: ='Vaccine coverage'!K117 -> 0.39421384 | L17: ='Vaccine coverage'!L117 -> 0.40584096 | M17: ='Vaccine coverage'!M117 -> 0.36457131 | N17: ='Vaccine coverage'!N117 -> 0.34257838 | O17: ='Vaccine coverage'!O117 -> 0.15323087 | ... AV17: ='Vaccine coverage'!AV117 -> 0.40478963
E18: Baseline proportion of children in the target population who receive the 1st dose of the measles vaccine | F18: ='Vaccine coverage'!F124 -> % | G18: supp | H18: ='Vaccine coverage'!H124 -> - | I18: ='Vaccine coverage'!I124 -> 0.30803947 | J18: ='Vaccine coverage'!J124 -> 0.36704703 | K18: ='Vaccine coverage'!K124 -> 0.55907163 | L18: ='Vaccine coverage'!L124 -> 0.56707265 | M18: ='Vaccine coverage'!M124 -> 0.40505189 | N18: ='Vaccine coverage'!N124 -> 0.43705599 | O18: ='Vaccine coverage'!O124 -> 0.63208098 | ... AV18: ='Vaccine coverage'!AV124 -> 0.71309136
E19: Baseline proportion of children in the target population who receive the 2nd dose of the measles vaccine | F19: ='Vaccine coverage'!F125 -> % | G19: supp | H19: ='Vaccine coverage'!H125 -> - | I19: ='Vaccine coverage'!I125 -> 0.10801384 | J19: ='Vaccine coverage'!J125 -> 0.17802281 | K19: ='Vaccine coverage'!K125 -> 0.3270419 | L19: ='Vaccine coverage'!L125 -> 0.30903959 | M19: ='Vaccine coverage'!M125 -> 0.1420182 | N19: ='Vaccine coverage'!N125 -> 0.24703165 | O19: ='Vaccine coverage'!O125 -> 0.54907035 | ... AV19: ='Vaccine coverage'!AV125 -> 0.48406202
C21: Proportion of vaccine-preventable mortalities that could be prevented by each vaccine dose
E22: Proportion of vaccine-preventable mortalities among people under age 5 that could be prevented by the BCG vaccine | F22: ='Disease burden'!F388 -> % | G22: ='Disease burden'!G388 -> feed | H22: ='Disease burden'!H388 -> - | I22: ='Disease burden'!I388 -> 0.17823491 | J22: ='Disease burden'!J388 -> 0.12033359 | K22: ='Disease burden'!K388 -> 0.20302136 | L22: ='Disease burden'!L388 -> 0.10657065 | M22: ='Disease burden'!M388 -> 0.13277628 | ... AV22: ='Disease burden'!AV388 -> 0.15986442
E23: Proportion of vaccine-preventable mortalities among people under age 5 that could be prevented by the 1st dose of the Penta vaccine | F23: ='Disease burden'!F389 -> % | G23: supp | H23: ='Disease burden'!H389 -> - | I23: ='Disease burden'!I389 -> 0.073644315 | J23: ='Disease burden'!J389 -> 0.09622371 | K23: ='Disease burden'!K389 -> 0.091772594 | L23: ='Disease burden'!L389 -> 0.11232443 | M23: ='Disease burden'!M389 -> 0.085575908 | N23: ='Disease burden'!N389 -> 0.089629168 | O23: ='Disease burden'!O389 -> 0.10466208 | ... AV23: ='Disease burden'!AV389 -> 0.11459606
E24: Proportion of vaccine-preventable mortalities among people under age 5 that could be prevented by the 2nd dose of the Penta vaccine | F24: ='Disease burden'!F390 -> % | G24: supp | H24: ='Disease burden'!H390 -> - | I24: ='Disease burden'!I390 -> 0.11572678 | J24: ='Disease burden'!J390 -> 0.15120869 | K24: ='Disease burden'!K390 -> 0.14421408 | L24: ='Disease burden'!L390 -> 0.17650982 | M24: ='Disease burden'!M390 -> 0.13447643 | N24: ='Disease burden'!N390 -> 0.14084584 | O24: ='Disease burden'!O390 -> 0.16446899 | ... AV24: ='Disease burden'!AV390 -> 0.18007952
E25: Proportion of vaccine-preventable mortalities among people under age 5 that could be prevented by the 3rd dose of the Penta vaccine | F25: ='Disease burden'!F391 -> % | G25: supp | H25: ='Disease burden'!H391 -> - | I25: ='Disease burden'!I391 -> 0.021041233 | J25: ='Disease burden'!J391 -> 0.027492489 | K25: ='Disease burden'!K391 -> 0.026220741 | L25: ='Disease burden'!L391 -> 0.032092695 | M25: ='Disease burden'!M391 -> 0.024450259 | N25: ='Disease burden'!N391 -> 0.025608334 | O25: ='Disease burden'!O391 -> 0.029903452 | ... AV25: ='Disease burden'!AV391 -> 0.032741731
E26: Proportion of vaccine-preventable mortalities among people under age 5 that could be prevented by the 1st dose of the PCV vaccine | F26: ='Disease burden'!F392 -> % | G26: supp | H26: ='Disease burden'!H392 -> - | I26: ='Disease burden'!I392 -> 0.089900525 | J26: ='Disease burden'!J392 -> 0.10135603 | K26: ='Disease burden'!K392 -> 0.085648045 | L26: ='Disease burden'!L392 -> 0.107903 | M26: ='Disease burden'!M392 -> 0.11094009 | N26: ='Disease burden'!N392 -> 0.079775398 | O26: ='Disease burden'!O392 -> 0.076462066 | ... AV26: ='Disease burden'!AV392 -> 0.073761103
E27: Proportion of vaccine-preventable mortalities among people under age 5 that could be prevented by the 2nd dose of the PCV vaccine | F27: ='Disease burden'!F393 -> % | G27: supp | H27: ='Disease burden'!H393 -> - | I27: ='Disease burden'!I393 -> 0.14127225 | J27: ='Disease burden'!J393 -> 0.15927376 | K27: ='Disease burden'!K393 -> 0.13458978 | L27: ='Disease burden'!L393 -> 0.16956186 | M27: ='Disease burden'!M393 -> 0.17433442 | N27: ='Disease burden'!N393 -> 0.12536134 | O27: ='Disease burden'!O393 -> 0.12015467 | ... AV27: ='Disease burden'!AV393 -> 0.1159103
E28: Proportion of vaccine-preventable mortalities among people under age 5 that could be prevented by the 3rd dose of the PCV vaccine | F28: ='Disease burden'!F394 -> % | G28: supp | H28: ='Disease burden'!H394 -> - | I28: ='Disease burden'!I394 -> 0.025685864 | J28: ='Disease burden'!J394 -> 0.028958866 | K28: ='Disease burden'!K394 -> 0.02447087 | L28: ='Disease burden'!L394 -> 0.030829429 | M28: ='Disease burden'!M394 -> 0.031697167 | N28: ='Disease burden'!N394 -> 0.022792971 | O28: ='Disease burden'!O394 -> 0.021846305 | ... AV28: ='Disease burden'!AV394 -> 0.021074601
E29: Proportion of vaccine-preventable mortalities among people under age 5 that could be prevented by the 1st dose of the rotavirus vaccine | F29: ='Disease burden'!F395 -> % | G29: supp | H29: ='Disease burden'!H395 -> - | I29: ='Disease burden'!I395 -> 0.20662453 | J29: ='Disease burden'!J395 -> 0.19100692 | K29: ='Disease burden'!K395 -> 0.14601898 | L29: ='Disease burden'!L395 -> 0.14558025 | M29: ='Disease burden'!M395 -> 0.19432922 | N29: ='Disease burden'!N395 -> 0.17668733 | O29: ='Disease burden'!O395 -> 0.16305604 | ... AV29: ='Disease burden'!AV395 -> 0.14035311
E30: Proportion of vaccine-preventable mortalities among people under age 5 that could be prevented by the 2nd dose of the rotavirus vaccine | F30: ='Disease burden'!F396 -> % | G30: supp | H30: ='Disease burden'!H396 -> - | I30: ='Disease burden'!I396 -> 0.041324906 | J30: ='Disease burden'!J396 -> 0.038201384 | K30: ='Disease burden'!K396 -> 0.029203795 | L30: ='Disease burden'!L396 -> 0.02911605 | M30: ='Disease burden'!M396 -> 0.038865843 | N30: ='Disease burden'!N396 -> 0.035337465 | O30: ='Disease burden'!O396 -> 0.032611208 | ... AV30: ='Disease burden'!AV396 -> 0.028070622
E31: Proportion of vaccine-preventable mortalities among people under age 5 that could be prevented by the 3rd dose of the rotavirus vaccine | F31: ='Disease burden'!F398 -> % | G31: supp | H31: ='Disease burden'!H398 -> - | I31: ='Disease burden'!I397 -> 0.027549937 | J31: ='Disease burden'!J397 -> 0.025467589 | K31: ='Disease burden'!K397 -> 0.019469197 | L31: ='Disease burden'!L397 -> 0.0194107 | M31: ='Disease burden'!M397 -> 0.025910562 | N31: ='Disease burden'!N397 -> 0.02355831 | O31: ='Disease burden'!O397 -> 0.021740806 | P31: ='Disease burden'!P397 -> 0.02699738 | ... AV31: ='Disease burden'!AV397 -> 0.018713748
E32: Proportion of vaccine-preventable mortalities among people under age 5 that could be prevented by the 1st dose of the measles vaccine | F32: ='Disease burden'!F398 -> % | G32: supp | H32: ='Disease burden'!H398 -> - | I32: ='Disease burden'!I398 -> 0.074606151 | J32: ='Disease burden'!J398 -> 0.057117138 | K32: ='Disease burden'!K398 -> 0.090072195 | L32: ='Disease burden'!L398 -> 0.066206609 | M32: ='Disease burden'!M398 -> 0.044052509 | N32: ='Disease burden'!N398 -> 0.10112555 | O32: ='Disease burden'!O398 -> 0.10124241 | ... AV32: ='Disease burden'!AV398 -> 0.10845507
E33: Proportion of vaccine-preventable mortalities among people under age 5 that could be prevented by the 2nd dose of the measles vaccine | F33: ='Disease burden'!F399 -> % | G33: supp | H33: ='Disease burden'!H399 -> - | I33: ='Disease burden'!I399 -> 0.0043885971 | J33: ='Disease burden'!J399 -> 0.0033598316 | K33: ='Disease burden'!K399 -> 0.0052983644 | L33: ='Disease burden'!L399 -> 0.0038945064 | M33: ='Disease burden'!M399 -> 0.0025913241 | N33: ='Disease burden'!N399 -> 0.0059485617 | O33: ='Disease burden'!O399 -> 0.0059554359 | ... AV33: ='Disease burden'!AV399 -> 0.0063797102
C35: Baseline vaccination coverage for the target population, aggregated across vaccines
E36: Proportion of children in the target population who would be vaccinated in the absence of the program, aggregated across vaccines | F36: % | G36: calc | H36: - | I36: =SUMPRODUCT(I8:I19,I22:I33) -> 0.46367056 | J36: =SUMPRODUCT(J8:J19,J22:J33) -> 0.62012448 | K36: =SUMPRODUCT(K8:K19,K22:K33) -> 0.54488278 | L36: =SUMPRODUCT(L8:L19,L22:L33) -> 0.54538777 | M36: =SUMPRODUCT(M8:M19,M22:M33) -> 0.51246873 | N36: =SUMPRODUCT(N8:N19,N22:N33) -> 0.43419286 | O36: =SUMPRODUCT(O8:O19,O22:O33) -> 0.33392894 | P36: =SUMPRODUCT(P8:P19,P22:P33) -> 0.24636944 | ... AV36: =SUMPRODUCT(AV8:AV19,AV22:AV33) -> 0.57166016
E37: Proportion of children in the target population who would not be vaccinated in the absence of the program, aggregated across vaccines - in year of baseline measurement | F37: % | G37: calc | I37: =1-I36 -> 0.53632944 | J37: =1-J36 -> 0.37987552 | K37: =1-K36 -> 0.45511722 | L37: =1-L36 -> 0.45461223 | M37: =1-M36 -> 0.48753127 | N37: =1-N36 -> 0.56580714 | O37: =1-O36 -> 0.66607106 | P37: =1-P36 -> 0.75363056 | ... AV37: =1-AV36 -> 0.42833984
E38: Effective year of baseline measurement | F38: # | G38: supp | I38: ='Vaccine coverage'!I15 -> 2022 | J38: ='Vaccine coverage'!J15 -> 2022.5 | K38: ='Vaccine coverage'!K15 -> 2021.5 | L38: ='Vaccine coverage'!L15 -> 2023 | M38: ='Vaccine coverage'!M15 -> 2022.5 | N38: ='Vaccine coverage'!N15 -> 2021.2647 | O38: ='Vaccine coverage'!O15 -> 2023 | P38: ='Vaccine coverage'!P15 -> 2021.913 | ... AV38: ='Vaccine coverage'!AV15 -> 2023.6471
E39: Counterfactual change in the proportion of unvaccinated children per year in the absence of New Incentives | F39: % | G39: input | H39: =Inputs!H80 -> -0.05 | I39: - | J39: - | K39: - | L39: - | M39: - | N39: - | O39: - | P39: - | Q39: - | R39: - | S39: - | T39: - | U39: - | V39: - | W39: - | X39: - | Y39: - | Z39: - | AA39: - | AB39: - | AC39: - | AD39: - | AE39: - | AF39: - | AG39: - | AH39: - | AI39: - | AJ39: - | AK39: - | AL39: - | AM39: - | AN39: - | AO39: - | AP39: - | AQ39: - | AR39: - | AS39: - | AT39: - | AU39: - | AV39: -
E40: Middle year of grant period | F40: # | G40: input | H40: 2026
E41: Proportion of children in the target population who would not be vaccinated in the absence of the program, aggregated across vaccines - in middle year of grant period | F41: % | G41: calc | I41: =I37*(1+$H$39)^($H$40-I38) -> 0.43684368 | J41: =J37*(1+$H$39)^($H$40-J38) -> 0.31744898 | K41: =K37*(1+$H$39)^($H$40-K38) -> 0.36130959 | L41: =L37*(1+$H$39)^($H$40-L38) -> 0.38977316 | M41: =M37*(1+$H$39)^($H$40-M38) -> 0.4074132 | N41: =N37*(1+$H$39)^($H$40-N38) -> 0.44379575 | O41: =O37*(1+$H$39)^($H$40-O38) -> 0.57107267 | P41: =P37*(1+$H$39)^($H$40-P38) -> 0.61110501 | ... AV41: =AV37*(1+$H$39)^($H$40-AV38) -> 0.37964128
E42: Proportion of children in the target population who would be vaccinated in the absence of the program, aggregated across vaccines - in middle year of grant period | F42: % | G42: calc | I42: =1-I41 -> 0.56315632 | J42: =1-J41 -> 0.68255102 | K42: =1-K41 -> 0.63869041 | L42: =1-L41 -> 0.61022684 | M42: =1-M41 -> 0.5925868 | N42: =1-N41 -> 0.55620425 | O42: =1-O41 -> 0.42892733 | P42: =1-P41 -> 0.38889499 | ... AV42: =1-AV41 -> 0.62035872
A44: Vaccine efficacy and coverage for people under age 5, aggregated across vaccines
...

Sheet Treatment effect
I1: New Incentives – current states of operation | R1: New Incentives – prospective states | AF1: New Incentives – prospective states
I2: Nigeria | J2: Nigeria | K2: Nigeria | L2: Nigeria | M2: Nigeria | N2: Nigeria | O2: Nigeria | P2: Nigeria | Q2: Nigeria | R2: Nigeria | S2: Nigeria | T2: Nigeria | U2: Nigeria | V2: Nigeria | W2: Nigeria | X2: Nigeria | Y2: Nigeria | Z2: Nigeria | AA2: Nigeria | AB2: Nigeria | AC2: Nigeria | AD2: Nigeria | AE2: Nigeria | AF2: Nigeria | AG2: Nigeria | AH2: Nigeria | AI2: Nigeria | AJ2: Nigeria | AK2: Nigeria | AL2: Nigeria | AM2: Nigeria | AN2: Nigeria | AO2: Nigeria | AP2: Nigeria | AQ2: Nigeria | AR2: Nigeria | AS2: Nigeria | AT2: Nigeria | AU2: Nigeria | AV2: Nigeria
A3: Main calculations | F3: unit | G3: type | H3: Overall | I3: Bauchi | J3: Gombe | K3: Jigawa | L3: Kaduna - cohort 17 | M3: Kano | N3: Katsina | O3: Kebbi | P3: Sokoto | Q3: Zamfara | R3: Abia | S3: Adamawa | T3: Akwa Ibom | U3: Anambra | V3: Bayelsa | W3: Benue | X3: Borno | Y3: Cross River | Z3: Delta | AA3: Ebonyi | AB3: Edo | AC3: Ekiti | AD3: Enugu | AE3: FCT | AF3: Imo | AG3: Kaduna | AH3: Kogi | AI3: Kwara | AJ3: Lagos | AK3: Nasarawa | AL3: Niger | AM3: Niger - cohorts 32 & 36 | AN3: Niger - cohort 34 | AO3: Ogun | AP3: Ondo | AQ3: Osun | AR3: Oyo | AS3: Plateau | AT3: Rivers | AU3: Taraba | AV3: Yobe
E4: Final cost-effectiveness estimate (pulled from "Main calcs" sheet for visibility) | F4: ='Main CEA'!F242 -> xbenchmark | G4: ='Main CEA'!G242 -> calc | H4: ='Main CEA'!H242 -> - | I4: ='Main CEA'!I242 -> 20.039606 | J4: ='Main CEA'!J242 -> 10.020838 | K4: ='Main CEA'!K242 -> 18.177505 | L4: ='Main CEA'!L242 -> 9.0027672 | M4: ='Main CEA'!M242 -> 12.612827 | ... AV4: ='Main CEA'!AV242 -> 11.471963
A5: Vaccination coverage rates for the control group of the New Incentives RCT
C7: Vaccination coverage rates for the control group of the New Incentives RCT
E8: Proportion of children in the New Incentives RCT control group who reported receiving the BCG vaccine | F8: =Inputs!F208 -> % | G8: =Inputs!G208 -> input | H8: =Inputs!H208 -> 0.63 | I8: =Inputs!I208 -> - | J8: =Inputs!J208 -> - | K8: =Inputs!K208 -> - | L8: =Inputs!L208 -> - | M8: =Inputs!M208 -> - | ... AV8: =Inputs!AV208 -> -
E9: Proportion of children in the New Incentives RCT control group who reported receiving the 1st dose of the Penta vaccine | F9: =Inputs!F209 -> % | G9: =Inputs!G209 -> input | H9: =Inputs!H209 -> 0.5419 | I9: =Inputs!I209 -> - | J9: =Inputs!J209 -> - | K9: =Inputs!K209 -> - | L9: =Inputs!L209 -> - | M9: =Inputs!M209 -> - | ... AV9: =Inputs!AV209 -> -
E10: Proportion of children in the New Incentives RCT control group who reported receiving the 2nd dose of the Penta vaccine | F10: =Inputs!F210 -> % | G10: =Inputs!G210 -> input | H10: =Inputs!H210 -> 0.3961 | I10: =Inputs!I210 -> - | J10: =Inputs!J210 -> - | K10: =Inputs!K210 -> - | L10: =Inputs!L210 -> - | M10: =Inputs!M210 -> - | ... AV10: =Inputs!AV210 -> -
E11: Proportion of children in the New Incentives RCT control group who reported receiving the 3rd dose of the Penta vaccine | F11: =Inputs!F211 -> % | G11: =Inputs!G211 -> input | H11: =Inputs!H211 -> 0.2978 | I11: =Inputs!I211 -> - | J11: =Inputs!J211 -> - | K11: =Inputs!K211 -> - | L11: =Inputs!L211 -> - | M11: =Inputs!M211 -> - | ... AV11: =Inputs!AV211 -> -
E12: Proportion of children in the New Incentives RCT control group who reported receiving the 1st dose of the PCV vaccine | F12: =Inputs!F212 -> % | G12: =Inputs!G212 -> input | H12: =Inputs!H212 -> 0.4954 | I12: =Inputs!I212 -> - | J12: =Inputs!J212 -> - | K12: =Inputs!K212 -> - | L12: =Inputs!L212 -> - | M12: =Inputs!M212 -> - | ... AV12: =Inputs!AV212 -> -
E13: Proportion of children in the New Incentives RCT control group who reported receiving the 2nd dose of the PCV vaccine | F13: =Inputs!F213 -> % | G13: =Inputs!G213 -> input | H13: =Inputs!H213 -> 0.3554 | I13: =Inputs!I213 -> - | J13: =Inputs!J213 -> - | K13: =Inputs!K213 -> - | L13: =Inputs!L213 -> - | M13: =Inputs!M213 -> - | ... AV13: =Inputs!AV213 -> -
E14: Proportion of children in the New Incentives RCT control group who reported receiving the 3rd dose of the PCV vaccine | F14: =Inputs!F214 -> % | G14: =Inputs!G214 -> input | H14: =Inputs!H214 -> 0.266 | I14: =Inputs!I214 -> - | J14: =Inputs!J214 -> - | K14: =Inputs!K214 -> - | L14: =Inputs!L214 -> - | M14: =Inputs!M214 -> - | ... AV14: =Inputs!AV214 -> -
E15: Proportion of children in the New Incentives RCT control group who reported receiving the measles vaccine | F15: =Inputs!F215 -> % | G15: =Inputs!G215 -> input | H15: =Inputs!H215 -> 0.5894 | I15: =Inputs!I215 -> - | J15: =Inputs!J215 -> - | K15: =Inputs!K215 -> - | L15: =Inputs!L215 -> - | M15: =Inputs!M215 -> - | ... AV15: =Inputs!AV215 -> -
C17: Adjustment for self-report bias
E18: Adjustment for self-report bias in the New Incentives RCT | F18: =Inputs!F218 -> % | G18: =Inputs!G218 -> input | H18: =Inputs!H218 -> -0.2768959 | I18: =Inputs!I218 -> - | J18: =Inputs!J218 -> - | K18: =Inputs!K218 -> - | L18: =Inputs!L218 -> - | M18: =Inputs!M218 -> - | ... AV18: =Inputs!AV218 -> -
C20: Vaccination coverage rates for the control group of the New Incentives RCT, adjusted for self-report bias
E21: Proportion of children in the New Incentives RCT control group who received the BCG vaccine | F21: % | G21: calc | H21: =H8*(1+H$18) -> 0.45555558 | I21: - | J21: - | K21: - | L21: - | M21: - | N21: - | O21: - | P21: - | Q21: - | R21: - | S21: - | T21: - | U21: - | V21: - | W21: - | X21: - | Y21: - | Z21: - | AA21: - | AB21: - | AC21: - | AD21: - | AE21: - | AF21: - | AG21: - | AH21: - | AI21: - | AJ21: - | AK21: - | AL21: - | AM21: - | AN21: - | AO21: - | AP21: - | AQ21: - | AR21: - | AS21: - | AT21: - | AU21: - | AV21: -
E22: Proportion of children in the New Incentives RCT control group who received the 1st dose of the Penta vaccine | F22: % | G22: calc | H22: =H9*(1+H$18) -> 0.39185011 | I22: - | J22: - | K22: - | L22: - | M22: - | N22: - | O22: - | P22: - | Q22: - | R22: - | S22: - | T22: - | U22: - | V22: - | W22: - | X22: - | Y22: - | Z22: - | AA22: - | AB22: - | AC22: - | AD22: - | AE22: - | AF22: - | AG22: - | AH22: - | AI22: - | AJ22: - | AK22: - | AL22: - | AM22: - | AN22: - | AO22: - | AP22: - | AQ22: - | AR22: - | AS22: - | AT22: - | AU22: - | AV22: -
E23: Proportion of children in the New Incentives RCT control group who received the 2nd dose of the Penta vaccine | F23: % | G23: calc | H23: =H10*(1+H$18) -> 0.28642153 | I23: - | J23: - | K23: - | L23: - | M23: - | N23: - | O23: - | P23: - | Q23: - | R23: - | S23: - | T23: - | U23: - | V23: - | W23: - | X23: - | Y23: - | Z23: - | AA23: - | AB23: - | AC23: - | AD23: - | AE23: - | AF23: - | AG23: - | AH23: - | AI23: - | AJ23: - | AK23: - | AL23: - | AM23: - | AN23: - | AO23: - | AP23: - | AQ23: - | AR23: - | AS23: - | AT23: - | AU23: - | AV23: -
E24: Proportion of children in the New Incentives RCT control group who received the 3rd dose of the Penta vaccine | F24: % | G24: calc | H24: =H11*(1+H$18) -> 0.2153404 | I24: - | J24: - | K24: - | L24: - | M24: - | N24: - | O24: - | P24: - | Q24: - | R24: - | S24: - | T24: - | U24: - | V24: - | W24: - | X24: - | Y24: - | Z24: - | AA24: - | AB24: - | AC24: - | AD24: - | AE24: - | AF24: - | AG24: - | AH24: - | AI24: - | AJ24: - | AK24: - | AL24: - | AM24: - | AN24: - | AO24: - | AP24: - | AQ24: - | AR24: - | AS24: - | AT24: - | AU24: - | AV24: -
E25: Proportion of children in the New Incentives RCT control group who received the 1st dose of the PCV vaccine | F25: % | G25: calc | H25: =H12*(1+H$18) -> 0.35822577 | I25: - | J25: - | K25: - | L25: - | M25: - | N25: - | O25: - | P25: - | Q25: - | R25: - | S25: - | T25: - | U25: - | V25: - | W25: - | X25: - | Y25: - | Z25: - | AA25: - | AB25: - | AC25: - | AD25: - | AE25: - | AF25: - | AG25: - | AH25: - | AI25: - | AJ25: - | AK25: - | AL25: - | AM25: - | AN25: - | AO25: - | AP25: - | AQ25: - | AR25: - | AS25: - | AT25: - | AU25: - | AV25: -
E26: Proportion of children in the New Incentives RCT control group who received the 2nd dose of the PCV vaccine | F26: % | G26: calc | H26: =H13*(1+H$18) -> 0.2569912 | I26: - | J26: - | K26: - | L26: - | M26: - | N26: - | O26: - | P26: - | Q26: - | R26: - | S26: - | T26: - | U26: - | V26: - | W26: - | X26: - | Y26: - | Z26: - | AA26: - | AB26: - | AC26: - | AD26: - | AE26: - | AF26: - | AG26: - | AH26: - | AI26: - | AJ26: - | AK26: - | AL26: - | AM26: - | AN26: - | AO26: - | AP26: - | AQ26: - | AR26: - | AS26: - | AT26: - | AU26: - | AV26: -
E27: Proportion of children in the New Incentives RCT control group who received the 3rd dose of the PCV vaccine | F27: % | G27: calc | H27: =H14*(1+H$18) -> 0.19234569 | I27: - | J27: - | K27: - | L27: - | M27: - | N27: - | O27: - | P27: - | Q27: - | R27: - | S27: - | T27: - | U27: - | V27: - | W27: - | X27: - | Y27: - | Z27: - | AA27: - | AB27: - | AC27: - | AD27: - | AE27: - | AF27: - | AG27: - | AH27: - | AI27: - | AJ27: - | AK27: - | AL27: - | AM27: - | AN27: - | AO27: - | AP27: - | AQ27: - | AR27: - | AS27: - | AT27: - | AU27: - | AV27: -
E28: Proportion of children in the New Incentives RCT control group who received the measles vaccine | F28: % | G28: calc | H28: =H15*(1+H$18) -> 0.42619756 | I28: - | J28: - | K28: - | L28: - | M28: - | N28: - | O28: - | P28: - | Q28: - | R28: - | S28: - | T28: - | U28: - | V28: - | W28: - | X28: - | Y28: - | Z28: - | AA28: - | AB28: - | AC28: - | AD28: - | AE28: - | AF28: - | AG28: - | AH28: - | AI28: - | AJ28: - | AK28: - | AL28: - | AM28: - | AN28: - | AO28: - | AP28: - | AQ28: - | AR28: - | AS28: - | AT28: - | AU28: - | AV28: -
C30: Proportion of vaccine-preventable mortalities that could be prevented by each vaccine dose
E31: Proportion of vaccine-preventable mortalities among people under age 5 that could be prevented by the BCG vaccine | F31: ='Disease burden'!F388 -> % | G31: supp | H31: ='Disease burden'!H388 -> - | I31: ='Disease burden'!I388 -> 0.17823491 | J31: ='Disease burden'!J388 -> 0.12033359 | K31: ='Disease burden'!K388 -> 0.20302136 | L31: ='Disease burden'!L388 -> 0.10657065 | M31: ='Disease burden'!M388 -> 0.13277628 | N31: ='Disease burden'!N388 -> 0.17332974 | O31: ='Disease burden'!O388 -> 0.15789653 | ... AV31: ='Disease burden'!AV388 -> 0.15986442
E32: Proportion of vaccine-preventable mortalities among people under age 5 that could be prevented by the 1st dose of the Penta vaccine | F32: ='Disease burden'!F389 -> % | G32: supp | H32: ='Disease burden'!H389 -> - | I32: ='Disease burden'!I389 -> 0.073644315 | J32: ='Disease burden'!J389 -> 0.09622371 | K32: ='Disease burden'!K389 -> 0.091772594 | L32: ='Disease burden'!L389 -> 0.11232443 | M32: ='Disease burden'!M389 -> 0.085575908 | N32: ='Disease burden'!N389 -> 0.089629168 | O32: ='Disease burden'!O389 -> 0.10466208 | ... AV32: ='Disease burden'!AV389 -> 0.11459606
E33: Proportion of vaccine-preventable mortalities among people under age 5 that could be prevented by the 2nd dose of the Penta vaccine | F33: ='Disease burden'!F390 -> % | G33: supp | H33: ='Disease burden'!H390 -> - | I33: ='Disease burden'!I390 -> 0.11572678 | J33: ='Disease burden'!J390 -> 0.15120869 | K33: ='Disease burden'!K390 -> 0.14421408 | L33: ='Disease burden'!L390 -> 0.17650982 | M33: ='Disease burden'!M390 -> 0.13447643 | N33: ='Disease burden'!N390 -> 0.14084584 | O33: ='Disease burden'!O390 -> 0.16446899 | ... AV33: ='Disease burden'!AV390 -> 0.18007952
E34: Proportion of vaccine-preventable mortalities among people under age 5 that could be prevented by the 3rd dose of the Penta vaccine | F34: ='Disease burden'!F391 -> % | G34: supp | H34: ='Disease burden'!H391 -> - | I34: ='Disease burden'!I391 -> 0.021041233 | J34: ='Disease burden'!J391 -> 0.027492489 | K34: ='Disease burden'!K391 -> 0.026220741 | L34: ='Disease burden'!L391 -> 0.032092695 | M34: ='Disease burden'!M391 -> 0.024450259 | N34: ='Disease burden'!N391 -> 0.025608334 | O34: ='Disease burden'!O391 -> 0.029903452 | ... AV34: ='Disease burden'!AV391 -> 0.032741731
E35: Proportion of vaccine-preventable mortalities among people under age 5 that could be prevented by the 1st dose of the PCV vaccine | F35: ='Disease burden'!F392 -> % | G35: supp | H35: ='Disease burden'!H392 -> - | I35: ='Disease burden'!I392 -> 0.089900525 | J35: ='Disease burden'!J392 -> 0.10135603 | K35: ='Disease burden'!K392 -> 0.085648045 | L35: ='Disease burden'!L392 -> 0.107903 | M35: ='Disease burden'!M392 -> 0.11094009 | N35: ='Disease burden'!N392 -> 0.079775398 | O35: ='Disease burden'!O392 -> 0.076462066 | ... AV35: ='Disease burden'!AV392 -> 0.073761103
E36: Proportion of vaccine-preventable mortalities among people under age 5 that could be prevented by the 2nd dose of the PCV vaccine | F36: ='Disease burden'!F393 -> % | G36: supp | H36: ='Disease burden'!H393 -> - | I36: ='Disease burden'!I393 -> 0.14127225 | J36: ='Disease burden'!J393 -> 0.15927376 | K36: ='Disease burden'!K393 -> 0.13458978 | L36: ='Disease burden'!L393 -> 0.16956186 | M36: ='Disease burden'!M393 -> 0.17433442 | N36: ='Disease burden'!N393 -> 0.12536134 | O36: ='Disease burden'!O393 -> 0.12015467 | ... AV36: ='Disease burden'!AV393 -> 0.1159103
E37: Proportion of vaccine-preventable mortalities among people under age 5 that could be prevented by the 3rd dose of the PCV vaccine | F37: ='Disease burden'!F394 -> % | G37: supp | H37: ='Disease burden'!H394 -> - | I37: ='Disease burden'!I394 -> 0.025685864 | J37: ='Disease burden'!J394 -> 0.028958866 | K37: ='Disease burden'!K394 -> 0.02447087 | L37: ='Disease burden'!L394 -> 0.030829429 | M37: ='Disease burden'!M394 -> 0.031697167 | N37: ='Disease burden'!N394 -> 0.022792971 | O37: ='Disease burden'!O394 -> 0.021846305 | ... AV37: ='Disease burden'!AV394 -> 0.021074601
E38: Proportion of vaccine-preventable mortalities among people under age 5 that could be prevented by the 1st dose of the measles vaccine | F38: ='Disease burden'!F398 -> % | G38: supp | H38: ='Disease burden'!H398 -> - | I38: ='Disease burden'!I398 -> 0.074606151 | J38: ='Disease burden'!J398 -> 0.057117138 | K38: ='Disease burden'!K398 -> 0.090072195 | L38: ='Disease burden'!L395 -> 0.14558025 | M38: ='Disease burden'!M398 -> 0.044052509 | N38: ='Disease burden'!N398 -> 0.10112555 | O38: ='Disease burden'!O398 -> 0.10124241 | P38: ='Disease burden'!P398 -> 0.077921789 | Q38: ='Disease burden'!Q398 -> 0.092018777 | R38: ='Disease burden'!R398 -> 0.035524554 | S38: ='Disease burden'!S398 -> 0.045762037 | T38: ='Disease burden'!T398 -> 0.068727418 | ... AV38: ='Disease burden'!AV398 -> 0.10845507
E39: Proportion of vaccine-preventable mortalities among people under age 5 that could be prevented by the 2nd dose of the measles vaccine | F39: ='Disease burden'!F399 -> % | G39: supp | H39: ='Disease burden'!H399 -> - | I39: ='Disease burden'!I399 -> 0.0043885971 | J39: ='Disease burden'!J399 -> 0.0033598316 | K39: ='Disease burden'!K399 -> 0.0052983644 | L39: ='Disease burden'!L396 -> 0.02911605 | M39: ='Disease burden'!M399 -> 0.0025913241 | N39: ='Disease burden'!N399 -> 0.0059485617 | O39: ='Disease burden'!O399 -> 0.0059554359 | P39: ='Disease burden'!P399 -> 0.0045836346 | Q39: ='Disease burden'!Q399 -> 0.0054128692 | R39: ='Disease burden'!R399 -> 0.0020896796 | S39: ='Disease burden'!S399 -> 0.0026918845 | T39: ='Disease burden'!T399 -> 0.0040427893 | ... AV39: ='Disease burden'!AV399 -> 0.0063797102
C41: Average proportion of vaccine-preventable mortalities that could be prevented by each vaccine dose in RCT states (Jigawa, Katsina, Zamfara)
E42: Proportion of vaccine-preventable mortalities among people under age 5 that could be prevented by the BCG vaccine in RCT states | F42: % | G42: calc | H42: =AVERAGE(K31,N31,Q31) -> 0.1939556 | I42: - | J42: - | K42: - | L42: - | M42: - | N42: - | O42: - | P42: - | Q42: - | R42: - | S42: - | T42: - | U42: - | V42: - | W42: - | X42: - | Y42: - | Z42: - | AA42: - | AB42: - | AC42: - | AD42: - | AE42: - | AF42: - | AG42: - | AH42: - | AI42: - | AJ42: - | AK42: - | AL42: - | AM42: - | AN42: - | AO42: - | AP42: - | AQ42: - | AR42: - | AS42: - | AT42: - | AU42: - | AV42: -
E43: Proportion of vaccine-preventable mortalities among people under age 5 that could be prevented by the 1st dose of the Penta vaccine in RCT states | F43: % | G43: calc | H43: =AVERAGE(K32,N32,Q32) -> 0.088879196 | I43: - | J43: - | K43: - | L43: - | M43: - | N43: - | O43: - | P43: - | Q43: - | R43: - | S43: - | T43: - | U43: - | V43: - | W43: - | X43: - | Y43: - | Z43: - | AA43: - | AB43: - | AC43: - | AD43: - | AE43: - | AF43: - | AG43: - | AH43: - | AI43: - | AJ43: - | AK43: - | AL43: - | AM43: - | AN43: - | AO43: - | AP43: - | AQ43: - | AR43: - | AS43: - | AT43: - | AU43: - | AV43: -
E44: Proportion of vaccine-preventable mortalities among people under age 5 that could be prevented by the 2nd dose of the Penta vaccine in RCT states | F44: % | G44: calc | H44: =AVERAGE(K33,N33,Q33) -> 0.13966731 | I44: - | J44: - | K44: - | L44: - | M44: - | N44: - | O44: - | P44: - | Q44: - | R44: - | S44: - | T44: - | U44: - | V44: - | W44: - | X44: - | Y44: - | Z44: - | AA44: - | AB44: - | AC44: - | AD44: - | AE44: - | AF44: - | AG44: - | AH44: - | AI44: - | AJ44: - | AK44: - | AL44: - | AM44: - | AN44: - | AO44: - | AP44: - | AQ44: - | AR44: - | AS44: - | AT44: - | AU44: - | AV44: -
E45: Proportion of vaccine-preventable mortalities among people under age 5 that could be prevented by the 3rd dose of the Penta vaccine in RCT states | F45: % | G45: calc | H45: =AVERAGE(K34,N34,Q34) -> 0.025394056 | I45: - | J45: - | K45: - | L45: - | M45: - | N45: - | O45: - | P45: - | Q45: - | R45: - | S45: - | T45: - | U45: - | V45: - | W45: - | X45: - | Y45: - | Z45: - | AA45: - | AB45: - | AC45: - | AD45: - | AE45: - | AF45: - | AG45: - | AH45: - | AI45: - | AJ45: - | AK45: - | AL45: - | AM45: - | AN45: - | AO45: - | AP45: - | AQ45: - | AR45: - | AS45: - | AT45: - | AU45: - | AV45: -
...

Sheet Disease burden
I1: New Incentives – current states of operation | R1: New Incentives – prospective states | AF1: New Incentives – prospective states
I2: Nigeria | J2: Nigeria | K2: Nigeria | L2: Nigeria | M2: Nigeria | N2: Nigeria | O2: Nigeria | P2: Nigeria | Q2: Nigeria | R2: Nigeria | S2: Nigeria | T2: Nigeria | U2: Nigeria | V2: Nigeria | W2: Nigeria | X2: Nigeria | Y2: Nigeria | Z2: Nigeria | AA2: Nigeria | AB2: Nigeria | AC2: Nigeria | AD2: Nigeria | AE2: Nigeria | AF2: Nigeria | AG2: Nigeria | AH2: Nigeria | AI2: Nigeria | AJ2: Nigeria | AK2: Nigeria | AL2: Nigeria | AM2: Nigeria | AN2: Nigeria | AO2: Nigeria | AP2: Nigeria | AQ2: Nigeria | AR2: Nigeria | AS2: Nigeria | AT2: Nigeria | AU2: Nigeria | AV2: Nigeria
A3: Main calculations | F3: unit | G3: type | H3: Overall | I3: Bauchi | J3: Gombe | K3: Jigawa | L3: Kaduna - cohort 17 | M3: Kano | N3: Katsina | O3: Kebbi | P3: Sokoto | Q3: Zamfara | R3: Abia | S3: Adamawa | T3: Akwa Ibom | U3: Anambra | V3: Bayelsa | W3: Benue | X3: Borno | Y3: Cross River | Z3: Delta | AA3: Ebonyi | AB3: Edo | AC3: Ekiti | AD3: Enugu | AE3: FCT | AF3: Imo | AG3: Kaduna | AH3: Kogi | AI3: Kwara | AJ3: Lagos | AK3: Nasarawa | AL3: Niger | AM3: Niger - cohorts 32 & 36 | AN3: Niger - cohort 34 | AO3: Ogun | AP3: Ondo | AQ3: Osun | AR3: Oyo | AS3: Plateau | AT3: Rivers | AU3: Taraba | AV3: Yobe
E4: Final cost-effectiveness estimate (pulled from "Main calcs" sheet for visibility) | F4: ='Main CEA'!F242 -> xbenchmark | G4: ='Main CEA'!G242 -> calc | H4: ='Main CEA'!H242 -> - | I4: ='Main CEA'!I242 -> 20.039606 | J4: ='Main CEA'!J242 -> 10.020838 | K4: ='Main CEA'!K242 -> 18.177505 | L4: ='Main CEA'!L242 -> 9.0027672 | M4: ='Main CEA'!M242 -> 12.612827 | ... AV4: ='Main CEA'!AV242 -> 11.471963
A5: Tuberculosis
C7: Probability of dying of tuberculosis
E8: Probability that a person will die of tuberculosis before reaching age 5 | F8: =Inputs!F111 -> % | G8: =Inputs!G111 -> input | H8: =Inputs!H111 -> - | I8: =Inputs!I111 -> 0.003629763 | J8: =Inputs!J111 -> 0.001693533 | K8: =Inputs!K111 -> 0.004321809 | L8: =Inputs!L111 -> 0.000876042 | M8: =Inputs!M111 -> 0.001723095 | ... AV8: =Inputs!AV111 -> 0.00187352
E9: Probability that a 5-year-old will die of tuberculosis before reaching age 15 | F9: =Inputs!F112 -> % | G9: =Inputs!G112 -> input | H9: =Inputs!H112 -> - | I9: =Inputs!I112 -> 0.000531146 | J9: =Inputs!J112 -> 0.000260845 | K9: =Inputs!K112 -> 0.000599109 | L9: =Inputs!L112 -> 0.000139527 | M9: =Inputs!M112 -> 0.000283003 | ... AV9: =Inputs!AV112 -> 0.000388626
E10: Probability that a 15-year-old will die of tuberculosis before reaching age 50 | F10: =Inputs!F113 -> % | G10: =Inputs!G113 -> input | H10: =Inputs!H113 -> - | I10: =Inputs!I113 -> 0.007150253 | J10: =Inputs!J113 -> 0.004007767 | K10: =Inputs!K113 -> 0.008685948 | L10: =Inputs!L113 -> 0.002843472 | M10: =Inputs!M113 -> 0.003815045 | ... AV10: =Inputs!AV113 -> 0.006708114
E11: Probability that a 50-year-old will die of tuberculosis before reaching age 75 | F11: =Inputs!F114 -> % | G11: =Inputs!G114 -> input | H11: =Inputs!H114 -> - | I11: =Inputs!I114 -> 0.049361812 | J11: =Inputs!J114 -> 0.030242318 | K11: =Inputs!K114 -> 0.052337352 | L11: =Inputs!L114 -> 0.017468647 | M11: =Inputs!M114 -> 0.024547523 | ... AV11: =Inputs!AV114 -> 0.043770944
C13: Tuberculosis mortalities occurring before the age of vaccination
